Workbook

Sheet SCHEDULE
D1: Block 1 | I1: Block 2 | N1: Block 3 | X1: Block 5 | AC1: End of the year Block | AE1: Block 6 | AJ1: Block 7 | AO1: Block 8 | AT1: Block 9 | AY1: Block 10 | BD1: CARDIO | BE1: CLINIC | BF1: ED | BG1: FLOORS | BH1: ICU | BI1: ICU E | BJ1: ICU N | BK1: ID | BL1: NEURO | BM1: NF | BN1: SWING | BO1: VACATION | BP1: SUB-TOTAL | BQ1: PALLIATIVE | BR1: GERIATRIC | BS1: GS / GI | BT1: HEM/ONC | BU1: PAIN MANGEMENT | BV1: RHEUMA | BW1: ENDO | BX1: PLASTIC | BY1: PULM | BZ1: SICU | CA1: DERMATOLOGY | CB1: NEPHRO | CC1: SUB-TOTAL | CD1: TOTAL
D2: 1 | E2: 2 | F2: 3 | G2: 4 | H2: 5 | I2: 6 | J2: 7 | K2: 8 | L2: 9 | M2: 10 | N2: 11 | O2: 12 | P2: 13 | Q2: 14 | R2: 15 | S2: 16 | T2: 17 | U2: 18 | V2: 19 | W2: 20 | X2: 21 | Y2: 22 | Z2: 23 | AA2: 24 | AB2: 25 | AC2: 26 | AD2: 27 | AE2: 28 | AF2: 29 | AG2: 30 | AH2: 31 | AI2: 32 | AJ2: 33 | AK2: 34 | AL2: 35 | AM2: 36 | AN2: 37 | AO2: 38 | AP2: 39 | AQ2: 40 | AR2: 41 | AS2: 42 | AT2: 43 | AU2: 44 | AV2: 45 | AW2: 46 | AX2: 47 | AY2: 48 | AZ2: 49 | BA2: 50 | BB2: 51 | BC2: 52
A3: PGY | D3: 07/01-07/06 | E3: 07/07-07/13 | F3: 07/14-07/20 | G3: 07/21-07/27 | H3: 07/28-08/03 | I3: 08/04-08/10 | J3: 08/11-08/17 | K3: 08/18-08/24 | L3: 08/25-8/31 | M3: 09/01-09/07 | N3: 09/08-09/14 | O3: 09/15-09/21 | P3: 09/22-09/28 | Q3: 09/29-10/05 | R3: 10/06-10/12 | S3: 10/13-10/19 | T3: 10/20-10/26 | U3: 10/27-11/02 | V3: 11/03-11/09 | W3: 11/10-11/16 | X3: 11/17-11/23 | Y3: 11/24-11/30 | Z3: 12/01-12/07 | AA3: 12/08-12/14 | AB3: 12/15-12/21 | AC3: 12/22-12/28 | AD3: 12/29-01/04 | AE3: 01/05-01/11 | AF3: 01/12-01/18 | AG3: 01/19-01/25 | AH3: 01/26-02/01 | AI3: 02/02-02/08 | AJ3: 02/09-02/15 | AK3: 02/16-02/22 | AL3: 02/23-03/01 | AM3: 03/02-03/08 | AN3: 03/09-03/15 | AO3: 03/16-03/22 | AP3: 03/23-03/29 | AQ3: 03/30-04/05 | AR3: 04/06-04/12 | AS3: 04/13-04/19 | AT3: 04/20-04/26 | AU3: 04/27-05/03 | AV3: 05/04-05/10 | AW3: 05/11-05/17 | AX3: 05/18-05/24 | AY3: 05/25-05/31 | AZ3: 06/01-06/07 | BA3: 06/08-06/14 | BB3: 06/15-06/21 | BC3: 06/22-06/30
A4: Cohort 1 | B4: PGY-1 | C4: B. Perez | D4: CLINIC * | E4: CLINIC * | F4: D | G4: ICU | H4: CARDIO-HCA | I4: CLINIC * | J4: NF | K4: NF | L4: NF | M4: NF | N4: CLINIC | O4: CLINIC | P4: SWING | Q4: SWING | R4: SWING | S4: CLINIC * | T4: VACATION | U4: VACATION | V4: VACATION | W4: VACATION | X4: CLINIC * | Y4: A | Z4: A | AA4: A | AB4: A | AC4: A | AD4: CARDIO-HCA | AE4: CLINIC * | AF4: ED | AG4: ED | AH4: ID | AI4: ID | AJ4: CLINIC * | AK4: D | AL4: D | AM4: D | AN4: CLINIC | AO4: CLINIC | AP4: ICU N | AQ4: ICU N | AR4: ICU N | AS4: ICU N | AT4: CLINIC * | AU4: B | AV4: B | AW4: B | AX4: B | AY4: CLINIC * | AZ4: ICU E | BA4: ICU E | BB4: CLINIC * | BC4: ICU E | BD4: =COUNTIF($D4:$BC4,"CARDIO")+COUNTIF($D4:$BC4,"CARDIO E")+COUNTIF($D4:$BC4,"CARDIO E *")+COUNTIF($D4:$BC4,"CARDIO-HCA")+COUNTIF($D4:$BC4,"CARDIO-HCA *")+COUNTIF($D4:$BC4,"CARDIO-RAM")+COUNTIF($D4:$BC4,"CARDIO-RAM *") | BE4: =COUNTIF($D4:$BC4,"CLINIC")+COUNTIF($D4:$BC4,"CLINIC *")+COUNTIF($D4:$BC4,"URGENT CARE")+COUNTIF($D4:$BC4,"URGENT CARE *") | BF4: =COUNTIF($D4:$BC4,"ED") | BG4: =COUNTIF($D4:$BC4,"A")+COUNTIF($D4:$BC4,"B")+COUNTIF($D4:$BC4,"C")+COUNTIF($D4:$BC4,"D")+COUNTIF($D4:$BC4,"G") | BH4: =COUNTIF($D4:$BC4,"ICU") | BI4: =COUNTIF($D4:$BC4,"ICU E") | BJ4: =COUNTIF($D4:$BC4,"ICU N") | BK4: =COUNTIF($D4:$BC4,"ID")+COUNTIF($D4:$BC4,"ID *") | BL4: =COUNTIF($D4:$BC4,"NEURO")+COUNTIF($D4:$BC4,"NEURO *") | BM4: =COUNTIF($D4:$BC4,"NF") | BN4: =COUNTIF($D4:$BC4,"SWING") | BO4: =COUNTIF($D4:$BC4,"VACATION") | BP4: =SUM(BD4:BO4) | BQ4: =COUNTIF($D4:$BC4,"PALLIATIVE")+COUNTIF($D4:$BC4,"PALLIATIVE *") | BR4: =COUNTIF($D4:$BC4,"GERIATRIC")+COUNTIF($D4:$BC4,"GERIATRIC 2") | BS4: =COUNTIF($D4:$BC4,"GS")+COUNTIF($D4:$BC4,"GI")+COUNTIF($D4:$BC4,"GI *") | BT4: =COUNTIF($D4:$BC4,"HEM/ONC")+COUNTIF($D4:$BC4,"HEM/ONC *") | BU4: =COUNTIF($D4:$BC4,"IR RADIOLOGY")+COUNTIF($D4:$BC4,"IR RADIOLOGY *") | BV4: =COUNTIF($D4:$BC4,"RHEUMA")+COUNTIF($D4:$BC4,"RHEUMA *") | BW4: =COUNTIF($D4:$BC4,"ENDO")+COUNTIF($D4:$BC4,"ENDO *") | BX4: =COUNTIF($D4:$BC4,"PLASTIC")+COUNTIF($D4:$BC4,"PLASTIC *") | BY4: =COUNTIF($D4:$BC4,"PULM")+COUNTIF($D4:$BC4,"PULM *") | BZ4: =COUNTIF($D4:$BC4,"SICU")+COUNTIF($D4:$BC4,"SICU *") | CA4: =COUNTIF($D4:$BC4,"DERMATOLOGY")+COUNTIF($D4:$BC4,"DERMATOLOGY *") | CB4: =COUNTIF($D4:$BC4,"NEPHRO")+COUNTIF($D4:$BC4,"NEPHRO *") | CC4: =SUM(BQ4:CB4) | CD4: =BP4+CC4
C5: L. Duarte | D5: CLINIC * | E5: C | F5: C | G5: C | H5: ED | I5: CLINIC * | J5: C | K5: C | L5: C | M5: C | N5: CLINIC * | O5: CLINIC * | P5: ID | Q5: ID | R5: ICU N | S5: CLINIC * | T5: A | U5: A | V5: A | W5: A | X5: CLINIC * | Y5: C | Z5: ICU N | AA5: ICU N | AB5: ICU N | AC5: ICU N | AD5: ED | AE5: CLINIC * | AF5: CARDIO-HCA | AG5: CARDIO-HCA | AH5: NF | AI5: ICU N | AJ5: CLINIC * | AK5: VACATION | AL5: VACATION | AM5: VACATION | AN5: VACATION | AO5: CLINIC * | AP5: D | AQ5: D | AR5: D | AS5: D | AT5: CLINIC | AU5: CLINIC | AV5: A | AW5: A | AX5: A | AY5: CLINIC * | AZ5: ICU E | BA5: ICU E | BB5: CLINIC | BC5: CLINIC | BD5: =COUNTIF($D5:$BC5,"CARDIO")+COUNTIF($D5:$BC5,"CARDIO E")+COUNTIF($D5:$BC5,"CARDIO E *")+COUNTIF($D5:$BC5,"CARDIO-HCA")+COUNTIF($D5:$BC5,"CARDIO-HCA *")+COUNTIF($D5:$BC5,"CARDIO-RAM")+COUNTIF($D5:$BC5,"CARDIO-RAM *") | BE5: =COUNTIF($D5:$BC5,"CLINIC")+COUNTIF($D5:$BC5,"CLINIC *")+COUNTIF($D5:$BC5,"URGENT CARE")+COUNTIF($D5:$BC5,"URGENT CARE *") | BF5: =COUNTIF($D5:$BC5,"ED") | BG5: =COUNTIF($D5:$BC5,"A")+COUNTIF($D5:$BC5,"B")+COUNTIF($D5:$BC5,"C")+COUNTIF($D5:$BC5,"D")+COUNTIF($D5:$BC5,"G") | BH5: =COUNTIF($D5:$BC5,"ICU") | BI5: =COUNTIF($D5:$BC5,"ICU E") | BJ5: =COUNTIF($D5:$BC5,"ICU N") | BK5: =COUNTIF($D5:$BC5,"ID")+COUNTIF($D5:$BC5,"ID *") | BL5: =COUNTIF($D5:$BC5,"NEURO")+COUNTIF($D5:$BC5,"NEURO *") | BM5: =COUNTIF($D5:$BC5,"NF") | BN5: =COUNTIF($D5:$BC5,"SWING") | BO5: =COUNTIF($D5:$BC5,"VACATION") | BP5: =SUM(BD5:BO5) | BQ5: =COUNTIF($D5:$BC5,"PALLIATIVE")+COUNTIF($D5:$BC5,"PALLIATIVE *") | BR5: =COUNTIF($D5:$BC5,"GERIATRIC")+COUNTIF($D5:$BC5,"GERIATRIC 2") | BS5: =COUNTIF($D5:$BC5,"GS")+COUNTIF($D5:$BC5,"GI")+COUNTIF($D5:$BC5,"GI *") | BT5: =COUNTIF($D5:$BC5,"HEM/ONC")+COUNTIF($D5:$BC5,"HEM/ONC *") | BU5: =COUNTIF($D5:$BC5,"PAIN MANAGEMENT")+COUNTIF($D5:$BC5,"PAIN MANAGEMENT *") | BV5: =COUNTIF($D5:$BC5,"RHEUMA")+COUNTIF($D5:$BC5,"RHEUMA *") | BW5: =COUNTIF($D5:$BC5,"ENDO")+COUNTIF($D5:$BC5,"ENDO *") | BX5: =COUNTIF($D5:$BC5,"PLASTIC")+COUNTIF($D5:$BC5,"PLASTIC *") | BY5: =COUNTIF($D5:$BC5,"PULM")+COUNTIF($D5:$BC5,"PULM *") | BZ5: =COUNTIF($D5:$BC5,"SICU")+COUNTIF($D5:$BC5,"SICU *") | CA5: =COUNTIF($D5:$BC5,"DERMATOLOGY")+COUNTIF($D5:$BC5,"DERMATOLOGY *") | CB5: =COUNTIF($D5:$BC5,"NEPHRO")+COUNTIF($D5:$BC5,"NEPHRO *") | CC5: =SUM(BQ5:CB5) | CD5: =BP5+CC5
B6: PGY-2 | C6: M. Garcia | D6: CLINIC * | E6: B | F6: B | G6: B | H6: B | I6: CLINIC * | J6: ICU N | K6: ICU N | L6: SWING | M6: SWING | N6: CLINIC * | O6: NEURO | P6: NEURO | Q6: ID | R6: ID | S6: CLINIC * | T6: C | U6: C | V6: C | W6: C | X6: CLINIC * | Y6: ED | Z6: ED | AA6: CARDIO | AB6: CARDIO | AC6: CARDIO | AD6: CARDIO | AE6: CLINIC * | AF6: ICU | AG6: ICU | AH6: ICU | AI6: NF | AJ6: CLINIC * | AK6: C | AL6: NF | AM6: NF | AN6: NF | AO6: CLINIC * | AP6: VACATION | AQ6: VACATION | AR6: VACATION | AS6: VACATION | AT6: CLINIC * | AU6: SWING | AV6: ICU | AW6: ICU | AX6: ICU | AY6: CLINIC | AZ6: CLINIC | BA6: CLINIC | BB6: CLINIC | BC6: CLINIC | BD6: =COUNTIF($D6:$BC6,"CARDIO")+COUNTIF($D6:$BC6,"CARDIO E")+COUNTIF($D6:$BC6,"CARDIO E *")+COUNTIF($D6:$BC6,"CARDIO-HCA")+COUNTIF($D6:$BC6,"CARDIO-HCA *")+COUNTIF($D6:$BC6,"CARDIO-RAM")+COUNTIF($D6:$BC6,"CARDIO-RAM *") | BE6: =COUNTIF($D6:$BC6,"CLINIC")+COUNTIF($D6:$BC6,"CLINIC *")+COUNTIF($D6:$BC6,"URGENT CARE")+COUNTIF($D6:$BC6,"URGENT CARE *") | BF6: =COUNTIF($D6:$BC6,"ED") | BG6: =COUNTIF($D6:$BC6,"A")+COUNTIF($D6:$BC6,"B")+COUNTIF($D6:$BC6,"C")+COUNTIF($D6:$BC6,"D")+COUNTIF($D6:$BC6,"G") | BH6: =COUNTIF($D6:$BC6,"ICU") | BI6: =COUNTIF($D6:$BC6,"ICU E") | BJ6: =COUNTIF($D6:$BC6,"ICU N") | BK6: =COUNTIF($D6:$BC6,"ID")+COUNTIF($D6:$BC6,"ID *") | BL6: =COUNTIF($D6:$BC6,"NEURO")+COUNTIF($D6:$BC6,"NEURO *") | BM6: =COUNTIF($D6:$BC6,"NF") | BN6: =COUNTIF($D6:$BC6,"SWING") | BO6: =COUNTIF($D6:$BC6,"VACATION") | BP6: =SUM(BD6:BO6) | BQ6: =COUNTIF($D6:$BC6,"PALLIATIVE")+COUNTIF($D6:$BC6,"PALLIATIVE *") | BR6: =COUNTIF($D6:$BC6,"GERIATRIC")+COUNTIF($D6:$BC6,"GERIATRIC 2") | BS6: =COUNTIF($D6:$BC6,"GS")+COUNTIF($D6:$BC6,"GI")+COUNTIF($D6:$BC6,"GI *") | BT6: =COUNTIF($D6:$BC6,"HEM/ONC")+COUNTIF($D6:$BC6,"HEM/ONC *") | BU6: =COUNTIF($D6:$BC6,"PAIN MANAGEMENT")+COUNTIF($D6:$BC6,"PAIN MANAGEMENT *") | BV6: =COUNTIF($D6:$BC6,"RHEUMA")+COUNTIF($D6:$BC6,"RHEUMA *") | BW6: =COUNTIF($D6:$BC6,"ENDO")+COUNTIF($D6:$BC6,"ENDO *") | BX6: =COUNTIF($D6:$BC6,"PLASTIC")+COUNTIF($D6:$BC6,"PLASTIC *") | BY6: =COUNTIF($D6:$BC6,"PULM")+COUNTIF($D6:$BC6,"PULM *") | BZ6: =COUNTIF($D6:$BC6,"SICU")+COUNTIF($D6:$BC6,"SICU *") | CA6: =COUNTIF($D6:$BC6,"DERMATOLOGY")+COUNTIF($D6:$BC6,"DERMATOLOGY *") | CB6: =COUNTIF($D6:$BC6,"NEPHRO")+COUNTIF($D6:$BC6,"NEPHRO *") | CC6: =SUM(BQ6:CB6) | CD6: =BP6+CC6
C7: D. Cano | D7: CLINIC * | E7: D | F7: D | G7: NEURO | H7: NEURO | I7: CLINIC | J7: D | K7: D | L7: D | M7: ED | N7: CLINIC * | O7: D | P7: D | Q7: D | R7: D | S7: CLINIC * | T7: CARDIO | U7: CARDIO | V7: CARDIO | W7: CARDIO | X7: CLINIC * | Y7: ED | Z7: ID | AA7: ID | AB7: C | AC7: ICU E | AD7: ICU E | AE7: CLINIC * | AF7: VACATION | AG7: VACATION | AH7: VACATION | AI7: VACATION | AJ7: CLINIC * | AK7: ICU N | AL7: ICU N | AM7: ICU N | AN7: CLINIC | AO7: CLINIC | AP7: ICU N | AQ7: ICU N | AR7: SWING | AS7: SWING | AT7: CLINIC * | AU7: D | AV7: D | AW7: D | AX7: D | AY7: CLINIC | AZ7: CLINIC | BA7: CLINIC | BB7: CLINIC | BC7: ICU E | BD7: =COUNTIF($D7:$BC7,"CARDIO")+COUNTIF($D7:$BC7,"CARDIO E")+COUNTIF($D7:$BC7,"CARDIO E *")+COUNTIF($D7:$BC7,"CARDIO-HCA")+COUNTIF($D7:$BC7,"CARDIO-HCA *")+COUNTIF($D7:$BC7,"CARDIO-RAM")+COUNTIF($D7:$BC7,"CARDIO-RAM *") | BE7: =COUNTIF($D7:$BC7,"CLINIC")+COUNTIF($D7:$BC7,"CLINIC *")+COUNTIF($D7:$BC7,"URGENT CARE")+COUNTIF($D7:$BC7,"URGENT CARE *") | BF7: =COUNTIF($D7:$BC7,"ED") | BG7: =COUNTIF($D7:$BC7,"A")+COUNTIF($D7:$BC7,"B")+COUNTIF($D7:$BC7,"C")+COUNTIF($D7:$BC7,"D")+COUNTIF($D7:$BC7,"G") | BH7: =COUNTIF($D7:$BC7,"ICU") | BI7: =COUNTIF($D7:$BC7,"ICU E") | BJ7: =COUNTIF($D7:$BC7,"ICU N") | BK7: =COUNTIF($D7:$BC7,"ID")+COUNTIF($D7:$BC7,"ID *") | BL7: =COUNTIF($D7:$BC7,"NEURO")+COUNTIF($D7:$BC7,"NEURO *") | BM7: =COUNTIF($D7:$BC7,"NF") | BN7: =COUNTIF($D7:$BC7,"SWING") | BO7: =COUNTIF($D7:$BC7,"VACATION") | BP7: =SUM(BD7:BO7) | BQ7: =COUNTIF($D7:$BC7,"PALLIATIVE")+COUNTIF($D7:$BC7,"PALLIATIVE *") | BR7: =COUNTIF($D7:$BC7,"GERIATRIC")+COUNTIF($D7:$BC7,"GERIATRIC 2") | BS7: =COUNTIF($D7:$BC7,"GS")+COUNTIF($D7:$BC7,"GI")+COUNTIF($D7:$BC7,"GI *") | BT7: =COUNTIF($D7:$BC7,"HEM/ONC")+COUNTIF($D7:$BC7,"HEM/ONC *") | BU7: =COUNTIF($D7:$BC7,"PAIN MANAGEMENT")+COUNTIF($D7:$BC7,"PAIN MANAGEMENT *") | BV7: =COUNTIF($D7:$BC7,"RHEUMA")+COUNTIF($D7:$BC7,"RHEUMA *") | BW7: =COUNTIF($D7:$BC7,"ENDO")+COUNTIF($D7:$BC7,"ENDO *") | BX7: =COUNTIF($D7:$BC7,"PLASTIC")+COUNTIF($D7:$BC7,"PLASTIC *") | BY7: =COUNTIF($D7:$BC7,"PULM")+COUNTIF($D7:$BC7,"PULM *") | BZ7: =COUNTIF($D7:$BC7,"SICU")+COUNTIF($D7:$BC7,"SICU *") | CA7: =COUNTIF($D7:$BC7,"DERMATOLOGY")+COUNTIF($D7:$BC7,"DERMATOLOGY *") | CB7: =COUNTIF($D7:$BC7,"NEPHRO")+COUNTIF($D7:$BC7,"NEPHRO *") | CC7: =SUM(BQ7:CB7) | CD7: =BP7+CC7
B8: PGY-3 | C8: J. Melendez | D8: CLINIC * | E8: C | F8: C | G8: C | H8: C | I8: CLINIC * | J8: CLINIC * | K8: CLINIC * | L8: ICU E | M8: ICU E | N8: CLINIC * | O8: C | P8: C | Q8: C | R8: C | S8: CLINIC * | T8: VACATION | U8: ICU | V8: ICU | W8: CLINIC * | X8: CLINIC * | Y8: CLINIC * | Z8: CLINIC * | AA8: ICU E | AB8: ICU E | AC8: ICU E | AD8: ICU E | AE8: CLINIC * | AF8: CLINIC * | AG8: VACATION | AH8: VACATION | AI8: VACATION | AJ8: CLINIC * | AK8: SWING | AL8: SWING | AM8: SWING | AN8: SWING | AO8: CLINIC * | AP8: D | AQ8: D | AR8: D | AS8: CLINIC | AT8: CLINIC | AU8: CLINIC | AV8: CLINIC | AW8: CLINIC | AX8: CLINIC | AY8: CLINIC | AZ8: ICU N | BA8: ICU N | BB8: CLINIC * | BC8: SWING | BD8: =COUNTIF($D8:$BC8,"CARDIO")+COUNTIF($D8:$BC8,"CARDIO E")+COUNTIF($D8:$BC8,"CARDIO E *")+COUNTIF($D8:$BC8,"CARDIO-HCA")+COUNTIF($D8:$BC8,"CARDIO-HCA *")+COUNTIF($D8:$BC8,"CARDIO-RAM")+COUNTIF($D8:$BC8,"CARDIO-RAM *") | BE8: =COUNTIF($D8:$BC8,"CLINIC")+COUNTIF($D8:$BC8,"CLINIC *")+COUNTIF($D8:$BC8,"URGENT CARE")+COUNTIF($D8:$BC8,"URGENT CARE *") | BF8: =COUNTIF($D8:$BC8,"ED") | BG8: =COUNTIF($D8:$BC8,"A")+COUNTIF($D8:$BC8,"B")+COUNTIF($D8:$BC8,"C")+COUNTIF($D8:$BC8,"D")+COUNTIF($D8:$BC8,"G") | BH8: =COUNTIF($D8:$BC8,"ICU") | BI8: =COUNTIF($D8:$BC8,"ICU E") | BJ8: =COUNTIF($D8:$BC8,"ICU N") | BK8: =COUNTIF($D8:$BC8,"ID")+COUNTIF($D8:$BC8,"ID *") | BL8: =COUNTIF($D8:$BC8,"NEURO")+COUNTIF($D8:$BC8,"NEURO *") | BM8: =COUNTIF($D8:$BC8,"NF") | BN8: =COUNTIF($D8:$BC8,"SWING") | BO8: =COUNTIF($D8:$BC8,"VACATION") | BP8: =SUM(BD8:BO8) | BQ8: =COUNTIF($D8:$BC8,"PALLIATIVE")+COUNTIF($D8:$BC8,"PALLIATIVE *") | BR8: =COUNTIF($D8:$BC8,"GERIATRIC")+COUNTIF($D8:$BC8,"GERIATRIC 2") | BS8: =COUNTIF($D8:$BC8,"GS")+COUNTIF($D8:$BC8,"GI")+COUNTIF($D8:$BC8,"GI *") | BT8: =COUNTIF($D8:$BC8,"HEM/ONC")+COUNTIF($D8:$BC8,"HEM/ONC *") | BU8: =COUNTIF($D8:$BC8,"PAIN MANAGEMENT")+COUNTIF($D8:$BC8,"PAIN MANAGEMENT *") | BV8: =COUNTIF($D8:$BC8,"RHEUMA")+COUNTIF($D8:$BC8,"RHEUMA *") | BW8: =COUNTIF($D8:$BC8,"ENDO")+COUNTIF($D8:$BC8,"ENDO *") | BX8: =COUNTIF($D8:$BC8,"PLASTIC")+COUNTIF($D8:$BC8,"PLASTIC *") | BY8: =COUNTIF($D8:$BC8,"PULM")+COUNTIF($D8:$BC8,"PULM *") | BZ8: =COUNTIF($D8:$BC8,"SICU")+COUNTIF($D8:$BC8,"SICU *") | CA8: =COUNTIF($D8:$BC8,"DERMATOLOGY")+COUNTIF($D8:$BC8,"DERMATOLOGY *") | CB8: =COUNTIF($D8:$BC8,"NEPHRO")+COUNTIF($D8:$BC8,"NEPHRO *") | CC8: =SUM(BQ8:CB8) | CD8: =BP8+CC8
C9: C. Correa | D9: CLINIC * | E9: VACATION | F9: VACATION | G9: VACATION | H9: VACATION | I9: CLINIC * | J9: C | K9: C | L9: ICU N | M9: ICU N | N9: CLINIC * | O9: NF | P9: NF | Q9: NF | R9: NF | S9: CLINIC * | T9: CLINIC * | U9: ICU E | V9: ICU E | W9: CLINIC * | X9: CLINIC * | Y9: A | Z9: A | AA9: A | AB9: A | AC9: A | AD9: A | AE9: CLINIC * | AF9: B | AG9: B | AH9: B | AI9: CLINIC * | AJ9: CLINIC * | AK9: CLINIC * | AL9: CLINIC | AM9: CLINIC | AN9: CLINIC | AO9: CLINIC | AP9: CLINIC | AQ9: ICU | AR9: ICU | AS9: ICU | AT9: CLINIC | AU9: CLINIC | AV9: CLINIC | AW9: G | AX9: G | AY9: CLINIC * | AZ9: CLINIC * | BA9: ICU E | BB9: CLINIC | BC9: CLINIC | BD9: =COUNTIF($D9:$BC9,"CARDIO")+COUNTIF($D9:$BC9,"CARDIO E")+COUNTIF($D9:$BC9,"CARDIO E *")+COUNTIF($D9:$BC9,"CARDIO-HCA")+COUNTIF($D9:$BC9,"CARDIO-HCA *")+COUNTIF($D9:$BC9,"CARDIO-RAM")+COUNTIF($D9:$BC9,"CARDIO-RAM *") | BE9: =COUNTIF($D9:$BC9,"CLINIC")+COUNTIF($D9:$BC9,"CLINIC *")+COUNTIF($D9:$BC9,"URGENT CARE")+COUNTIF($D9:$BC9,"URGENT CARE *") | BF9: =COUNTIF($D9:$BC9,"ED") | BG9: =COUNTIF($D9:$BC9,"A")+COUNTIF($D9:$BC9,"B")+COUNTIF($D9:$BC9,"C")+COUNTIF($D9:$BC9,"D")+COUNTIF($D9:$BC9,"G") | BH9: =COUNTIF($D9:$BC9,"ICU") | BI9: =COUNTIF($D9:$BC9,"ICU E") | BJ9: =COUNTIF($D9:$BC9,"ICU N") | BK9: =COUNTIF($D9:$BC9,"ID")+COUNTIF($D9:$BC9,"ID *") | BL9: =COUNTIF($D9:$BC9,"NEURO")+COUNTIF($D9:$BC9,"NEURO *") | BM9: =COUNTIF($D9:$BC9,"NF") | BN9: =COUNTIF($D9:$BC9,"SWING") | BO9: =COUNTIF($D9:$BC9,"VACATION") | BP9: =SUM(BD9:BO9) | BQ9: =COUNTIF($D9:$BC9,"PALLIATIVE")+COUNTIF($D9:$BC9,"PALLIATIVE *") | BR9: =COUNTIF($D9:$BC9,"GERIATRIC")+COUNTIF($D9:$BC9,"GERIATRIC 2") | BS9: =COUNTIF($D9:$BC9,"GS")+COUNTIF($D9:$BC9,"GI")+COUNTIF($D9:$BC9,"GI *") | BT9: =COUNTIF($D9:$BC9,"HEM/ONC")+COUNTIF($D9:$BC9,"HEM/ONC *") | BU9: =COUNTIF($D9:$BC9,"PAIN MANAGEMENT")+COUNTIF($D9:$BC9,"PAIN MANAGEMENT *") | BV9: =COUNTIF($D9:$BC9,"RHEUMA")+COUNTIF($D9:$BC9,"RHEUMA *") | BW9: =COUNTIF($D9:$BC9,"ENDO")+COUNTIF($D9:$BC9,"ENDO *") | BX9: =COUNTIF($D9:$BC9,"PLASTIC")+COUNTIF($D9:$BC9,"PLASTIC *") | BY9: =COUNTIF($D9:$BC9,"PULM")+COUNTIF($D9:$BC9,"PULM *") | BZ9: =COUNTIF($D9:$BC9,"SICU")+COUNTIF($D9:$BC9,"SICU *") | CA9: =COUNTIF($D9:$BC9,"DERMATOLOGY")+COUNTIF($D9:$BC9,"DERMATOLOGY *") | CB9: =COUNTIF($D9:$BC9,"NEPHRO")+COUNTIF($D9:$BC9,"NEPHRO *") | CC9: =SUM(BQ9:CB9) | CD9: =BP9+CC9
C10: L. Diaz-Fajardo | D10: CLINIC * | E10: CLINIC * | F10: ICU | G10: ICU | H10: ICU | I10: CLINIC * | J10: SWING | K10: SWING | L10: SWING | M10: SWING | N10: CLINIC * | O10: CLINIC * | P10: CLINIC * | Q10: CLINIC * | R10: CLINIC * | S10: CLINIC * | T10: CLINIC * | U10: CLINIC * | V10: CLINIC * | W10: CLINIC * | X10: CLINIC * | Y10: B | Z10: B | AA10: B | AB10: B | AC10: VACATION | AD10: VACATION | AE10: CLINIC * | AF10: D | AG10: D | AH10: D | AI10: D | AJ10: CLINIC * | AK10: VACATION | AL10: VACATION | AM10: ICU | AN10: ICU | AO10: CLINIC | AP10: CLINIC | AQ10: ICU E | AR10: ICU E | AS10: CLINIC * | AT10: CLINIC * | AU10: A | AV10: A | AW10: A | AX10: A | AY10: CLINIC | AZ10: CLINIC | BA10: CLINIC | BB10: CLINIC | BC10: CLINIC | BD10: =COUNTIF($D10:$BC10,"CARDIO")+COUNTIF($D10:$BC10,"CARDIO E")+COUNTIF($D10:$BC10,"CARDIO E *")+COUNTIF($D10:$BC10,"CARDIO-HCA")+COUNTIF($D10:$BC10,"CARDIO-HCA *")+COUNTIF($D10:$BC10,"CARDIO-RAM")+COUNTIF($D10:$BC10,"CARDIO-RAM *") | BE10: =COUNTIF($D10:$BC10,"CLINIC")+COUNTIF($D10:$BC10,"CLINIC *")+COUNTIF($D10:$BC10,"URGENT CARE")+COUNTIF($D10:$BC10,"URGENT CARE *") | BF10: =COUNTIF($D10:$BC10,"ED") | BG10: =COUNTIF($D10:$BC10,"A")+COUNTIF($D10:$BC10,"B")+COUNTIF($D10:$BC10,"C")+COUNTIF($D10:$BC10,"D")+COUNTIF($D10:$BC10,"G") | BH10: =COUNTIF($D10:$BC10,"ICU") | BI10: =COUNTIF($D10:$BC10,"ICU E") | BJ10: =COUNTIF($D10:$BC10,"ICU N") | BK10: =COUNTIF($D10:$BC10,"ID")+COUNTIF($D10:$BC10,"ID *") | BL10: =COUNTIF($D10:$BC10,"NEURO")+COUNTIF($D10:$BC10,"NEURO *") | BM10: =COUNTIF($D10:$BC10,"NF") | BN10: =COUNTIF($D10:$BC10,"SWING") | BO10: =COUNTIF($D10:$BC10,"VACATION") | BP10: =SUM(BD10:BO10) | BQ10: =COUNTIF($D10:$BC10,"PALLIATIVE")+COUNTIF($D10:$BC10,"PALLIATIVE *") | BR10: =COUNTIF($D10:$BC10,"GERIATRIC")+COUNTIF($D10:$BC10,"GERIATRIC 2") | BS10: =COUNTIF($D10:$BC10,"GS")+COUNTIF($D10:$BC10,"GI")+COUNTIF($D10:$BC10,"GI *") | BT10: =COUNTIF($D10:$BC10,"HEM/ONC")+COUNTIF($D10:$BC10,"HEM/ONC *") | BU10: =COUNTIF($D10:$BC10,"PAIN MANAGEMENT")+COUNTIF($D10:$BC10,"PAIN MANAGEMENT *") | BV10: =COUNTIF($D10:$BC10,"RHEUMA")+COUNTIF($D10:$BC10,"RHEUMA *") | BW10: =COUNTIF($D10:$BC10,"ENDO")+COUNTIF($D10:$BC10,"ENDO *") | BX10: =COUNTIF($D10:$BC10,"PLASTIC")+COUNTIF($D10:$BC10,"PLASTIC *") | BY10: =COUNTIF($D10:$BC10,"PULM")+COUNTIF($D10:$BC10,"PULM *") | BZ10: =COUNTIF($D10:$BC10,"SICU")+COUNTIF($D10:$BC10,"SICU *") | CA10: =COUNTIF($D10:$BC10,"DERMATOLOGY")+COUNTIF($D10:$BC10,"DERMATOLOGY *") | CB10: =COUNTIF($D10:$BC10,"NEPHRO")+COUNTIF($D10:$BC10,"NEPHRO *") | CC10: =SUM(BQ10:CB10) | CD10: =BP10+CC10
C11: J. Garcia-Blaya | D11: CLINIC * | E11: CLINIC * | F11: CLINIC * | G11: CLINIC * | H11: CLINIC * | I11: CLINIC * | J11: CLINIC * | K11: CLINIC * | L11: CLINIC * | M11: CLINIC * | N11: CLINIC * | O11: CLINIC * | P11: CLINIC * | Q11: CLINIC * | R11: CLINIC * | S11: CLINIC * | T11: B | U11: VACATION | V11: VACATION | W11: VACATION | X11: CLINIC | Y11: CLINIC | Z11: CLINIC | AA11: C | AB11: C | AC11: C | AD11: C | AE11: CLINIC * | AF11: ICU N | AG11: ICU N | AH11: ICU N | AI11: ICU N | AJ11: CLINIC * | AK11: B | AL11: B | AM11: B | AN11: B | AO11: CLINIC * | AP11: CLINIC * | AQ11: B | AR11: B | AS11: B | AT11: CLINIC * | AU11: C | AV11: NF | AW11: NF | AX11: CLINIC * | AY11: CLINIC * | AZ11: VACATION | BA11: C | BB11: CLINIC * | BC11: CLINIC * | BD11: =COUNTIF($D11:$BC11,"CARDIO")+COUNTIF($D11:$BC11,"CARDIO E")+COUNTIF($D11:$BC11,"CARDIO E *")+COUNTIF($D11:$BC11,"CARDIO-HCA")+COUNTIF($D11:$BC11,"CARDIO-HCA *")+COUNTIF($D11:$BC11,"CARDIO-RAM")+COUNTIF($D11:$BC11,"CARDIO-RAM *") | BE11: =COUNTIF($D11:$BC11,"CLINIC")+COUNTIF($D11:$BC11,"CLINIC *")+COUNTIF($D11:$BC11,"URGENT CARE")+COUNTIF($D11:$BC11,"URGENT CARE *") | BF11: =COUNTIF($D11:$BC11,"ED") | BG11: =COUNTIF($D11:$BC11,"A")+COUNTIF($D11:$BC11,"B")+COUNTIF($D11:$BC11,"C")+COUNTIF($D11:$BC11,"D")+COUNTIF($D11:$BC11,"G") | BH11: =COUNTIF($D11:$BC11,"ICU") | BI11: =COUNTIF($D11:$BC11,"ICU E") | BJ11: =COUNTIF($D11:$BC11,"ICU N") | BK11: =COUNTIF($D11:$BC11,"ID")+COUNTIF($D11:$BC11,"ID *") | BL11: =COUNTIF($D11:$BC11,"NEURO")+COUNTIF($D11:$BC11,"NEURO *") | BM11: =COUNTIF($D11:$BC11,"NF") | BN11: =COUNTIF($D11:$BC11,"SWING") | BO11: =COUNTIF($D11:$BC11,"VACATION") | BP11: =SUM(BD11:BO11) | BQ11: =COUNTIF($D11:$BC11,"PALLIATIVE")+COUNTIF($D11:$BC11,"PALLIATIVE *") | BR11: =COUNTIF($D11:$BC11,"GERIATRIC")+COUNTIF($D11:$BC11,"GERIATRIC 2") | BS11: =COUNTIF($D11:$BC11,"GS")+COUNTIF($D11:$BC11,"GI")+COUNTIF($D11:$BC11,"GI *") | BT11: =COUNTIF($D11:$BC11,"HEM/ONC")+COUNTIF($D11:$BC11,"HEM/ONC *") | BU11: =COUNTIF($D11:$BC11,"PAIN MANAGEMENT")+COUNTIF($D11:$BC11,"PAIN MANAGEMENT *") | BV11: =COUNTIF($D11:$BC11,"RHEUMA")+COUNTIF($D11:$BC11,"RHEUMA *") | BW11: =COUNTIF($D11:$BC11,"ENDO")+COUNTIF($D11:$BC11,"ENDO *") | BX11: =COUNTIF($D11:$BC11,"PLASTIC")+COUNTIF($D11:$BC11,"PLASTIC *") | BY11: =COUNTIF($D11:$BC11,"PULM")+COUNTIF($D11:$BC11,"PULM *") | BZ11: =COUNTIF($D11:$BC11,"SICU")+COUNTIF($D11:$BC11,"SICU *") | CA11: =COUNTIF($D11:$BC11,"DERMATOLOGY")+COUNTIF($D11:$BC11,"DERMATOLOGY *") | CB11: =COUNTIF($D11:$BC11,"NEPHRO")+COUNTIF($D11:$BC11,"NEPHRO *") | CC11: =SUM(BQ11:CB11) | CD11: =BP11+CC11
A12: Cohort 2 | B12: PGY-1 | C12: J. Jhooty | D12: CLINIC * | E12: CLINIC * | F12: A | G12: A | H12: A | I12: A | J12: CLINIC * | K12: ICU E | L12: ICU E | M12: ID | N12: ID | O12: CLINIC * | P12: ICU | Q12: ICU | R12: ICU | S12: ICU | T12: CLINIC * | U12: VACATION | V12: VACATION | W12: VACATION | X12: CLINIC * | Y12: CLINIC * | Z12: SWING | AA12: SWING | AB12: SWING | AC12: SWING | AD12: CARDIO | AE12: CARDIO | AF12: CLINIC * | AG12: B | AH12: B | AI12: B | AJ12: CLINIC | AK12: CLINIC | AL12: ICU N | AM12: ICU N | AN12: D | AO12: D | AP12: CLINIC * | AQ12: NF | AR12: NF | AS12: NF | AT12: NF | AU12: CLINIC | AV12: CLINIC | AW12: VACATION | AX12: ED | AY12: ED | AZ12: CLINIC * | BA12: D | BB12: D | BC12: D | BD12: =COUNTIF($D12:$BC12,"CARDIO")+COUNTIF($D12:$BC12,"CARDIO E")+COUNTIF($D12:$BC12,"CARDIO E *")+COUNTIF($D12:$BC12,"CARDIO-HCA")+COUNTIF($D12:$BC12,"CARDIO-HCA *")+COUNTIF($D12:$BC12,"CARDIO-RAM")+COUNTIF($D12:$BC12,"CARDIO-RAM *") | BE12: =COUNTIF($D12:$BC12,"CLINIC")+COUNTIF($D12:$BC12,"CLINIC *")+COUNTIF($D12:$BC12,"URGENT CARE")+COUNTIF($D12:$BC12,"URGENT CARE *") | BF12: =COUNTIF($D12:$BC12,"ED") | BG12: =COUNTIF($D12:$BC12,"A")+COUNTIF($D12:$BC12,"B")+COUNTIF($D12:$BC12,"C")+COUNTIF($D12:$BC12,"D")+COUNTIF($D12:$BC12,"G") | BH12: =COUNTIF($D12:$BC12,"ICU") | BI12: =COUNTIF($D12:$BC12,"ICU E") | BJ12: =COUNTIF($D12:$BC12,"ICU N") | BK12: =COUNTIF($D12:$BC12,"ID")+COUNTIF($D12:$BC12,"ID *") | BL12: =COUNTIF($D12:$BC12,"NEURO")+COUNTIF($D12:$BC12,"NEURO *") | BM12: =COUNTIF($D12:$BC12,"NF") | BN12: =COUNTIF($D12:$BC12,"SWING") | BO12: =COUNTIF($D12:$BC12,"VACATION") | BP12: =SUM(BD12:BO12) | BQ12: =COUNTIF($D12:$BC12,"PALLIATIVE")+COUNTIF($D12:$BC12,"PALLIATIVE *") | BR12: =COUNTIF($D12:$BC12,"GERIATRIC")+COUNTIF($D12:$BC12,"GERIATRIC 2") | BS12: =COUNTIF($D12:$BC12,"GS")+COUNTIF($D12:$BC12,"GI")+COUNTIF($D12:$BC12,"GI *") | BT12: =COUNTIF($D12:$BC12,"HEM/ONC")+COUNTIF($D12:$BC12,"HEM/ONC *") | BU12: =COUNTIF($D12:$BC12,"PAIN MANAGEMENT")+COUNTIF($D12:$BC12,"PAIN MANAGEMENT *") | BV12: =COUNTIF($D12:$BC12,"RHEUMA")+COUNTIF($D12:$BC12,"RHEUMA *") | BW12: =COUNTIF($D12:$BC12,"ENDO")+COUNTIF($D12:$BC12,"ENDO *") | BX12: =COUNTIF($D12:$BC12,"PLASTIC")+COUNTIF($D12:$BC12,"PLASTIC *") | BY12: =COUNTIF($D12:$BC12,"PULM")+COUNTIF($D12:$BC12,"PULM *") | BZ12: =COUNTIF($D12:$BC12,"SICU")+COUNTIF($D12:$BC12,"SICU *") | CA12: =COUNTIF($D12:$BC12,"DERMATOLOGY")+COUNTIF($D12:$BC12,"DERMATOLOGY *") | CB12: =COUNTIF($D12:$BC12,"NEPHRO")+COUNTIF($D12:$BC12,"NEPHRO *") | CC12: =SUM(BQ12:CB12) | CD12: =BP12+CC12
C13: M. Artavia | D13: ICU N | E13: CLINIC * | F13: CLINIC * | G13: NF | H13: CARDIO-HCA | I13: CARDIO | J13: CLINIC * | K13: ICU N | L13: ICU N | M13: VACATION | N13: D | O13: CLINIC * | P13: D | Q13: D | R13: D | S13: D | T13: CLINIC * | U13: B | V13: B | W13: ICU E | X13: ICU E | Y13: CLINIC | Z13: CLINIC | AA13: B | AB13: B | AC13: D | AD13: D | AE13: D | AF13: CLINIC * | AG13: VACATION | AH13: VACATION | AI13: VACATION | AJ13: ICU N | AK13: CLINIC * | AL13: A | AM13: A | AN13: A | AO13: CLINIC | AP13: CLINIC | AQ13: B | AR13: B | AS13: B | AT13: CLINIC | AU13: CLINIC | AV13: ICU E | AW13: ICU E | AX13: ID | AY13: ID | AZ13: CLINIC * | BA13: ED | BB13: ED | BC13: C | BD13: =COUNTIF($D13:$BC13,"CARDIO")+COUNTIF($D13:$BC13,"CARDIO E")+COUNTIF($D13:$BC13,"CARDIO E *")+COUNTIF($D13:$BC13,"CARDIO-HCA")+COUNTIF($D13:$BC13,"CARDIO-HCA *")+COUNTIF($D13:$BC13,"CARDIO-RAM")+COUNTIF($D13:$BC13,"CARDIO-RAM *") | BE13: =COUNTIF($D13:$BC13,"CLINIC")+COUNTIF($D13:$BC13,"CLINIC *")+COUNTIF($D13:$BC13,"URGENT CARE")+COUNTIF($D13:$BC13,"URGENT CARE *") | BF13: =COUNTIF($D13:$BC13,"ED") | BG13: =COUNTIF($D13:$BC13,"A")+COUNTIF($D13:$BC13,"B")+COUNTIF($D13:$BC13,"C")+COUNTIF($D13:$BC13,"D")+COUNTIF($D13:$BC13,"G") | BH13: =COUNTIF($D13:$BC13,"ICU") | BI13: =COUNTIF($D13:$BC13,"ICU E") | BJ13: =COUNTIF($D13:$BC13,"ICU N") | BK13: =COUNTIF($D13:$BC13,"ID")+COUNTIF($D13:$BC13,"ID *") | BL13: =COUNTIF($D13:$BC13,"NEURO")+COUNTIF($D13:$BC13,"NEURO *") | BM13: =COUNTIF($D13:$BC13,"NF") | BN13: =COUNTIF($D13:$BC13,"SWING") | BO13: =COUNTIF($D13:$BC13,"VACATION") | BP13: =SUM(BD13:BO13) | BQ13: =COUNTIF($D13:$BC13,"PALLIATIVE")+COUNTIF($D13:$BC13,"PALLIATIVE *") | BR13: =COUNTIF($D13:$BC13,"GERIATRIC")+COUNTIF($D13:$BC13,"GERIATRIC 2") | BS13: =COUNTIF($D13:$BC13,"GS")+COUNTIF($D13:$BC13,"GI")+COUNTIF($D13:$BC13,"GI *") | BT13: =COUNTIF($D13:$BC13,"HEM/ONC")+COUNTIF($D13:$BC13,"HEM/ONC *") | BU13: =COUNTIF($D13:$BC13,"PAIN MANAGEMENT")+COUNTIF($D13:$BC13,"PAIN MANAGEMENT *") | BV13: =COUNTIF($D13:$BC13,"RHEUMA")+COUNTIF($D13:$BC13,"RHEUMA *") | BW13: =COUNTIF($D13:$BC13,"ENDO")+COUNTIF($D13:$BC13,"ENDO *") | BX13: =COUNTIF($D13:$BC13,"PLASTIC")+COUNTIF($D13:$BC13,"PLASTIC *") | BY13: =COUNTIF($D13:$BC13,"PULM")+COUNTIF($D13:$BC13,"PULM *") | BZ13: =COUNTIF($D13:$BC13,"SICU")+COUNTIF($D13:$BC13,"SICU *") | CA13: =COUNTIF($D13:$BC13,"DERMATOLOGY")+COUNTIF($D13:$BC13,"DERMATOLOGY *") | CB13: =COUNTIF($D13:$BC13,"NEPHRO")+COUNTIF($D13:$BC13,"NEPHRO *") | CC13: =SUM(BQ13:CB13) | CD13: =BP13+CC13
C14: M. Delgadillo | D14: VACATION | E14: CLINIC * | F14: D | G14: D | H14: D | I14: D | J14: CLINIC * | K14: ED | L14: ED | M14: ICU E | N14: ICU E | O14: CLINIC * | P14: B | Q14: B | R14: B | S14: B | T14: CLINIC * | U14: ICU N | V14: ICU N | W14: D | X14: D | Y14: CLINIC * | Z14: SWING | AA14: B | AB14: B | AC14: B | AD14: B | AE14: CLINIC * | AF14: CLINIC * | AG14: ICU | AH14: ICU | AI14: ICU | AJ14: CLINIC * | AK14: CLINIC * | AL14: CLINIC * | AM14: C | AN14: C | AO14: C | AP14: CLINIC | AQ14: CLINIC | AR14: CARDIO-HCA | AS14: CARDIO-HCA | AT14: ICU E | AU14: CLINIC * | AV14: NF | AW14: NF | AX14: ID | AY14: ID | AZ14: CLINIC * | BA14: VACATION | BB14: VACATION | BC14: VACATION | BD14: =COUNTIF($D14:$BC14,"CARDIO")+COUNTIF($D14:$BC14,"CARDIO E")+COUNTIF($D14:$BC14,"CARDIO E *")+COUNTIF($D14:$BC14,"CARDIO-HCA")+COUNTIF($D14:$BC14,"CARDIO-HCA *")+COUNTIF($D14:$BC14,"CARDIO-RAM")+COUNTIF($D14:$BC14,"CARDIO-RAM *") | BE14: =COUNTIF($D14:$BC14,"CLINIC")+COUNTIF($D14:$BC14,"CLINIC *")+COUNTIF($D14:$BC14,"URGENT CARE")+COUNTIF($D14:$BC14,"URGENT CARE *") | BF14: =COUNTIF($D14:$BC14,"ED") | BG14: =COUNTIF($D14:$BC14,"A")+COUNTIF($D14:$BC14,"B")+COUNTIF($D14:$BC14,"C")+COUNTIF($D14:$BC14,"D")+COUNTIF($D14:$BC14,"G") | BH14: =COUNTIF($D14:$BC14,"ICU") | BI14: =COUNTIF($D14:$BC14,"ICU E") | BJ14: =COUNTIF($D14:$BC14,"ICU N") | BK14: =COUNTIF($D14:$BC14,"ID")+COUNTIF($D14:$BC14,"ID *") | BL14: =COUNTIF($D14:$BC14,"NEURO")+COUNTIF($D14:$BC14,"NEURO *") | BM14: =COUNTIF($D14:$BC14,"NF") | BN14: =COUNTIF($D14:$BC14,"SWING") | BO14: =COUNTIF($D14:$BC14,"VACATION") | BP14: =SUM(BD14:BO14) | BQ14: =COUNTIF($D14:$BC14,"PALLIATIVE")+COUNTIF($D14:$BC14,"PALLIATIVE *") | BR14: =COUNTIF($D14:$BC14,"GERIATRIC")+COUNTIF($D14:$BC14,"GERIATRIC 2") | BS14: =COUNTIF($D14:$BC14,"GS")+COUNTIF($D14:$BC14,"GI")+COUNTIF($D14:$BC14,"GI *") | BT14: =COUNTIF($D14:$BC14,"HEM/ONC")+COUNTIF($D14:$BC14,"HEM/ONC *") | BU14: =COUNTIF($D14:$BC14,"PAIN MANAGEMENT")+COUNTIF($D14:$BC14,"PAIN MANAGEMENT *") | BV14: =COUNTIF($D14:$BC14,"RHEUMA")+COUNTIF($D14:$BC14,"RHEUMA *") | BW14: =COUNTIF($D14:$BC14,"ENDO")+COUNTIF($D14:$BC14,"ENDO *") | BX14: =COUNTIF($D14:$BC14,"PLASTIC")+COUNTIF($D14:$BC14,"PLASTIC *") | BY14: =COUNTIF($D14:$BC14,"PULM")+COUNTIF($D14:$BC14,"PULM *") | BZ14: =COUNTIF($D14:$BC14,"SICU")+COUNTIF($D14:$BC14,"SICU *") | CA14: =COUNTIF($D14:$BC14,"DERMATOLOGY")+COUNTIF($D14:$BC14,"DERMATOLOGY *") | CB14: =COUNTIF($D14:$BC14,"NEPHRO")+COUNTIF($D14:$BC14,"NEPHRO *") | CC14: =SUM(BQ14:CB14) | CD14: =BP14+CC14
C15: K. Gonzalez | D15: CLINIC * | E15: CLINIC * | F15: VACATION | G15: VACATION | H15: VACATION | I15: VACATION | J15: CLINIC | K15: CLINIC | L15: ED | M15: D | N15: D | O15: CLINIC * | P15: ED | Q15: ID | R15: ID | S15: CLINIC | T15: CLINIC | U15: D | V15: D | W15: NF | X15: NF | Y15: CLINIC * | Z15: C | AA15: C | AB15: C | AC15: ICU | AD15: ICU | AE15: ICU | AF15: CLINIC * | AG15: C | AH15: C | AI15: C | AJ15: C | AK15: CLINIC * | AL15: CARDIO | AM15: CARDIO | AN15: ICU N | AO15: ICU N | AP15: CLINIC | AQ15: CLINIC | AR15: D | AS15: D | AT15: D | AU15: CLINIC * | AV15: B | AW15: B | AX15: B | AY15: B | AZ15: CLINIC * | BA15: ICU N | BB15: ICU N | BC15: ICU N | BD15: =COUNTIF($D15:$BC15,"CARDIO")+COUNTIF($D15:$BC15,"CARDIO E")+COUNTIF($D15:$BC15,"CARDIO E *")+COUNTIF($D15:$BC15,"CARDIO-HCA")+COUNTIF($D15:$BC15,"CARDIO-HCA *")+COUNTIF($D15:$BC15,"CARDIO-RAM")+COUNTIF($D15:$BC15,"CARDIO-RAM *") | BE15: =COUNTIF($D15:$BC15,"CLINIC")+COUNTIF($D15:$BC15,"CLINIC *")+COUNTIF($D15:$BC15,"URGENT CARE")+COUNTIF($D15:$BC15,"URGENT CARE *") | BF15: =COUNTIF($D15:$BC15,"ED") | BG15: =COUNTIF($D15:$BC15,"A")+COUNTIF($D15:$BC15,"B")+COUNTIF($D15:$BC15,"C")+COUNTIF($D15:$BC15,"D")+COUNTIF($D15:$BC15,"G") | BH15: =COUNTIF($D15:$BC15,"ICU") | BI15: =COUNTIF($D15:$BC15,"ICU E") | BJ15: =COUNTIF($D15:$BC15,"ICU N") | BK15: =COUNTIF($D15:$BC15,"ID")+COUNTIF($D15:$BC15,"ID *") | BL15: =COUNTIF($D15:$BC15,"NEURO")+COUNTIF($D15:$BC15,"NEURO *") | BM15: =COUNTIF($D15:$BC15,"NF") | BN15: =COUNTIF($D15:$BC15,"SWING") | BO15: =COUNTIF($D15:$BC15,"VACATION") | BP15: =SUM(BD15:BO15) | BQ15: =COUNTIF($D15:$BC15,"PALLIATIVE")+COUNTIF($D15:$BC15,"PALLIATIVE *") | BR15: =COUNTIF($D15:$BC15,"GERIATRIC")+COUNTIF($D15:$BC15,"GERIATRIC 2") | BS15: =COUNTIF($D15:$BC15,"GS")+COUNTIF($D15:$BC15,"GI")+COUNTIF($D15:$BC15,"GI *") | BT15: =COUNTIF($D15:$BC15,"HEM/ONC")+COUNTIF($D15:$BC15,"HEM/ONC *") | BU15: =COUNTIF($D15:$BC15,"PAIN MANAGEMENT")+COUNTIF($D15:$BC15,"PAIN MANAGEMENT *") | BV15: =COUNTIF($D15:$BC15,"RHEUMA")+COUNTIF($D15:$BC15,"RHEUMA *") | BW15: =COUNTIF($D15:$BC15,"ENDO")+COUNTIF($D15:$BC15,"ENDO *") | BX15: =COUNTIF($D15:$BC15,"PLASTIC")+COUNTIF($D15:$BC15,"PLASTIC *") | BY15: =COUNTIF($D15:$BC15,"PULM")+COUNTIF($D15:$BC15,"PULM *") | BZ15: =COUNTIF($D15:$BC15,"SICU")+COUNTIF($D15:$BC15,"SICU *") | CA15: =COUNTIF($D15:$BC15,"DERMATOLOGY")+COUNTIF($D15:$BC15,"DERMATOLOGY *") | CB15: =COUNTIF($D15:$BC15,"NEPHRO")+COUNTIF($D15:$BC15,"NEPHRO *") | CC15: =SUM(BQ15:CB15) | CD15: =BP15+CC15
B16: PGY-2 | C16: C. Ayala | D16: C | E16: CLINIC * | F16: CARDIO-HCA | G16: CARDIO-HCA | H16: CARDIO-HCA | I16: CARDIO-HCA | J16: CLINIC * | K16: A | L16: A | M16: A | N16: A | O16: CLINIC * | P16: ICU E | Q16: ICU E | R16: ICU E | S16: NEURO | T16: CLINIC * | U16: A | V16: A | W16: NEURO | X16: CLINIC | Y16: CLINIC | Z16: CLINIC | AA16: CLINIC | AB16: NF | AC16: NF | AD16: NF | AE16: NF | AF16: CLINIC * | AG16: VACATION | AH16: VACATION | AI16: VACATION | AJ16: VACATION | AK16: CLINIC * | AL16: ID | AM16: ID | AN16: ED | AO16: ED | AP16: CLINIC * | AQ16: A | AR16: A | AS16: A | AT16: A | AU16: CLINIC * | AV16: ICU N | AW16: ICU N | AX16: ICU N | AY16: ICU N | AZ16: CLINIC * | BA16: CLINIC * | BB16: ICU | BC16: B | BD16: =COUNTIF($D16:$BC16,"CARDIO")+COUNTIF($D16:$BC16,"CARDIO E")+COUNTIF($D16:$BC16,"CARDIO E *")+COUNTIF($D16:$BC16,"CARDIO-HCA")+COUNTIF($D16:$BC16,"CARDIO-HCA *")+COUNTIF($D16:$BC16,"CARDIO-RAM")+COUNTIF($D16:$BC16,"CARDIO-RAM *") | BE16: =COUNTIF($D16:$BC16,"CLINIC")+COUNTIF($D16:$BC16,"CLINIC *")+COUNTIF($D16:$BC16,"URGENT CARE")+COUNTIF($D16:$BC16,"URGENT CARE *") | BF16: =COUNTIF($D16:$BC16,"ED") | BG16: =COUNTIF($D16:$BC16,"A")+COUNTIF($D16:$BC16,"B")+COUNTIF($D16:$BC16,"C")+COUNTIF($D16:$BC16,"D")+COUNTIF($D16:$BC16,"G") | BH16: =COUNTIF($D16:$BC16,"ICU") | BI16: =COUNTIF($D16:$BC16,"ICU E") | BJ16: =COUNTIF($D16:$BC16,"ICU N") | BK16: =COUNTIF($D16:$BC16,"ID")+COUNTIF($D16:$BC16,"ID *") | BL16: =COUNTIF($D16:$BC16,"NEURO")+COUNTIF($D16:$BC16,"NEURO *") | BM16: =COUNTIF($D16:$BC16,"NF") | BN16: =COUNTIF($D16:$BC16,"SWING") | BO16: =COUNTIF($D16:$BC16,"VACATION") | BP16: =SUM(BD16:BO16) | BQ16: =COUNTIF($D16:$BC16,"PALLIATIVE")+COUNTIF($D16:$BC16,"PALLIATIVE *") | BR16: =COUNTIF($D16:$BC16,"GERIATRIC")+COUNTIF($D16:$BC16,"GERIATRIC 2") | BS16: =COUNTIF($D16:$BC16,"GS")+COUNTIF($D16:$BC16,"GI")+COUNTIF($D16:$BC16,"GI *") | BT16: =COUNTIF($D16:$BC16,"HEM/ONC")+COUNTIF($D16:$BC16,"HEM/ONC *") | BU16: =COUNTIF($D16:$BC16,"PAIN MANAGEMENT")+COUNTIF($D16:$BC16,"PAIN MANAGEMENT *") | BV16: =COUNTIF($D16:$BC16,"RHEUMA")+COUNTIF($D16:$BC16,"RHEUMA *") | BW16: =COUNTIF($D16:$BC16,"ENDO")+COUNTIF($D16:$BC16,"ENDO *") | BX16: =COUNTIF($D16:$BC16,"PLASTIC")+COUNTIF($D16:$BC16,"PLASTIC *") | BY16: =COUNTIF($D16:$BC16,"PULM")+COUNTIF($D16:$BC16,"PULM *") | BZ16: =COUNTIF($D16:$BC16,"SICU")+COUNTIF($D16:$BC16,"SICU *") | CA16: =COUNTIF($D16:$BC16,"DERMATOLOGY")+COUNTIF($D16:$BC16,"DERMATOLOGY *") | CB16: =COUNTIF($D16:$BC16,"NEPHRO")+COUNTIF($D16:$BC16,"NEPHRO *") | CC16: =SUM(BQ16:CB16) | CD16: =BP16+CC16
C17: K. Vallejo | D17: VACATION | E17: CLINIC * | F17: CLINIC * | G17: ICU E | H17: ICU E | I17: ICU E | J17: CLINIC * | K17: ID | L17: ID | M17: G | N17: CLINIC | O17: CLINIC | P17: B | Q17: B | R17: B | S17: CLINIC | T17: CLINIC | U17: C | V17: C | W17: C | X17: C | Y17: CLINIC * | Z17: ICU N | AA17: D | AB17: D | AC17: D | AD17: NEURO | AE17: NEURO | AF17: CLINIC * | AG17: ICU | AH17: ICU | AI17: ICU | AJ17: ICU | AK17: CLINIC * | AL17: CARDIO-HCA | AM17: CARDIO-HCA | AN17: CARDIO-HCA | AO17: CARDIO-HCA | AP17: CLINIC * | AQ17: ED | AR17: ED | AS17: SWING | AT17: SWING | AU17: CLINIC * | AV17: B | AW17: B | AX17: B | AY17: CLINIC * | AZ17: CLINIC * | BA17: VACATION | BB17: VACATION | BC17: VACATION | BD17: =COUNTIF($D17:$BC17,"CARDIO")+COUNTIF($D17:$BC17,"CARDIO E")+COUNTIF($D17:$BC17,"CARDIO E *")+COUNTIF($D17:$BC17,"CARDIO-HCA")+COUNTIF($D17:$BC17,"CARDIO-HCA *")+COUNTIF($D17:$BC17,"CARDIO-RAM")+COUNTIF($D17:$BC17,"CARDIO-RAM *") | BE17: =COUNTIF($D17:$BC17,"CLINIC")+COUNTIF($D17:$BC17,"CLINIC *")+COUNTIF($D17:$BC17,"URGENT CARE")+COUNTIF($D17:$BC17,"URGENT CARE *") | BF17: =COUNTIF($D17:$BC17,"ED") | BG17: =COUNTIF($D17:$BC17,"A")+COUNTIF($D17:$BC17,"B")+COUNTIF($D17:$BC17,"C")+COUNTIF($D17:$BC17,"D")+COUNTIF($D17:$BC17,"G") | BH17: =COUNTIF($D17:$BC17,"ICU") | BI17: =COUNTIF($D17:$BC17,"ICU E") | BJ17: =COUNTIF($D17:$BC17,"ICU N") | BK17: =COUNTIF($D17:$BC17,"ID")+COUNTIF($D17:$BC17,"ID *") | BL17: =COUNTIF($D17:$BC17,"NEURO")+COUNTIF($D17:$BC17,"NEURO *") | BM17: =COUNTIF($D17:$BC17,"NF") | BN17: =COUNTIF($D17:$BC17,"SWING") | BO17: =COUNTIF($D17:$BC17,"VACATION") | BP17: =SUM(BD17:BO17) | BQ17: =COUNTIF($D17:$BC17,"PALLIATIVE")+COUNTIF($D17:$BC17,"PALLIATIVE *") | BR17: =COUNTIF($D17:$BC17,"GERIATRIC")+COUNTIF($D17:$BC17,"GERIATRIC 2") | BS17: =COUNTIF($D17:$BC17,"GS")+COUNTIF($D17:$BC17,"GI")+COUNTIF($D17:$BC17,"GI *") | BT17: =COUNTIF($D17:$BC17,"HEM/ONC")+COUNTIF($D17:$BC17,"HEM/ONC *") | BU17: =COUNTIF($D17:$BC17,"PAIN MANAGEMENT")+COUNTIF($D17:$BC17,"PAIN MANAGEMENT *") | BV17: =COUNTIF($D17:$BC17,"RHEUMA")+COUNTIF($D17:$BC17,"RHEUMA *") | BW17: =COUNTIF($D17:$BC17,"ENDO")+COUNTIF($D17:$BC17,"ENDO *") | BX17: =COUNTIF($D17:$BC17,"PLASTIC")+COUNTIF($D17:$BC17,"PLASTIC *") | BY17: =COUNTIF($D17:$BC17,"PULM")+COUNTIF($D17:$BC17,"PULM *") | BZ17: =COUNTIF($D17:$BC17,"SICU")+COUNTIF($D17:$BC17,"SICU *") | CA17: =COUNTIF($D17:$BC17,"DERMATOLOGY")+COUNTIF($D17:$BC17,"DERMATOLOGY *") | CB17: =COUNTIF($D17:$BC17,"NEPHRO")+COUNTIF($D17:$BC17,"NEPHRO *") | CC17: =SUM(BQ17:CB17) | CD17: =BP17+CC17
B18: PGY-3 | C18: A. Silva | D18: CLINIC * | E18: CLINIC * | F18: NF | G18: NF | H18: NF | I18: NF | J18: CLINIC | K18: CLINIC | L18: CLINIC | M18: CLINIC | N18: CLINIC | O18: CLINIC | P18: ICU E | Q18: ICU E | R18: ICU E | S18: CLINIC * | T18: CLINIC * | U18: VACATION | V18: VACATION | W18: VACATION | X18: CLINIC * | Y18: CLINIC * | Z18: CLINIC * | AA18: CLINIC * | AB18: VACATION | AC18: SWING | AD18: SWING | AE18: ICU E | AF18: CLINIC * | AG18: SWING | AH18: SWING | AI18: SWING | AJ18: SWING | AK18: CLINIC * | AL18: ICU N | AM18: ICU N | AN18: ICU N | AO18: ICU N | AP18: CLINIC | AQ18: CLINIC | AR18: CLINIC | AS18: CLINIC | AT18: CLINIC | AU18: CLINIC | AV18: C | AW18: C | AX18: C | AY18: C | AZ18: CLINIC * | BA18: CLINIC * | BB18: C | BC18: C | BD18: =COUNTIF($D18:$BC18,"CARDIO")+COUNTIF($D18:$BC18,"CARDIO E")+COUNTIF($D18:$BC18,"CARDIO E *")+COUNTIF($D18:$BC18,"CARDIO-HCA")+COUNTIF($D18:$BC18,"CARDIO-HCA *")+COUNTIF($D18:$BC18,"CARDIO-RAM")+COUNTIF($D18:$BC18,"CARDIO-RAM *") | BE18: =COUNTIF($D18:$BC18,"CLINIC")+COUNTIF($D18:$BC18,"CLINIC *")+COUNTIF($D18:$BC18,"URGENT CARE")+COUNTIF($D18:$BC18,"URGENT CARE *") | BF18: =COUNTIF($D18:$BC18,"ED") | BG18: =COUNTIF($D18:$BC18,"A")+COUNTIF($D18:$BC18,"B")+COUNTIF($D18:$BC18,"C")+COUNTIF($D18:$BC18,"D")+COUNTIF($D18:$BC18,"G") | BH18: =COUNTIF($D18:$BC18,"ICU") | BI18: =COUNTIF($D18:$BC18,"ICU E") | BJ18: =COUNTIF($D18:$BC18,"ICU N") | BK18: =COUNTIF($D18:$BC18,"ID")+COUNTIF($D18:$BC18,"ID *") | BL18: =COUNTIF($D18:$BC18,"NEURO")+COUNTIF($D18:$BC18,"NEURO *") | BM18: =COUNTIF($D18:$BC18,"NF") | BN18: =COUNTIF($D18:$BC18,"SWING") | BO18: =COUNTIF($D18:$BC18,"VACATION") | BP18: =SUM(BD18:BO18) | BQ18: =COUNTIF($D18:$BC18,"PALLIATIVE")+COUNTIF($D18:$BC18,"PALLIATIVE *") | BR18: =COUNTIF($D18:$BC18,"GERIATRIC")+COUNTIF($D18:$BC18,"GERIATRIC 2") | BS18: =COUNTIF($D18:$BC18,"GS")+COUNTIF($D18:$BC18,"GI")+COUNTIF($D18:$BC18,"GI *") | BT18: =COUNTIF($D18:$BC18,"HEM/ONC")+COUNTIF($D18:$BC18,"HEM/ONC *") | BU18: =COUNTIF($D18:$BC18,"PAIN MANAGEMENT")+COUNTIF($D18:$BC18,"PAIN MANAGEMENT *") | BV18: =COUNTIF($D18:$BC18,"RHEUMA")+COUNTIF($D18:$BC18,"RHEUMA *") | BW18: =COUNTIF($D18:$BC18,"ENDO")+COUNTIF($D18:$BC18,"ENDO *") | BX18: =COUNTIF($D18:$BC18,"PLASTIC")+COUNTIF($D18:$BC18,"PLASTIC *") | BY18: =COUNTIF($D18:$BC18,"PULM")+COUNTIF($D18:$BC18,"PULM *") | BZ18: =COUNTIF($D18:$BC18,"SICU")+COUNTIF($D18:$BC18,"SICU *") | CA18: =COUNTIF($D18:$BC18,"DERMATOLOGY")+COUNTIF($D18:$BC18,"DERMATOLOGY *") | CB18: =COUNTIF($D18:$BC18,"NEPHRO")+COUNTIF($D18:$BC18,"NEPHRO *") | CC18: =SUM(BQ18:CB18) | CD18: =BP18+CC18
C19: F. Monefeldt | D19: CLINIC * | E19: CLINIC * | F19: B | G19: B | H19: B | I19: B | J19: CLINIC * | K19: G | L19: ICU | M19: CLINIC | N19: CLINIC | O19: CLINIC | P19: ICU N | Q19: ICU N | R19: ICU N | S19: CLINIC * | T19: CLINIC * | U19: G | V19: G | W19: G | X19: G | Y19: CLINIC * | Z19: SWING | AA19: SWING | AB19: SWING | AC19: SWING | AD19: SWING | AE19: ICU E | AF19: CLINIC * | AG19: G | AH19: G | AI19: CLINIC * | AJ19: CLINIC * | AK19: CLINIC * | AL19: CLINIC * | AM19: ICU E | AN19: CLINIC * | AO19: CLINIC * | AP19: CLINIC * | AQ19: VACATION | AR19: VACATION | AS19: VACATION | AT19: VACATION | AU19: CLINIC * | AV19: ICU E | AW19: ICU E | AX19: ICU E | AY19: ICU E | AZ19: CLINIC | BA19: CLINIC | BB19: CLINIC | BC19: CLINIC | BD19: =COUNTIF($D19:$BC19,"CARDIO")+COUNTIF($D19:$BC19,"CARDIO E")+COUNTIF($D19:$BC19,"CARDIO E *")+COUNTIF($D19:$BC19,"CARDIO-HCA")+COUNTIF($D19:$BC19,"CARDIO-HCA *")+COUNTIF($D19:$BC19,"CARDIO-RAM")+COUNTIF($D19:$BC19,"CARDIO-RAM *") | BE19: =COUNTIF($D19:$BC19,"CLINIC")+COUNTIF($D19:$BC19,"CLINIC *")+COUNTIF($D19:$BC19,"URGENT CARE")+COUNTIF($D19:$BC19,"URGENT CARE *") | BF19: =COUNTIF($D19:$BC19,"ED") | BG19: =COUNTIF($D19:$BC19,"A")+COUNTIF($D19:$BC19,"B")+COUNTIF($D19:$BC19,"C")+COUNTIF($D19:$BC19,"D")+COUNTIF($D19:$BC19,"G") | BH19: =COUNTIF($D19:$BC19,"ICU") | BI19: =COUNTIF($D19:$BC19,"ICU E") | BJ19: =COUNTIF($D19:$BC19,"ICU N") | BK19: =COUNTIF($D19:$BC19,"ID")+COUNTIF($D19:$BC19,"ID *") | BL19: =COUNTIF($D19:$BC19,"NEURO")+COUNTIF($D19:$BC19,"NEURO *") | BM19: =COUNTIF($D19:$BC19,"NF") | BN19: =COUNTIF($D19:$BC19,"SWING") | BO19: =COUNTIF($D19:$BC19,"VACATION") | BP19: =SUM(BD19:BO19) | BQ19: =COUNTIF($D19:$BC19,"PALLIATIVE")+COUNTIF($D19:$BC19,"PALLIATIVE *") | BR19: =COUNTIF($D19:$BC19,"GERIATRIC")+COUNTIF($D19:$BC19,"GERIATRIC 2") | BS19: =COUNTIF($D19:$BC19,"GS")+COUNTIF($D19:$BC19,"GI")+COUNTIF($D19:$BC19,"GI *") | BT19: =COUNTIF($D19:$BC19,"HEM/ONC")+COUNTIF($D19:$BC19,"HEM/ONC *") | BU19: =COUNTIF($D19:$BC19,"PAIN MANAGEMENT")+COUNTIF($D19:$BC19,"PAIN MANAGEMENT *") | BV19: =COUNTIF($D19:$BC19,"RHEUMA")+COUNTIF($D19:$BC19,"RHEUMA *") | BW19: =COUNTIF($D19:$BC19,"ENDO")+COUNTIF($D19:$BC19,"ENDO *") | BX19: =COUNTIF($D19:$BC19,"PLASTIC")+COUNTIF($D19:$BC19,"PLASTIC *") | BY19: =COUNTIF($D19:$BC19,"PULM")+COUNTIF($D19:$BC19,"PULM *") | BZ19: =COUNTIF($D19:$BC19,"SICU")+COUNTIF($D19:$BC19,"SICU *") | CA19: =COUNTIF($D19:$BC19,"DERMATOLOGY")+COUNTIF($D19:$BC19,"DERMATOLOGY *") | CB19: =COUNTIF($D19:$BC19,"NEPHRO")+COUNTIF($D19:$BC19,"NEPHRO *") | CC19: =SUM(BQ19:CB19) | CD19: =BP19+CC19
A20: Cohort 3 | B20: PGY-1 | C20: M. Cruz | D20: C | E20: CLINIC | F20: CLINIC | G20: B | H20: B | I20: ICU N | J20: ICU N | K20: CLINIC * | L20: VACATION | M20: ICU | N20: ICU | O20: ICU | P20: CLINIC * | Q20: CARDIO-HCA | R20: CARDIO-HCA | S20: B | T20: B | U20: CLINIC * | V20: C | W20: C | X20: ID | Y20: ID | Z20: CLINIC | AA20: CLINIC | AB20: D | AC20: D | AD20: D | AE20: ED | AF20: ED | AG20: CLINIC * | AH20: ICU N | AI20: VACATION | AJ20: VACATION | AK20: VACATION | AL20: CLINIC * | AM20: ICU E | AN20: ICU E | AO20: C | AP20: C | AQ20: CLINIC * | AR20: A | AS20: A | AT20: A | AU20: CLINIC * | AV20: CLINIC * | AW20: C | AX20: C | AY20: C | AZ20: CLINIC * | BA20: CLINIC * | BB20: D | BC20: D | BD20: =COUNTIF($D20:$BC20,"CARDIO")+COUNTIF($D20:$BC20,"CARDIO E")+COUNTIF($D20:$BC20,"CARDIO E *")+COUNTIF($D20:$BC20,"CARDIO-HCA")+COUNTIF($D20:$BC20,"CARDIO-HCA *")+COUNTIF($D20:$BC20,"CARDIO-RAM")+COUNTIF($D20:$BC20,"CARDIO-RAM *") | BE20: =COUNTIF($D20:$BC20,"CLINIC")+COUNTIF($D20:$BC20,"CLINIC *")+COUNTIF($D20:$BC20,"URGENT CARE")+COUNTIF($D20:$BC20,"URGENT CARE *") | BF20: =COUNTIF($D20:$BC20,"ED") | BG20: =COUNTIF($D20:$BC20,"A")+COUNTIF($D20:$BC20,"B")+COUNTIF($D20:$BC20,"C")+COUNTIF($D20:$BC20,"D")+COUNTIF($D20:$BC20,"G") | BH20: =COUNTIF($D20:$BC20,"ICU") | BI20: =COUNTIF($D20:$BC20,"ICU E") | BJ20: =COUNTIF($D20:$BC20,"ICU N") | BK20: =COUNTIF($D20:$BC20,"ID")+COUNTIF($D20:$BC20,"ID *") | BL20: =COUNTIF($D20:$BC20,"NEURO")+COUNTIF($D20:$BC20,"NEURO *") | BM20: =COUNTIF($D20:$BC20,"NF") | BN20: =COUNTIF($D20:$BC20,"SWING") | BO20: =COUNTIF($D20:$BC20,"VACATION") | BP20: =SUM(BD20:BO20) | BQ20: =COUNTIF($D20:$BC20,"PALLIATIVE")+COUNTIF($D20:$BC20,"PALLIATIVE *") | BR20: =COUNTIF($D20:$BC20,"GERIATRIC")+COUNTIF($D20:$BC20,"GERIATRIC 2") | BS20: =COUNTIF($D20:$BC20,"GS")+COUNTIF($D20:$BC20,"GI")+COUNTIF($D20:$BC20,"GI *") | BT20: =COUNTIF($D20:$BC20,"HEM/ONC")+COUNTIF($D20:$BC20,"HEM/ONC *") | BU20: =COUNTIF($D20:$BC20,"PAIN MANAGEMENT")+COUNTIF($D20:$BC20,"PAIN MANAGEMENT *") | BV20: =COUNTIF($D20:$BC20,"RHEUMA")+COUNTIF($D20:$BC20,"RHEUMA *") | BW20: =COUNTIF($D20:$BC20,"ENDO")+COUNTIF($D20:$BC20,"ENDO *") | BX20: =COUNTIF($D20:$BC20,"PLASTIC")+COUNTIF($D20:$BC20,"PLASTIC *") | BY20: =COUNTIF($D20:$BC20,"PULM")+COUNTIF($D20:$BC20,"PULM *") | BZ20: =COUNTIF($D20:$BC20,"SICU")+COUNTIF($D20:$BC20,"SICU *") | CA20: =COUNTIF($D20:$BC20,"DERMATOLOGY")+COUNTIF($D20:$BC20,"DERMATOLOGY *") | CB20: =COUNTIF($D20:$BC20,"NEPHRO")+COUNTIF($D20:$BC20,"NEPHRO *") | CC20: =SUM(BQ20:CB20) | CD20: =BP20+CC20
C21: I. Estrada | D21: D | E21: D | F21: CLINIC * | G21: CLINIC * | H21: ID | I21: ID | J21: VACATION | K21: CLINIC * | L21: C | M21: ICU N | N21: ICU N | O21: ICU N | P21: CLINIC * | Q21: ED | R21: ED | S21: D | T21: D | U21: CLINIC * | V21: CARDIO-HCA | W21: CARDIO-HCA | X21: A | Y21: A | Z21: CLINIC * | AA21: CLINIC * | AB21: CLINIC * | AC21: B | AD21: B | AE21: B | AF21: B | AG21: CLINIC * | AH21: D | AI21: D | AJ21: D | AK21: ICU N | AL21: CLINIC * | AM21: D | AN21: D | AO21: D | AP21: ICU E | AQ21: CLINIC | AR21: CLINIC | AS21: VACATION | AT21: VACATION | AU21: VACATION | AV21: CLINIC * | AW21: ICU | AX21: ICU | AY21: ICU | AZ21: NF | BA21: CLINIC * | BB21: C | BC21: C | BD21: =COUNTIF($D21:$BC21,"CARDIO")+COUNTIF($D21:$BC21,"CARDIO E")+COUNTIF($D21:$BC21,"CARDIO E *")+COUNTIF($D21:$BC21,"CARDIO-HCA")+COUNTIF($D21:$BC21,"CARDIO-HCA *")+COUNTIF($D21:$BC21,"CARDIO-RAM")+COUNTIF($D21:$BC21,"CARDIO-RAM *") | BE21: =COUNTIF($D21:$BC21,"CLINIC")+COUNTIF($D21:$BC21,"CLINIC *")+COUNTIF($D21:$BC21,"URGENT CARE")+COUNTIF($D21:$BC21,"URGENT CARE *") | BF21: =COUNTIF($D21:$BC21,"ED") | BG21: =COUNTIF($D21:$BC21,"A")+COUNTIF($D21:$BC21,"B")+COUNTIF($D21:$BC21,"C")+COUNTIF($D21:$BC21,"D")+COUNTIF($D21:$BC21,"G") | BH21: =COUNTIF($D21:$BC21,"ICU") | BI21: =COUNTIF($D21:$BC21,"ICU E") | BJ21: =COUNTIF($D21:$BC21,"ICU N") | BK21: =COUNTIF($D21:$BC21,"ID")+COUNTIF($D21:$BC21,"ID *") | BL21: =COUNTIF($D21:$BC21,"NEURO")+COUNTIF($D21:$BC21,"NEURO *") | BM21: =COUNTIF($D21:$BC21,"NF") | BN21: =COUNTIF($D21:$BC21,"SWING") | BO21: =COUNTIF($D21:$BC21,"VACATION") | BP21: =SUM(BD21:BO21) | BQ21: =COUNTIF($D21:$BC21,"PALLIATIVE")+COUNTIF($D21:$BC21,"PALLIATIVE *") | BR21: =COUNTIF($D21:$BC21,"GERIATRIC")+COUNTIF($D21:$BC21,"GERIATRIC 2") | BS21: =COUNTIF($D21:$BC21,"GS")+COUNTIF($D21:$BC21,"GI")+COUNTIF($D21:$BC21,"GI *") | BT21: =COUNTIF($D21:$BC21,"HEM/ONC")+COUNTIF($D21:$BC21,"HEM/ONC *") | BU21: =COUNTIF($D21:$BC21,"PAIN MANAGEMENT")+COUNTIF($D21:$BC21,"PAIN MANAGEMENT *") | BV21: =COUNTIF($D21:$BC21,"RHEUMA")+COUNTIF($D21:$BC21,"RHEUMA *") | BW21: =COUNTIF($D21:$BC21,"ENDO")+COUNTIF($D21:$BC21,"ENDO *") | BX21: =COUNTIF($D21:$BC21,"PLASTIC")+COUNTIF($D21:$BC21,"PLASTIC *") | BY21: =COUNTIF($D21:$BC21,"PULM")+COUNTIF($D21:$BC21,"PULM *") | BZ21: =COUNTIF($D21:$BC21,"SICU")+COUNTIF($D21:$BC21,"SICU *") | CA21: =COUNTIF($D21:$BC21,"DERMATOLOGY")+COUNTIF($D21:$BC21,"DERMATOLOGY *") | CB21: =COUNTIF($D21:$BC21,"NEPHRO")+COUNTIF($D21:$BC21,"NEPHRO *") | CC21: =SUM(BQ21:CB21) | CD21: =BP21+CC21
B22: PGY-2 | C22: J. Cabrera | D22: D | E22: D | F22: CLINIC * | G22: ID | H22: ID | I22: NEURO | J22: NEURO | K22: CLINIC * | L22: C | M22: C | N22: C | O22: C | P22: CLINIC * | Q22: A | R22: A | S22: VACATION | T22: CLINIC * | U22: CLINIC * | V22: ICU N | W22: ICU N | X22: ICU N | Y22: ICU N | Z22: CLINIC * | AA22: D | AB22: D | AC22: D | AD22: D | AE22: D | AF22: D | AG22: CLINIC * | AH22: A | AI22: A | AJ22: ED | AK22: ED | AL22: CLINIC | AM22: CLINIC | AN22: CLINIC | AO22: CARDIO-HCA | AP22: CARDIO-HCA | AQ22: CLINIC * | AR22: ICU N | AS22: ICU N | AT22: ICU N | AU22: ICU N | AV22: CLINIC | AW22: CLINIC | AX22: VACATION | AY22: VACATION | AZ22: VACATION | BA22: CLINIC * | BB22: CARDIO | BC22: CARDIO | BD22: =COUNTIF($D22:$BC22,"CARDIO")+COUNTIF($D22:$BC22,"CARDIO E")+COUNTIF($D22:$BC22,"CARDIO E *")+COUNTIF($D22:$BC22,"CARDIO-HCA")+COUNTIF($D22:$BC22,"CARDIO-HCA *")+COUNTIF($D22:$BC22,"CARDIO-RAM")+COUNTIF($D22:$BC22,"CARDIO-RAM *") | BE22: =COUNTIF($D22:$BC22,"CLINIC")+COUNTIF($D22:$BC22,"CLINIC *")+COUNTIF($D22:$BC22,"URGENT CARE")+COUNTIF($D22:$BC22,"URGENT CARE *") | BF22: =COUNTIF($D22:$BC22,"ED") | BG22: =COUNTIF($D22:$BC22,"A")+COUNTIF($D22:$BC22,"B")+COUNTIF($D22:$BC22,"C")+COUNTIF($D22:$BC22,"D")+COUNTIF($D22:$BC22,"G") | BH22: =COUNTIF($D22:$BC22,"ICU") | BI22: =COUNTIF($D22:$BC22,"ICU E") | BJ22: =COUNTIF($D22:$BC22,"ICU N") | BK22: =COUNTIF($D22:$BC22,"ID")+COUNTIF($D22:$BC22,"ID *") | BL22: =COUNTIF($D22:$BC22,"NEURO")+COUNTIF($D22:$BC22,"NEURO *") | BM22: =COUNTIF($D22:$BC22,"NF") | BN22: =COUNTIF($D22:$BC22,"SWING") | BO22: =COUNTIF($D22:$BC22,"VACATION") | BP22: =SUM(BD22:BO22) | BQ22: =COUNTIF($D22:$BC22,"PALLIATIVE")+COUNTIF($D22:$BC22,"PALLIATIVE *") | BR22: =COUNTIF($D22:$BC22,"GERIATRIC")+COUNTIF($D22:$BC22,"GERIATRIC 2") | BS22: =COUNTIF($D22:$BC22,"GS")+COUNTIF($D22:$BC22,"GI")+COUNTIF($D22:$BC22,"GI *") | BT22: =COUNTIF($D22:$BC22,"HEM/ONC")+COUNTIF($D22:$BC22,"HEM/ONC *") | BU22: =COUNTIF($D22:$BC22,"PAIN MANAGEMENT")+COUNTIF($D22:$BC22,"PAIN MANAGEMENT *") | BV22: =COUNTIF($D22:$BC22,"RHEUMA")+COUNTIF($D22:$BC22,"RHEUMA *") | BW22: =COUNTIF($D22:$BC22,"ENDO")+COUNTIF($D22:$BC22,"ENDO *") | BX22: =COUNTIF($D22:$BC22,"PLASTIC")+COUNTIF($D22:$BC22,"PLASTIC *") | BY22: =COUNTIF($D22:$BC22,"PULM")+COUNTIF($D22:$BC22,"PULM *") | BZ22: =COUNTIF($D22:$BC22,"SICU")+COUNTIF($D22:$BC22,"SICU *") | CA22: =COUNTIF($D22:$BC22,"DERMATOLOGY")+COUNTIF($D22:$BC22,"DERMATOLOGY *") | CB22: =COUNTIF($D22:$BC22,"NEPHRO")+COUNTIF($D22:$BC22,"NEPHRO *") | CC22: =SUM(BQ22:CB22) | CD22: =BP22+CC22
C23: J. Perez | D23: NEURO | E23: NEURO | F23: CLINIC * | G23: ICU N | H23: ICU N | I23: ICU N | J23: ICU N | K23: CLINIC * | L23: CLINIC * | M23: CLINIC * | N23: CLINIC * | O23: CLINIC * | P23: CLINIC * | Q23: ID | R23: ID | S23: ICU E | T23: ICU E | U23: CLINIC * | V23: NF | W23: NF | X23: NF | Y23: NF | Z23: CLINIC * | AA23: D | AB23: D | AC23: D | AD23: D | AE23: D | AF23: D | AG23: CLINIC * | AH23: B | AI23: B | AJ23: B | AK23: B | AL23: CLINIC * | AM23: C | AN23: C | AO23: ICU E | AP23: ICU E | AQ23: CLINIC * | AR23: VACATION | AS23: VACATION | AT23: VACATION | AU23: VACATION | AV23: CLINIC | AW23: CARDIO-HCA | AX23: CARDIO-HCA | AY23: CARDIO-HCA | AZ23: CARDIO-HCA | BA23: CLINIC * | BB23: ED | BC23: ED | BD23: =COUNTIF($D23:$BC23,"CARDIO")+COUNTIF($D23:$BC23,"CARDIO E")+COUNTIF($D23:$BC23,"CARDIO E *")+COUNTIF($D23:$BC23,"CARDIO-HCA")+COUNTIF($D23:$BC23,"CARDIO-HCA *")+COUNTIF($D23:$BC23,"CARDIO-RAM")+COUNTIF($D23:$BC23,"CARDIO-RAM *") | BE23: =COUNTIF($D23:$BC23,"CLINIC")+COUNTIF($D23:$BC23,"CLINIC *")+COUNTIF($D23:$BC23,"URGENT CARE")+COUNTIF($D23:$BC23,"URGENT CARE *") | BF23: =COUNTIF($D23:$BC23,"ED") | BG23: =COUNTIF($D23:$BC23,"A")+COUNTIF($D23:$BC23,"B")+COUNTIF($D23:$BC23,"C")+COUNTIF($D23:$BC23,"D")+COUNTIF($D23:$BC23,"G") | BH23: =COUNTIF($D23:$BC23,"ICU") | BI23: =COUNTIF($D23:$BC23,"ICU E") | BJ23: =COUNTIF($D23:$BC23,"ICU N") | BK23: =COUNTIF($D23:$BC23,"ID")+COUNTIF($D23:$BC23,"ID *") | BL23: =COUNTIF($D23:$BC23,"NEURO")+COUNTIF($D23:$BC23,"NEURO *") | BM23: =COUNTIF($D23:$BC23,"NF") | BN23: =COUNTIF($D23:$BC23,"SWING") | BO23: =COUNTIF($D23:$BC23,"VACATION") | BP23: =SUM(BD23:BO23) | BQ23: =COUNTIF($D23:$BC23,"PALLIATIVE")+COUNTIF($D23:$BC23,"PALLIATIVE *") | BR23: =COUNTIF($D23:$BC23,"GERIATRIC")+COUNTIF($D23:$BC23,"GERIATRIC 2") | BS23: =COUNTIF($D23:$BC23,"GS")+COUNTIF($D23:$BC23,"GI")+COUNTIF($D23:$BC23,"GI *") | BT23: =COUNTIF($D23:$BC23,"HEM/ONC")+COUNTIF($D23:$BC23,"HEM/ONC *") | BU23: =COUNTIF($D23:$BC23,"PAIN MANAGEMENT")+COUNTIF($D23:$BC23,"PAIN MANAGEMENT *") | BV23: =COUNTIF($D23:$BC23,"RHEUMA")+COUNTIF($D23:$BC23,"RHEUMA *") | BW23: =COUNTIF($D23:$BC23,"ENDO")+COUNTIF($D23:$BC23,"ENDO *") | BX23: =COUNTIF($D23:$BC23,"PLASTIC")+COUNTIF($D23:$BC23,"PLASTIC *") | BY23: =COUNTIF($D23:$BC23,"PULM")+COUNTIF($D23:$BC23,"PULM *") | BZ23: =COUNTIF($D23:$BC23,"SICU")+COUNTIF($D23:$BC23,"SICU *") | CA23: =COUNTIF($D23:$BC23,"DERMATOLOGY")+COUNTIF($D23:$BC23,"DERMATOLOGY *") | CB23: =COUNTIF($D23:$BC23,"NEPHRO")+COUNTIF($D23:$BC23,"NEPHRO *") | CC23: =SUM(BQ23:CB23) | CD23: =BP23+CC23
B24: PGY-3 | C24: C. Ndigamkong | D24: VACATION | E24: VACATION | F24: CLINIC * | G24: D | H24: D | I24: CLINIC * | J24: CLINIC * | K24: CLINIC * | L24: A | M24: A | N24: ICU E | O24: ICU E | P24: CLINIC * | Q24: CLINIC * | R24: CLINIC * | S24: A | T24: A | U24: CLINIC * | V24: D | W24: D | X24: D | Y24: D | Z24: CLINIC * | AA24: CLINIC * | AB24: CLINIC * | AC24: ICU | AD24: ICU | AE24: VACATION | AF24: VACATION | AG24: CLINIC * | AH24: ICU N | AI24: ICU N | AJ24: ICU N | AK24: CLINIC | AL24: CLINIC | AM24: CLINIC | AN24: ICU | AO24: ICU | AP24: ICU | AQ24: CLINIC * | AR24: CLINIC * | AS24: D | AT24: D | AU24: D | AV24: CLINIC * | AW24: CLINIC * | AX24: NF | AY24: NF | AZ24: NF | BA24: CLINIC * | BB24: NF | BC24: NF | BD24: =COUNTIF($D24:$BC24,"CARDIO")+COUNTIF($D24:$BC24,"CARDIO E")+COUNTIF($D24:$BC24,"CARDIO E *")+COUNTIF($D24:$BC24,"CARDIO-HCA")+COUNTIF($D24:$BC24,"CARDIO-HCA *")+COUNTIF($D24:$BC24,"CARDIO-RAM")+COUNTIF($D24:$BC24,"CARDIO-RAM *") | BE24: =COUNTIF($D24:$BC24,"CLINIC")+COUNTIF($D24:$BC24,"CLINIC *")+COUNTIF($D24:$BC24,"URGENT CARE")+COUNTIF($D24:$BC24,"URGENT CARE *") | BF24: =COUNTIF($D24:$BC24,"ED") | BG24: =COUNTIF($D24:$BC24,"A")+COUNTIF($D24:$BC24,"B")+COUNTIF($D24:$BC24,"C")+COUNTIF($D24:$BC24,"D")+COUNTIF($D24:$BC24,"G") | BH24: =COUNTIF($D24:$BC24,"ICU") | BI24: =COUNTIF($D24:$BC24,"ICU E") | BJ24: =COUNTIF($D24:$BC24,"ICU N") | BK24: 0 | BL24: =COUNTIF($D24:$BC24,"NEURO")+COUNTIF($D24:$BC24,"NEURO *") | BM24: =COUNTIF($D24:$BC24,"NF") | BN24: =COUNTIF($D24:$BC24,"SWING") | BO24: =COUNTIF($D24:$BC24,"VACATION") | BP24: =SUM(BD24:BO24) | BQ24: =COUNTIF($D24:$BC24,"PALLIATIVE")+COUNTIF($D24:$BC24,"PALLIATIVE *") | BR24: =COUNTIF($D24:$BC24,"GERIATRIC")+COUNTIF($D24:$BC24,"GERIATRIC 2") | BS24: =COUNTIF($D24:$BC24,"GS")+COUNTIF($D24:$BC24,"GI")+COUNTIF($D24:$BC24,"GI *") | BT24: =COUNTIF($D24:$BC24,"HEM/ONC")+COUNTIF($D24:$BC24,"HEM/ONC *") | BU24: =COUNTIF($D24:$BC24,"PAIN MANAGEMENT")+COUNTIF($D24:$BC24,"PAIN MANAGEMENT *") | BV24: =COUNTIF($D24:$BC24,"RHEUMA")+COUNTIF($D24:$BC24,"RHEUMA *") | BW24: =COUNTIF($D24:$BC24,"ENDO")+COUNTIF($D24:$BC24,"ENDO *") | BX24: =COUNTIF($D24:$BC24,"PLASTIC")+COUNTIF($D24:$BC24,"PLASTIC *") | BY24: =COUNTIF($D24:$BC24,"PULM")+COUNTIF($D24:$BC24,"PULM *") | BZ24: =COUNTIF($D24:$BC24,"SICU")+COUNTIF($D24:$BC24,"SICU *") | CA24: =COUNTIF($D24:$BC24,"DERMATOLOGY")+COUNTIF($D24:$BC24,"DERMATOLOGY *") | CB24: =COUNTIF($D24:$BC24,"NEPHRO")+COUNTIF($D24:$BC24,"NEPHRO *") | CC24: =SUM(BQ24:CB24) | CD24: =BP24+CC24
C25: C. Fontela | D25: NF | E25: NF | F25: CLINIC * | G25: SWING | H25: SWING | I25: SWING | J25: CLINIC | K25: CLINIC | L25: CLINIC | M25: ICU E | N25: ICU E | O25: ICU E | P25: CLINIC * | Q25: CLINIC * | R25: CLINIC * | S25: CLINIC * | T25: CLINIC * | U25: CLINIC * | V25: CLINIC * | W25: ICU E | X25: ICU E | Y25: ICU E | Z25: CLINIC * | AA25: SWING | AB25: SWING | AC25: SWING | AD25: SWING | AE25: SWING | AF25: SWING | AG25: CLINIC * | AH25: VACATION | AI25: VACATION | AJ25: CLINIC | AK25: CLINIC | AL25: CLINIC | AM25: A | AN25: A | AO25: ICU E | AP25: ICU E | AQ25: CLINIC * | AR25: CLINIC * | AS25: B | AT25: B | AU25: B | AV25: CLINIC * | AW25: CLINIC * | AX25: CLINIC * | AY25: CLINIC * | AZ25: CLINIC * | BA25: CLINIC * | BB25: VACATION | BC25: VACATION | BD25: =COUNTIF($D25:$BC25,"CARDIO")+COUNTIF($D25:$BC25,"CARDIO E")+COUNTIF($D25:$BC25,"CARDIO E *")+COUNTIF($D25:$BC25,"CARDIO-HCA")+COUNTIF($D25:$BC25,"CARDIO-HCA *")+COUNTIF($D25:$BC25,"CARDIO-RAM")+COUNTIF($D25:$BC25,"CARDIO-RAM *") | BE25: =COUNTIF($D25:$BC25,"CLINIC")+COUNTIF($D25:$BC25,"CLINIC *")+COUNTIF($D25:$BC25,"URGENT CARE")+COUNTIF($D25:$BC25,"URGENT CARE *") | BF25: =COUNTIF($D25:$BC25,"ED") | BG25: =COUNTIF($D25:$BC25,"A")+COUNTIF($D25:$BC25,"B")+COUNTIF($D25:$BC25,"C")+COUNTIF($D25:$BC25,"D")+COUNTIF($D25:$BC25,"G") | BH25: =COUNTIF($D25:$BC25,"ICU") | BI25: =COUNTIF($D25:$BC25,"ICU E") | BJ25: =COUNTIF($D25:$BC25,"ICU N") | BK25: =COUNTIF($D25:$BC25,"ID")+COUNTIF($D25:$BC25,"ID *") | BL25: =COUNTIF($D25:$BC25,"NEURO")+COUNTIF($D25:$BC25,"NEURO *") | BM25: =COUNTIF($D25:$BC25,"NF") | BN25: =COUNTIF($D25:$BC25,"SWING") | BO25: =COUNTIF($D25:$BC25,"VACATION") | BP25: =SUM(BD25:BO25) | BQ25: =COUNTIF($D25:$BC25,"PALLIATIVE")+COUNTIF($D25:$BC25,"PALLIATIVE *") | BR25: =COUNTIF($D25:$BC25,"GERIATRIC")+COUNTIF($D25:$BC25,"GERIATRIC 2") | BS25: =COUNTIF($D25:$BC25,"GS")+COUNTIF($D25:$BC25,"GI")+COUNTIF($D25:$BC25,"GI *") | BT25: =COUNTIF($D25:$BC25,"HEM/ONC")+COUNTIF($D25:$BC25,"HEM/ONC *") | BU25: =COUNTIF($D25:$BC25,"PAIN MANAGEMENT")+COUNTIF($D25:$BC25,"PAIN MANAGEMENT *") | BV25: =COUNTIF($D25:$BC25,"RHEUMA")+COUNTIF($D25:$BC25,"RHEUMA *") | BW25: =COUNTIF($D25:$BC25,"ENDO")+COUNTIF($D25:$BC25,"ENDO *") | BX25: =COUNTIF($D25:$BC25,"PLASTIC")+COUNTIF($D25:$BC25,"PLASTIC *") | BY25: =COUNTIF($D25:$BC25,"PULM")+COUNTIF($D25:$BC25,"PULM *") | BZ25: =COUNTIF($D25:$BC25,"SICU")+COUNTIF($D25:$BC25,"SICU *") | CA25: =COUNTIF($D25:$BC25,"DERMATOLOGY")+COUNTIF($D25:$BC25,"DERMATOLOGY *") | CB25: =COUNTIF($D25:$BC25,"NEPHRO")+COUNTIF($D25:$BC25,"NEPHRO *") | CC25: =SUM(BQ25:CB25) | CD25: =BP25+CC25
C26: M. Rodriguez | D26: VACATION | E26: VACATION | F26: CLINIC * | G26: CLINIC * | H26: CLINIC * | I26: NF | J26: NF | K26: CLINIC * | L26: CLINIC * | M26: NF | N26: NF | O26: NF | P26: CLINIC * | Q26: CLINIC * | R26: VACATION | S26: VACATION | T26: CLINIC * | U26: CLINIC * | V26: B | W26: B | X26: B | Y26: CLINIC | Z26: CLINIC | AA26: CLINIC | AB26: B | AC26: B | AD26: B | AE26: B | AF26: ICU E | AG26: CLINIC * | AH26: CLINIC * | AI26: CLINIC * | AJ26: CLINIC * | AK26: CLINIC * | AL26: CLINIC * | AM26: D | AN26: D | AO26: D | AP26: D | AQ26: CLINIC * | AR26: C | AS26: C | AT26: C | AU26: CLINIC * | AV26: CLINIC * | AW26: SWING | AX26: SWING | AY26: SWING | AZ26: ICU E | BA26: CLINIC * | BB26: NF | BC26: NF | BD26: =COUNTIF($D26:$BC26,"CARDIO")+COUNTIF($D26:$BC26,"CARDIO E")+COUNTIF($D26:$BC26,"CARDIO E *")+COUNTIF($D26:$BC26,"CARDIO-HCA")+COUNTIF($D26:$BC26,"CARDIO-HCA *")+COUNTIF($D26:$BC26,"CARDIO-RAM")+COUNTIF($D26:$BC26,"CARDIO-RAM *") | BE26: =COUNTIF($D26:$BC26,"CLINIC")+COUNTIF($D26:$BC26,"CLINIC *")+COUNTIF($D26:$BC26,"URGENT CARE")+COUNTIF($D26:$BC26,"URGENT CARE *") | BF26: =COUNTIF($D26:$BC26,"ED") | BG26: =COUNTIF($D26:$BC26,"A")+COUNTIF($D26:$BC26,"B")+COUNTIF($D26:$BC26,"C")+COUNTIF($D26:$BC26,"D")+COUNTIF($D26:$BC26,"G") | BH26: =COUNTIF($D26:$BC26,"ICU") | BI26: =COUNTIF($D26:$BC26,"ICU E") | BJ26: =COUNTIF($D26:$BC26,"ICU N") | BK26: =COUNTIF($D26:$BC26,"ID")+COUNTIF($D26:$BC26,"ID *") | BL26: =COUNTIF($D26:$BC26,"NEURO")+COUNTIF($D26:$BC26,"NEURO *") | BM26: =COUNTIF($D26:$BC26,"NF") | BN26: =COUNTIF($D26:$BC26,"SWING") | BO26: =COUNTIF($D26:$BC26,"VACATION") | BP26: =SUM(BD26:BO26) | BQ26: =COUNTIF($D26:$BC26,"PALLIATIVE")+COUNTIF($D26:$BC26,"PALLIATIVE *") | BR26: =COUNTIF($D26:$BC26,"GERIATRIC")+COUNTIF($D26:$BC26,"GERIATRIC 2") | BS26: =COUNTIF($D26:$BC26,"GS")+COUNTIF($D26:$BC26,"GI")+COUNTIF($D26:$BC26,"GI *") | BT26: =COUNTIF($D26:$BC26,"HEM/ONC")+COUNTIF($D26:$BC26,"HEM/ONC *") | BU26: =COUNTIF($D26:$BC26,"PAIN MANAGEMENT")+COUNTIF($D26:$BC26,"PAIN MANAGEMENT *") | BV26: =COUNTIF($D26:$BC26,"RHEUMA")+COUNTIF($D26:$BC26,"RHEUMA *") | BW26: =COUNTIF($D26:$BC26,"ENDO")+COUNTIF($D26:$BC26,"ENDO *") | BX26: =COUNTIF($D26:$BC26,"PLASTIC")+COUNTIF($D26:$BC26,"PLASTIC *") | BY26: =COUNTIF($D26:$BC26,"PULM")+COUNTIF($D26:$BC26,"PULM *") | BZ26: =COUNTIF($D26:$BC26,"SICU")+COUNTIF($D26:$BC26,"SICU *") | CA26: =COUNTIF($D26:$BC26,"DERMATOLOGY")+COUNTIF($D26:$BC26,"DERMATOLOGY *") | CB26: =COUNTIF($D26:$BC26,"NEPHRO")+COUNTIF($D26:$BC26,"NEPHRO *") | CC26: =SUM(BQ26:CB26) | CD26: =BP26+CC26
