Workbook

Sheet SCHEDULE
D1: Block 1 | I1: Block 2 | N1: Block 3 | X1: Block 5 | AC1: End of the year Block | AE1: Block 6 | AJ1: Block 7 | AO1: Block 8 | AT1: Block 9 | AY1: Block 10 | BD1: CARDIO | BE1: CLINIC | BF1: ED | BG1: FLOORS | BH1: ICU | BI1: ICU E | BJ1: ICU N | BK1: ID | BL1: NEURO | BM1: NF | BN1: SWING | BO1: VACATION | BP1: SUB-TOTAL | BQ1: PALLIATIVE | BR1: GERIATRIC | BS1: GS / GI | BT1: HEM/ONC | BU1: PAIN MANGEMENT | BV1: RHEUMA | BW1: ENDO | BX1: PLASTIC | BY1: PULM | BZ1: SICU | CA1: DERMATOLOGY | CB1: NEPHRO | CC1: SUB-TOTAL | CD1: TOTAL
D2: 1 | E2: 2 | F2: 3 | G2: 4 | H2: 5 | I2: 6 | J2: 7 | K2: 8 | L2: 9 | M2: 10 | N2: 11 | O2: 12 | P2: 13 | Q2: 14 | R2: 15 | S2: 16 | T2: 17 | U2: 18 | V2: 19 | W2: 20 | X2: 21 | Y2: 22 | Z2: 23 | AA2: 24 | AB2: 25 | AC2: 26 | AD2: 27 | AE2: 28 | AF2: 29 | AG2: 30 | AH2: 31 | AI2: 32 | AJ2: 33 | AK2: 34 | AL2: 35 | AM2: 36 | AN2: 37 | AO2: 38 | AP2: 39 | AQ2: 40 | AR2: 41 | AS2: 42 | AT2: 43 | AU2: 44 | AV2: 45 | AW2: 46 | AX2: 47 | AY2: 48 | AZ2: 49 | BA2: 50 | BB2: 51 | BC2: 52
A3: PGY | D3: 07/01-07/06 | E3: 07/07-07/13 | F3: 07/14-07/20 | G3: 07/21-07/27 | H3: 07/28-08/03 | I3: 08/04-08/10 | J3: 08/11-08/17 | K3: 08/18-08/24 | L3: 08/25-8/31 | M3: 09/01-09/07 | N3: 09/08-09/14 | O3: 09/15-09/21 | P3: 09/22-09/28 | Q3: 09/29-10/05 | R3: 10/06-10/12 | S3: 10/13-10/19 | T3: 10/20-10/26 | U3: 10/27-11/02 | V3: 11/03-11/09 | W3: 11/10-11/16 | X3: 11/17-11/23 | Y3: 11/24-11/30 | Z3: 12/01-12/07 | AA3: 12/08-12/14 | AB3: 12/15-12/21 | AC3: 12/22-12/28 | AD3: 12/29-01/04 | AE3: 01/05-01/11 | AF3: 01/12-01/18 | AG3: 01/19-01/25 | AH3: 01/26-02/01 | AI3: 02/02-02/08 | AJ3: 02/09-02/15 | AK3: 02/16-02/22 | AL3: 02/23-03/01 | AM3: 03/02-03/08 | AN3: 03/09-03/15 | AO3: 03/16-03/22 | AP3: 03/23-03/29 | AQ3: 03/30-04/05 | AR3: 04/06-04/12 | AS3: 04/13-04/19 | AT3: 04/20-04/26 | AU3: 04/27-05/03 | AV3: 05/04-05/10 | AW3: 05/11-05/17 | AX3: 05/18-05/24 | AY3: 05/25-05/31 | AZ3: 06/01-06/07 | BA3: 06/08-06/14 | BB3: 06/15-06/21 | BC3: 06/22-06/30
A4: Cohort 1 | B4: PGY-2 | C4: B. Perez | D4: CLINIC | E4: A | F4: A | G4: A | H4: A | I4: CLINIC | J4: ICU | K4: ICU | L4: ED | M4: ED | N4: CLINIC | O4: D | P4: D | Q4: D | R4: D | S4: CLINIC * | T4: ICU | U4: ICU | V4: VACATION | W4: VACATION | X4: CLINIC | Y4: A | Z4: A | AA4: A | AB4: A | AC4: ICU H | AD4: A | AE4: CLINIC | AF4: ICU | AG4: ID | AH4: CLINIC | AI4: D | AJ4: CLINIC | AK4: C | AL4: C | AM4: C | AN4: C | AO4: CLINIC | AP4: ICU N | AQ4: ICU N | AR4: CARDIO* | AS4: CARDIO | AT4: CLINIC | AU4: VACATION | AV4: VACATION | AW4: NF | AX4: NF | AY4: CLINIC | AZ4: D | BA4: C | BB4: ID * | BC4: C | BD4: =COUNTIF($D4:$BC4,"CARDIO")+COUNTIF($D4:$BC4,"CARDIO E")+COUNTIF($D4:$BC4,"CARDIO E *")+COUNTIF($D4:$BC4,"CARDIO-HCA")+COUNTIF($D4:$BC4,"CARDIO-HCA *")+COUNTIF($D4:$BC4,"CARDIO-RAM")+COUNTIF($D4:$BC4,"CARDIO-RAM *") | BE4: =COUNTIF($D4:$BC4,"CLINIC")+COUNTIF($D4:$BC4,"CLINIC *")+COUNTIF($D4:$BC4,"URGENT CARE")+COUNTIF($D4:$BC4,"URGENT CARE *") | BF4: =COUNTIF($D4:$BC4,"ED") | BG4: =COUNTIF($D4:$BC4,"A")+COUNTIF($D4:$BC4,"B")+COUNTIF($D4:$BC4,"C")+COUNTIF($D4:$BC4,"D")+COUNTIF($D4:$BC4,"G") | BH4: =COUNTIF($D4:$BC4,"ICU") | BI4: =COUNTIF($D4:$BC4,"ICU E") | BJ4: =COUNTIF($D4:$BC4,"ICU N") | BK4: =COUNTIF($D4:$BC4,"ID")+COUNTIF($D4:$BC4,"ID *") | BL4: =COUNTIF($D4:$BC4,"NEURO")+COUNTIF($D4:$BC4,"NEURO *") | BM4: =COUNTIF($D4:$BC4,"NF") | BN4: =COUNTIF($D4:$BC4,"SWING") | BO4: =COUNTIF($D4:$BC4,"VACATION") | BP4: =SUM(BD4:BO4) | BQ4: =COUNTIF($D4:$BC4,"PALLIATIVE")+COUNTIF($D4:$BC4,"PALLIATIVE *") | BR4: =COUNTIF($D4:$BC4,"GERIATRIC")+COUNTIF($D4:$BC4,"GERIATRIC 2") | BS4: =COUNTIF($D4:$BC4,"GS")+COUNTIF($D4:$BC4,"GI")+COUNTIF($D4:$BC4,"GI *") | BT4: =COUNTIF($D4:$BC4,"HEM/ONC")+COUNTIF($D4:$BC4,"HEM/ONC *") | BU4: =COUNTIF($D4:$BC4,"IR RADIOLOGY")+COUNTIF($D4:$BC4,"IR RADIOLOGY *") | BV4: =COUNTIF($D4:$BC4,"RHEUMA")+COUNTIF($D4:$BC4,"RHEUMA *") | BW4: =COUNTIF($D4:$BC4,"ENDO")+COUNTIF($D4:$BC4,"ENDO *") | BX4: =COUNTIF($D4:$BC4,"PLASTIC")+COUNTIF($D4:$BC4,"PLASTIC *") | BY4: =COUNTIF($D4:$BC4,"PULM")+COUNTIF($D4:$BC4,"PULM *") | BZ4: =COUNTIF($D4:$BC4,"SICU")+COUNTIF($D4:$BC4,"SICU *") | CA4: =COUNTIF($D4:$BC4,"DERMATOLOGY")+COUNTIF($D4:$BC4,"DERMATOLOGY *") | CB4: =COUNTIF($D4:$BC4,"NEPHRO")+COUNTIF($D4:$BC4,"NEPHRO *") | CC4: =SUM(BQ4:CB4) | CD4: =BP4+CC4
C5: L. Duarte | D5: CLINIC | E5: A | F5: A | G5: A | H5: A | I5: CLINIC | J5: ICU | K5: ICU | L5: ED | M5: ED | N5: CLINIC | O5: D | P5: D | Q5: D | R5: NF | S5: CLINIC | T5: ICU | U5: ICU | V5: VACATION | W5: VACATION | X5: CLINIC | Y5: A | Z5: A | AA5: A | AB5: A | AC5: ICU H | AD5: A | AE5: CLINIC | AF5: ICU | AG5: ICU | AH5: CLINIC * | AI5: D | AJ5: CLINIC | AK5: C | AL5: C | AM5: C | AN5: C | AO5: CLINIC | AP5: CARDIO | AQ5: CARDIO* | AR5: ICU N | AS5: ICU N | AT5: CLINIC | AU5: VACATION | AV5: VACATION | AW5: SWING | AX5: C | AY5: CLINIC | AZ5: D | BA5: NF | BB5: CARDIO | BC5: A | BD5: =COUNTIF($D5:$BC5,"CARDIO")+COUNTIF($D5:$BC5,"CARDIO E")+COUNTIF($D5:$BC5,"CARDIO E *")+COUNTIF($D5:$BC5,"CARDIO-HCA")+COUNTIF($D5:$BC5,"CARDIO-HCA *")+COUNTIF($D5:$BC5,"CARDIO-RAM")+COUNTIF($D5:$BC5,"CARDIO-RAM *") | BE5: =COUNTIF($D5:$BC5,"CLINIC")+COUNTIF($D5:$BC5,"CLINIC *")+COUNTIF($D5:$BC5,"URGENT CARE")+COUNTIF($D5:$BC5,"URGENT CARE *") | BF5: =COUNTIF($D5:$BC5,"ED") | BG5: =COUNTIF($D5:$BC5,"A")+COUNTIF($D5:$BC5,"B")+COUNTIF($D5:$BC5,"C")+COUNTIF($D5:$BC5,"D")+COUNTIF($D5:$BC5,"G") | BH5: =COUNTIF($D5:$BC5,"ICU") | BI5: =COUNTIF($D5:$BC5,"ICU E") | BJ5: =COUNTIF($D5:$BC5,"ICU N") | BK5: =COUNTIF($D5:$BC5,"ID")+COUNTIF($D5:$BC5,"ID *") | BL5: =COUNTIF($D5:$BC5,"NEURO")+COUNTIF($D5:$BC5,"NEURO *") | BM5: =COUNTIF($D5:$BC5,"NF") | BN5: =COUNTIF($D5:$BC5,"SWING") | BO5: =COUNTIF($D5:$BC5,"VACATION") | BP5: =SUM(BD5:BO5) | BQ5: =COUNTIF($D5:$BC5,"PALLIATIVE")+COUNTIF($D5:$BC5,"PALLIATIVE *") | BR5: =COUNTIF($D5:$BC5,"GERIATRIC")+COUNTIF($D5:$BC5,"GERIATRIC 2") | BS5: =COUNTIF($D5:$BC5,"GS")+COUNTIF($D5:$BC5,"GI")+COUNTIF($D5:$BC5,"GI *") | BT5: =COUNTIF($D5:$BC5,"HEM/ONC")+COUNTIF($D5:$BC5,"HEM/ONC *") | BU5: =COUNTIF($D5:$BC5,"PAIN MANAGEMENT")+COUNTIF($D5:$BC5,"PAIN MANAGEMENT *") | BV5: =COUNTIF($D5:$BC5,"RHEUMA")+COUNTIF($D5:$BC5,"RHEUMA *") | BW5: =COUNTIF($D5:$BC5,"ENDO")+COUNTIF($D5:$BC5,"ENDO *") | BX5: =COUNTIF($D5:$BC5,"PLASTIC")+COUNTIF($D5:$BC5,"PLASTIC *") | BY5: =COUNTIF($D5:$BC5,"PULM")+COUNTIF($D5:$BC5,"PULM *") | BZ5: =COUNTIF($D5:$BC5,"SICU")+COUNTIF($D5:$BC5,"SICU *") | CA5: =COUNTIF($D5:$BC5,"DERMATOLOGY")+COUNTIF($D5:$BC5,"DERMATOLOGY *") | CB5: =COUNTIF($D5:$BC5,"NEPHRO")+COUNTIF($D5:$BC5,"NEPHRO *") | CC5: =SUM(BQ5:CB5) | CD5: =BP5+CC5
B6: PGY-3 | C6: M. Garcia | D6: CLINIC | E6: HEM/ONC * | F6: CARDIO* | G6: CARDIO | H6: CLINIC | I6: CLINIC | J6: B | K6: G | L6: CARDIO | M6: CARDIO | N6: CLINIC | O6: NEPHRO | P6: ICU | Q6: ICU | R6: NEURO | S6: CLINIC | T6: NEURO | U6: ICU | V6: VACATION | W6: VACATION | X6: CLINIC | Y6: ED | Z6: ED | AA6: ICU N | AB6: NF | AC6: ICU H | AD6: B | AE6: CLINIC | AF6: B | AG6: B | AH6: B | AI6: CLINIC | AJ6: CLINIC | AK6: B | AL6: B | AM6: SWING | AN6: ICU N | AO6: CLINIC | AP6: A | AQ6: A | AR6: VACATION | AS6: VACATION | AT6: CLINIC | AU6: ICU | AV6: ICU | AW6: SWING | AX6: SWING | AY6: CLINIC | AZ6: ICU | BA6: CLINIC | BB6: D | BC6: NF | BD6: =COUNTIF($D6:$BC6,"CARDIO")+COUNTIF($D6:$BC6,"CARDIO E")+COUNTIF($D6:$BC6,"CARDIO E *")+COUNTIF($D6:$BC6,"CARDIO-HCA")+COUNTIF($D6:$BC6,"CARDIO-HCA *")+COUNTIF($D6:$BC6,"CARDIO-RAM")+COUNTIF($D6:$BC6,"CARDIO-RAM *") | BE6: =COUNTIF($D6:$BC6,"CLINIC")+COUNTIF($D6:$BC6,"CLINIC *")+COUNTIF($D6:$BC6,"URGENT CARE")+COUNTIF($D6:$BC6,"URGENT CARE *") | BF6: =COUNTIF($D6:$BC6,"ED") | BG6: =COUNTIF($D6:$BC6,"A")+COUNTIF($D6:$BC6,"B")+COUNTIF($D6:$BC6,"C")+COUNTIF($D6:$BC6,"D")+COUNTIF($D6:$BC6,"G") | BH6: =COUNTIF($D6:$BC6,"ICU") | BI6: =COUNTIF($D6:$BC6,"ICU E") | BJ6: =COUNTIF($D6:$BC6,"ICU N") | BK6: =COUNTIF($D6:$BC6,"ID")+COUNTIF($D6:$BC6,"ID *") | BL6: =COUNTIF($D6:$BC6,"NEURO")+COUNTIF($D6:$BC6,"NEURO *") | BM6: =COUNTIF($D6:$BC6,"NF") | BN6: =COUNTIF($D6:$BC6,"SWING") | BO6: =COUNTIF($D6:$BC6,"VACATION") | BP6: =SUM(BD6:BO6) | BQ6: =COUNTIF($D6:$BC6,"PALLIATIVE")+COUNTIF($D6:$BC6,"PALLIATIVE *") | BR6: =COUNTIF($D6:$BC6,"GERIATRIC")+COUNTIF($D6:$BC6,"GERIATRIC 2") | BS6: =COUNTIF($D6:$BC6,"GS")+COUNTIF($D6:$BC6,"GI")+COUNTIF($D6:$BC6,"GI *") | BT6: =COUNTIF($D6:$BC6,"HEM/ONC")+COUNTIF($D6:$BC6,"HEM/ONC *") | BU6: =COUNTIF($D6:$BC6,"PAIN MANAGEMENT")+COUNTIF($D6:$BC6,"PAIN MANAGEMENT *") | BV6: =COUNTIF($D6:$BC6,"RHEUMA")+COUNTIF($D6:$BC6,"RHEUMA *") | BW6: =COUNTIF($D6:$BC6,"ENDO")+COUNTIF($D6:$BC6,"ENDO *") | BX6: =COUNTIF($D6:$BC6,"PLASTIC")+COUNTIF($D6:$BC6,"PLASTIC *") | BY6: =COUNTIF($D6:$BC6,"PULM")+COUNTIF($D6:$BC6,"PULM *") | BZ6: =COUNTIF($D6:$BC6,"SICU")+COUNTIF($D6:$BC6,"SICU *") | CA6: =COUNTIF($D6:$BC6,"DERMATOLOGY")+COUNTIF($D6:$BC6,"DERMATOLOGY *") | CB6: =COUNTIF($D6:$BC6,"NEPHRO")+COUNTIF($D6:$BC6,"NEPHRO *") | CC6: =SUM(BQ6:CB6) | CD6: =BP6+CC6
C7: D. Cano | D7: CLINIC | E7: NEURO | F7: CARDIO | G7: CARDIO | H7: G | I7: CLINIC | J7: ICU N | K7: ICU N | L7: CARDIO | M7: CARDIO | N7: CLINIC | O7: HEM/ONC | P7: ICU | Q7: VACATION | R7: VACATION | S7: CLINIC | T7: ICU | U7: ICU | V7: D | W7: C | X7: CLINIC | Y7: ED | Z7: ED | AA7: CLINIC | AB7: ICU | AC7: ICU | AD7: ICU H* | AE7: CLINIC | AF7: NEURO * | AG7: A | AH7: ICU N | AI7: CLINIC | AJ7: CLINIC | AK7: A | AL7: A | AM7: VACATION | AN7: VACATION | AO7: CLINIC | AP7: B | AQ7: B | AR7: B | AS7: B | AT7: CLINIC | AU7: SWING | AV7: SWING | AW7: D | AX7: CLINIC | AY7: CLINIC | AZ7: NF | BA7: NF | BB7: CLINIC * | BC7: D | BD7: =COUNTIF($D7:$BC7,"CARDIO")+COUNTIF($D7:$BC7,"CARDIO E")+COUNTIF($D7:$BC7,"CARDIO E *")+COUNTIF($D7:$BC7,"CARDIO-HCA")+COUNTIF($D7:$BC7,"CARDIO-HCA *")+COUNTIF($D7:$BC7,"CARDIO-RAM")+COUNTIF($D7:$BC7,"CARDIO-RAM *") | BE7: =COUNTIF($D7:$BC7,"CLINIC")+COUNTIF($D7:$BC7,"CLINIC *")+COUNTIF($D7:$BC7,"URGENT CARE")+COUNTIF($D7:$BC7,"URGENT CARE *") | BF7: =COUNTIF($D7:$BC7,"ED") | BG7: =COUNTIF($D7:$BC7,"A")+COUNTIF($D7:$BC7,"B")+COUNTIF($D7:$BC7,"C")+COUNTIF($D7:$BC7,"D")+COUNTIF($D7:$BC7,"G") | BH7: =COUNTIF($D7:$BC7,"ICU") | BI7: =COUNTIF($D7:$BC7,"ICU E") | BJ7: =COUNTIF($D7:$BC7,"ICU N") | BK7: =COUNTIF($D7:$BC7,"ID")+COUNTIF($D7:$BC7,"ID *") | BL7: =COUNTIF($D7:$BC7,"NEURO")+COUNTIF($D7:$BC7,"NEURO *") | BM7: =COUNTIF($D7:$BC7,"NF") | BN7: =COUNTIF($D7:$BC7,"SWING") | BO7: =COUNTIF($D7:$BC7,"VACATION") | BP7: =SUM(BD7:BO7) | BQ7: =COUNTIF($D7:$BC7,"PALLIATIVE")+COUNTIF($D7:$BC7,"PALLIATIVE *") | BR7: =COUNTIF($D7:$BC7,"GERIATRIC")+COUNTIF($D7:$BC7,"GERIATRIC 2") | BS7: =COUNTIF($D7:$BC7,"GS")+COUNTIF($D7:$BC7,"GI")+COUNTIF($D7:$BC7,"GI *") | BT7: =COUNTIF($D7:$BC7,"HEM/ONC")+COUNTIF($D7:$BC7,"HEM/ONC *") | BU7: =COUNTIF($D7:$BC7,"PAIN MANAGEMENT")+COUNTIF($D7:$BC7,"PAIN MANAGEMENT *") | BV7: =COUNTIF($D7:$BC7,"RHEUMA")+COUNTIF($D7:$BC7,"RHEUMA *") | BW7: =COUNTIF($D7:$BC7,"ENDO")+COUNTIF($D7:$BC7,"ENDO *") | BX7: =COUNTIF($D7:$BC7,"PLASTIC")+COUNTIF($D7:$BC7,"PLASTIC *") | BY7: =COUNTIF($D7:$BC7,"PULM")+COUNTIF($D7:$BC7,"PULM *") | BZ7: =COUNTIF($D7:$BC7,"SICU")+COUNTIF($D7:$BC7,"SICU *") | CA7: =COUNTIF($D7:$BC7,"DERMATOLOGY")+COUNTIF($D7:$BC7,"DERMATOLOGY *") | CB7: =COUNTIF($D7:$BC7,"NEPHRO")+COUNTIF($D7:$BC7,"NEPHRO *") | CC7: =SUM(BQ7:CB7) | CD7: =BP7+CC7
B8: PGY-3 | C8: J. Melendez | D8: CLINIC | E8: C | F8: HEM/ONC | G8: HEM/ONC | H8: CLINIC | I8: CLINIC | J8: SWING | K8: NF | L8: NEURO | M8: D | N8: CLINIC | O8: G | P8: CLINIC | Q8: ICU N | R8: CARDIO | S8: CLINIC | T8: A | U8: A | V8: VACATION | W8: VACATION | X8: CLINIC | Y8: C | Z8: ICU | AA8: ICU | AB8: RHEUMA | AC8: ICU H | AD8: CLINIC | AE8: CLINIC | AF8: A | AG8: ID | AH8: RHEUMA | AI8: RHEUMA | AJ8: CLINIC | AK8: PULM | AL8: PULM | AM8: RHEUMA * | AN8: CLINIC | AO8: CLINIC | AP8: ID | AQ8: VACATION | AR8: VACATION | AS8: RHEUMA | AT8: CLINIC | AU8: GERIATRIC 2 | AV8: GERIATRIC 2 | AW8: RHEUMA | AX8: RHEUMA | AY8: CLINIC | AZ8: RHEUMA | BA8: RHEUMA | BB8: NEPHRO | BC8: NEPHRO | BD8: =COUNTIF($D8:$BC8,"CARDIO")+COUNTIF($D8:$BC8,"CARDIO E")+COUNTIF($D8:$BC8,"CARDIO E *")+COUNTIF($D8:$BC8,"CARDIO-HCA")+COUNTIF($D8:$BC8,"CARDIO-HCA *")+COUNTIF($D8:$BC8,"CARDIO-RAM")+COUNTIF($D8:$BC8,"CARDIO-RAM *") | BE8: =COUNTIF($D8:$BC8,"CLINIC")+COUNTIF($D8:$BC8,"CLINIC *")+COUNTIF($D8:$BC8,"URGENT CARE")+COUNTIF($D8:$BC8,"URGENT CARE *") | BF8: =COUNTIF($D8:$BC8,"ED") | BG8: =COUNTIF($D8:$BC8,"A")+COUNTIF($D8:$BC8,"B")+COUNTIF($D8:$BC8,"C")+COUNTIF($D8:$BC8,"D")+COUNTIF($D8:$BC8,"G") | BH8: =COUNTIF($D8:$BC8,"ICU") | BI8: =COUNTIF($D8:$BC8,"ICU E") | BJ8: =COUNTIF($D8:$BC8,"ICU N") | BK8: =COUNTIF($D8:$BC8,"ID")+COUNTIF($D8:$BC8,"ID *") | BL8: =COUNTIF($D8:$BC8,"NEURO")+COUNTIF($D8:$BC8,"NEURO *") | BM8: =COUNTIF($D8:$BC8,"NF") | BN8: =COUNTIF($D8:$BC8,"SWING") | BO8: =COUNTIF($D8:$BC8,"VACATION") | BP8: =SUM(BD8:BO8) | BQ8: =COUNTIF($D8:$BC8,"PALLIATIVE")+COUNTIF($D8:$BC8,"PALLIATIVE *") | BR8: =COUNTIF($D8:$BC8,"GERIATRIC")+COUNTIF($D8:$BC8,"GERIATRIC 2") | BS8: =COUNTIF($D8:$BC8,"GS")+COUNTIF($D8:$BC8,"GI")+COUNTIF($D8:$BC8,"GI *") | BT8: =COUNTIF($D8:$BC8,"HEM/ONC")+COUNTIF($D8:$BC8,"HEM/ONC *") | BU8: =COUNTIF($D8:$BC8,"PAIN MANAGEMENT")+COUNTIF($D8:$BC8,"PAIN MANAGEMENT *") | BV8: =COUNTIF($D8:$BC8,"RHEUMA")+COUNTIF($D8:$BC8,"RHEUMA *") | BW8: =COUNTIF($D8:$BC8,"ENDO")+COUNTIF($D8:$BC8,"ENDO *") | BX8: =COUNTIF($D8:$BC8,"PLASTIC")+COUNTIF($D8:$BC8,"PLASTIC *") | BY8: =COUNTIF($D8:$BC8,"PULM")+COUNTIF($D8:$BC8,"PULM *") | BZ8: =COUNTIF($D8:$BC8,"SICU")+COUNTIF($D8:$BC8,"SICU *") | CA8: =COUNTIF($D8:$BC8,"DERMATOLOGY")+COUNTIF($D8:$BC8,"DERMATOLOGY *") | CB8: =COUNTIF($D8:$BC8,"NEPHRO")+COUNTIF($D8:$BC8,"NEPHRO *") | CC8: =SUM(BQ8:CB8) | CD8: =BP8+CC8
C9: C. Correa | D9: CLINIC | E9: CLINIC | F9: B | G9: B | H9: CLINIC | I9: SWING | J9: VACATION | K9: VACATION | L9: HEM/ONC * | M9: ICU | N9: CLINIC | O9: CLINIC | P9: D | Q9: ICU | R9: CARDIO | S9: CLINIC | T9: D | U9: ID | V9: CLINIC | W9: ICU N | X9: CLINIC | Y9: PALLIATIVE | Z9: ICU | AA9: ICU | AB9: CLINIC | AC9: ICU H | AD9: A | AE9: CLINIC | AF9: D | AG9: ICU N | AH9: PALLIATIVE | AI9: RHEUMA | AJ9: CLINIC | AK9: PULM | AL9: PULM | AM9: DERMATOLOGY | AN9: CLINIC | AO9: CLINIC | AP9: VACATION | AQ9: VACATION | AR9: GERIATRIC | AS9: GERIATRIC | AT9: CLINIC | AU9: GI | AV9: GI | AW9: HEM/ONC | AX9: HEM/ONC | AY9: CLINIC | AZ9: GI | BA9: GI | BB9: CLINIC | BC9: HEM/ONC | BD9: =COUNTIF($D9:$BC9,"CARDIO")+COUNTIF($D9:$BC9,"CARDIO E")+COUNTIF($D9:$BC9,"CARDIO E *")+COUNTIF($D9:$BC9,"CARDIO-HCA")+COUNTIF($D9:$BC9,"CARDIO-HCA *")+COUNTIF($D9:$BC9,"CARDIO-RAM")+COUNTIF($D9:$BC9,"CARDIO-RAM *") | BE9: =COUNTIF($D9:$BC9,"CLINIC")+COUNTIF($D9:$BC9,"CLINIC *")+COUNTIF($D9:$BC9,"URGENT CARE")+COUNTIF($D9:$BC9,"URGENT CARE *") | BF9: =COUNTIF($D9:$BC9,"ED") | BG9: =COUNTIF($D9:$BC9,"A")+COUNTIF($D9:$BC9,"B")+COUNTIF($D9:$BC9,"C")+COUNTIF($D9:$BC9,"D")+COUNTIF($D9:$BC9,"G") | BH9: =COUNTIF($D9:$BC9,"ICU") | BI9: =COUNTIF($D9:$BC9,"ICU E") | BJ9: =COUNTIF($D9:$BC9,"ICU N") | BK9: =COUNTIF($D9:$BC9,"ID")+COUNTIF($D9:$BC9,"ID *") | BL9: =COUNTIF($D9:$BC9,"NEURO")+COUNTIF($D9:$BC9,"NEURO *") | BM9: =COUNTIF($D9:$BC9,"NF") | BN9: =COUNTIF($D9:$BC9,"SWING") | BO9: =COUNTIF($D9:$BC9,"VACATION") | BP9: =SUM(BD9:BO9) | BQ9: =COUNTIF($D9:$BC9,"PALLIATIVE")+COUNTIF($D9:$BC9,"PALLIATIVE *") | BR9: =COUNTIF($D9:$BC9,"GERIATRIC")+COUNTIF($D9:$BC9,"GERIATRIC 2") | BS9: =COUNTIF($D9:$BC9,"GS")+COUNTIF($D9:$BC9,"GI")+COUNTIF($D9:$BC9,"GI *") | BT9: =COUNTIF($D9:$BC9,"HEM/ONC")+COUNTIF($D9:$BC9,"HEM/ONC *") | BU9: =COUNTIF($D9:$BC9,"PAIN MANAGEMENT")+COUNTIF($D9:$BC9,"PAIN MANAGEMENT *") | BV9: =COUNTIF($D9:$BC9,"RHEUMA")+COUNTIF($D9:$BC9,"RHEUMA *") | BW9: =COUNTIF($D9:$BC9,"ENDO")+COUNTIF($D9:$BC9,"ENDO *") | BX9: =COUNTIF($D9:$BC9,"PLASTIC")+COUNTIF($D9:$BC9,"PLASTIC *") | BY9: =COUNTIF($D9:$BC9,"PULM")+COUNTIF($D9:$BC9,"PULM *") | BZ9: =COUNTIF($D9:$BC9,"SICU")+COUNTIF($D9:$BC9,"SICU *") | CA9: =COUNTIF($D9:$BC9,"DERMATOLOGY")+COUNTIF($D9:$BC9,"DERMATOLOGY *") | CB9: =COUNTIF($D9:$BC9,"NEPHRO")+COUNTIF($D9:$BC9,"NEPHRO *") | CC9: =SUM(BQ9:CB9) | CD9: =BP9+CC9
C10: L. Diaz-Fajardo | D10: CLINIC | E10: PALLIATIVE | F10: ICU | G10: ICU | H10: ICU N | I10: CLINIC | J10: CLINIC | K10: PULM | L10: ICU | M10: ID | N10: CLINIC | O10: VACATION | P10: VACATION | Q10: NF | R10: CLINIC * | S10: CLINIC | T10: C | U10: C | V10: NEPHRO | W10: SWING | X10: CLINIC | Y10: CLINIC | Z10: D | AA10: PALLIATIVE | AB10: D | AC10: ICU H | AD10: CLINIC | AE10: CLINIC | AF10: G | AG10: RHEUMA | AH10: PALLIATIVE | AI10: CARDIO | AJ10: CLINIC | AK10: VACATION | AL10: VACATION | AM10: CLINIC | AN10: CARDIO | AO10: CLINIC | AP10: GERIATRIC 2 | AQ10: GERIATRIC 2 | AR10: HEM/ONC | AS10: CLINIC | AT10: CLINIC | AU10: PULM | AV10: GI | AW10: CLINIC | AX10: GI | AY10: CLINIC | AZ10: PAIN MANAGEMENT * | BA10: PAIN MANAGEMENT | BB10: CLINIC | BC10: RHEUMA | BD10: =COUNTIF($D10:$BC10,"CARDIO")+COUNTIF($D10:$BC10,"CARDIO E")+COUNTIF($D10:$BC10,"CARDIO E *")+COUNTIF($D10:$BC10,"CARDIO-HCA")+COUNTIF($D10:$BC10,"CARDIO-HCA *")+COUNTIF($D10:$BC10,"CARDIO-RAM")+COUNTIF($D10:$BC10,"CARDIO-RAM *") | BE10: =COUNTIF($D10:$BC10,"CLINIC")+COUNTIF($D10:$BC10,"CLINIC *")+COUNTIF($D10:$BC10,"URGENT CARE")+COUNTIF($D10:$BC10,"URGENT CARE *") | BF10: =COUNTIF($D10:$BC10,"ED") | BG10: =COUNTIF($D10:$BC10,"A")+COUNTIF($D10:$BC10,"B")+COUNTIF($D10:$BC10,"C")+COUNTIF($D10:$BC10,"D")+COUNTIF($D10:$BC10,"G") | BH10: =COUNTIF($D10:$BC10,"ICU") | BI10: =COUNTIF($D10:$BC10,"ICU E") | BJ10: =COUNTIF($D10:$BC10,"ICU N") | BK10: =COUNTIF($D10:$BC10,"ID")+COUNTIF($D10:$BC10,"ID *") | BL10: =COUNTIF($D10:$BC10,"NEURO")+COUNTIF($D10:$BC10,"NEURO *") | BM10: =COUNTIF($D10:$BC10,"NF") | BN10: =COUNTIF($D10:$BC10,"SWING") | BO10: =COUNTIF($D10:$BC10,"VACATION") | BP10: =SUM(BD10:BO10) | BQ10: =COUNTIF($D10:$BC10,"PALLIATIVE")+COUNTIF($D10:$BC10,"PALLIATIVE *") | BR10: =COUNTIF($D10:$BC10,"GERIATRIC")+COUNTIF($D10:$BC10,"GERIATRIC 2") | BS10: =COUNTIF($D10:$BC10,"GS")+COUNTIF($D10:$BC10,"GI")+COUNTIF($D10:$BC10,"GI *") | BT10: =COUNTIF($D10:$BC10,"HEM/ONC")+COUNTIF($D10:$BC10,"HEM/ONC *") | BU10: =COUNTIF($D10:$BC10,"PAIN MANAGEMENT")+COUNTIF($D10:$BC10,"PAIN MANAGEMENT *") | BV10: =COUNTIF($D10:$BC10,"RHEUMA")+COUNTIF($D10:$BC10,"RHEUMA *") | BW10: =COUNTIF($D10:$BC10,"ENDO")+COUNTIF($D10:$BC10,"ENDO *") | BX10: =COUNTIF($D10:$BC10,"PLASTIC")+COUNTIF($D10:$BC10,"PLASTIC *") | BY10: =COUNTIF($D10:$BC10,"PULM")+COUNTIF($D10:$BC10,"PULM *") | BZ10: =COUNTIF($D10:$BC10,"SICU")+COUNTIF($D10:$BC10,"SICU *") | CA10: =COUNTIF($D10:$BC10,"DERMATOLOGY")+COUNTIF($D10:$BC10,"DERMATOLOGY *") | CB10: =COUNTIF($D10:$BC10,"NEPHRO")+COUNTIF($D10:$BC10,"NEPHRO *") | CC10: =SUM(BQ10:CB10) | CD10: =BP10+CC10
C11: J. Garcia-Blaya | D11: CLINIC | E11: VACATION | F11: VACATION | G11: D | H11: D | I11: CLINIC | J11: A | K11: ICU | L11: ICU | M11: C | N11: CLINIC | O11: C | P11: C | Q11: CLINIC | R11: SWING | S11: CLINIC | T11: ICU N | U11: CLINIC | V11: GI | W11: B | X11: CLINIC | Y11: HEM/ONC | Z11: NF | AA11: NF | AB11: GI | AC11: A | AD11: ICU H | AE11: CLINIC | AF11: ID | AG11: RHEUMA | AH11: CARDIO | AI11: CARDIO | AJ11: CLINIC | AK11: PAIN MANAGEMENT | AL11: PAIN MANAGEMENT | AM11: HEM/ONC | AN11: GERIATRIC | AO11: GERIATRIC | AP11: VACATION | AQ11: VACATION | AR11: PALLIATIVE | AS11: CLINIC | AT11: CLINIC | AU11: PULM | AV11: CLINIC * | AW11: HEM/ONC | AX11: PALLIATIVE | AY11: CLINIC | AZ11: NEPHRO | BA11: NEPHRO | BB11: CLINIC | BC11: DERMATOLOGY | BD11: =COUNTIF($D11:$BC11,"CARDIO")+COUNTIF($D11:$BC11,"CARDIO E")+COUNTIF($D11:$BC11,"CARDIO E *")+COUNTIF($D11:$BC11,"CARDIO-HCA")+COUNTIF($D11:$BC11,"CARDIO-HCA *")+COUNTIF($D11:$BC11,"CARDIO-RAM")+COUNTIF($D11:$BC11,"CARDIO-RAM *") | BE11: =COUNTIF($D11:$BC11,"CLINIC")+COUNTIF($D11:$BC11,"CLINIC *")+COUNTIF($D11:$BC11,"URGENT CARE")+COUNTIF($D11:$BC11,"URGENT CARE *") | BF11: =COUNTIF($D11:$BC11,"ED") | BG11: =COUNTIF($D11:$BC11,"A")+COUNTIF($D11:$BC11,"B")+COUNTIF($D11:$BC11,"C")+COUNTIF($D11:$BC11,"D")+COUNTIF($D11:$BC11,"G") | BH11: =COUNTIF($D11:$BC11,"ICU") | BI11: =COUNTIF($D11:$BC11,"ICU E") | BJ11: =COUNTIF($D11:$BC11,"ICU N") | BK11: =COUNTIF($D11:$BC11,"ID")+COUNTIF($D11:$BC11,"ID *") | BL11: =COUNTIF($D11:$BC11,"NEURO")+COUNTIF($D11:$BC11,"NEURO *") | BM11: =COUNTIF($D11:$BC11,"NF") | BN11: =COUNTIF($D11:$BC11,"SWING") | BO11: =COUNTIF($D11:$BC11,"VACATION") | BP11: =SUM(BD11:BO11) | BQ11: =COUNTIF($D11:$BC11,"PALLIATIVE")+COUNTIF($D11:$BC11,"PALLIATIVE *") | BR11: =COUNTIF($D11:$BC11,"GERIATRIC")+COUNTIF($D11:$BC11,"GERIATRIC 2") | BS11: =COUNTIF($D11:$BC11,"GS")+COUNTIF($D11:$BC11,"GI")+COUNTIF($D11:$BC11,"GI *") | BT11: =COUNTIF($D11:$BC11,"HEM/ONC")+COUNTIF($D11:$BC11,"HEM/ONC *") | BU11: =COUNTIF($D11:$BC11,"PAIN MANAGEMENT")+COUNTIF($D11:$BC11,"PAIN MANAGEMENT *") | BV11: =COUNTIF($D11:$BC11,"RHEUMA")+COUNTIF($D11:$BC11,"RHEUMA *") | BW11: =COUNTIF($D11:$BC11,"ENDO")+COUNTIF($D11:$BC11,"ENDO *") | BX11: =COUNTIF($D11:$BC11,"PLASTIC")+COUNTIF($D11:$BC11,"PLASTIC *") | BY11: =COUNTIF($D11:$BC11,"PULM")+COUNTIF($D11:$BC11,"PULM *") | BZ11: =COUNTIF($D11:$BC11,"SICU")+COUNTIF($D11:$BC11,"SICU *") | CA11: =COUNTIF($D11:$BC11,"DERMATOLOGY")+COUNTIF($D11:$BC11,"DERMATOLOGY *") | CB11: =COUNTIF($D11:$BC11,"NEPHRO")+COUNTIF($D11:$BC11,"NEPHRO *") | CC11: =SUM(BQ11:CB11) | CD11: =BP11+CC11
A12: Cohort 2 | B12: PGY-2 | C12: J. Jhooty | D12: ID* | E12: CLINIC | F12: B | G12: B | H12: B | I12: B | J12: CLINIC | K12: NF | L12: NF | M12: CLINIC | N12: ID * | O12: CLINIC | P12: VACATION | Q12: VACATION | R12: C | S12: C | T12: CLINIC | U12: A | V12: A | W12: A | X12: A | Y12: CLINIC * | Z12: C | AA12: C | AB12: C | AC12: C | AD12: ICU H | AE12: CLINIC | AF12: CLINIC | AG12: CARDIO | AH12: GI | AI12: RHEUMA | AJ12: RHEUMA | AK12: CLINIC | AL12: CARDIO | AM12: CARDIO | AN12: ICU | AO12: ICU | AP12: CLINIC | AQ12: VACATION | AR12: VACATION | AS12: ICU | AT12: ICU | AU12: CLINIC | AV12: B | AW12: ICU | AX12: ICU | AY12: C | AZ12: CLINIC | BA12: D | BB12: ICU | BC12: ICU | BD12: =COUNTIF($D12:$BC12,"CARDIO")+COUNTIF($D12:$BC12,"CARDIO E")+COUNTIF($D12:$BC12,"CARDIO E *")+COUNTIF($D12:$BC12,"CARDIO-HCA")+COUNTIF($D12:$BC12,"CARDIO-HCA *")+COUNTIF($D12:$BC12,"CARDIO-RAM")+COUNTIF($D12:$BC12,"CARDIO-RAM *") | BE12: =COUNTIF($D12:$BC12,"CLINIC")+COUNTIF($D12:$BC12,"CLINIC *")+COUNTIF($D12:$BC12,"URGENT CARE")+COUNTIF($D12:$BC12,"URGENT CARE *") | BF12: =COUNTIF($D12:$BC12,"ED") | BG12: =COUNTIF($D12:$BC12,"A")+COUNTIF($D12:$BC12,"B")+COUNTIF($D12:$BC12,"C")+COUNTIF($D12:$BC12,"D")+COUNTIF($D12:$BC12,"G") | BH12: =COUNTIF($D12:$BC12,"ICU") | BI12: =COUNTIF($D12:$BC12,"ICU E") | BJ12: =COUNTIF($D12:$BC12,"ICU N") | BK12: =COUNTIF($D12:$BC12,"ID")+COUNTIF($D12:$BC12,"ID *") | BL12: =COUNTIF($D12:$BC12,"NEURO")+COUNTIF($D12:$BC12,"NEURO *") | BM12: =COUNTIF($D12:$BC12,"NF") | BN12: =COUNTIF($D12:$BC12,"SWING") | BO12: =COUNTIF($D12:$BC12,"VACATION") | BP12: =SUM(BD12:BO12) | BQ12: =COUNTIF($D12:$BC12,"PALLIATIVE")+COUNTIF($D12:$BC12,"PALLIATIVE *") | BR12: =COUNTIF($D12:$BC12,"GERIATRIC")+COUNTIF($D12:$BC12,"GERIATRIC 2") | BS12: =COUNTIF($D12:$BC12,"GS")+COUNTIF($D12:$BC12,"GI")+COUNTIF($D12:$BC12,"GI *") | BT12: =COUNTIF($D12:$BC12,"HEM/ONC")+COUNTIF($D12:$BC12,"HEM/ONC *") | BU12: =COUNTIF($D12:$BC12,"PAIN MANAGEMENT")+COUNTIF($D12:$BC12,"PAIN MANAGEMENT *") | BV12: =COUNTIF($D12:$BC12,"RHEUMA")+COUNTIF($D12:$BC12,"RHEUMA *") | BW12: =COUNTIF($D12:$BC12,"ENDO")+COUNTIF($D12:$BC12,"ENDO *") | BX12: =COUNTIF($D12:$BC12,"PLASTIC")+COUNTIF($D12:$BC12,"PLASTIC *") | BY12: =COUNTIF($D12:$BC12,"PULM")+COUNTIF($D12:$BC12,"PULM *") | BZ12: =COUNTIF($D12:$BC12,"SICU")+COUNTIF($D12:$BC12,"SICU *") | CA12: =COUNTIF($D12:$BC12,"DERMATOLOGY")+COUNTIF($D12:$BC12,"DERMATOLOGY *") | CB12: =COUNTIF($D12:$BC12,"NEPHRO")+COUNTIF($D12:$BC12,"NEPHRO *") | CC12: =SUM(BQ12:CB12) | CD12: =BP12+CC12
C13: M. Artavia | D13: ID | E13: CLINIC | F13: B | G13: B | H13: B | I13: B | J13: CLINIC | K13: GI * | L13: C | M13: C | N13: GI | O13: CLINIC | P13: ICU N | Q13: ICU N | R13: C | S13: C | T13: CLINIC | U13: VACATION | V13: VACATION | W13: ICU | X13: ICU | Y13: CLINIC | Z13: C | AA13: C | AB13: C | AC13: C | AD13: ICU H | AE13: C | AF13: CLINIC | AG13: CARDIO* | AH13: CARDIO | AI13: ICU N | AJ13: ICU N | AK13: CLINIC | AL13: ED | AM13: ED | AN13: VACATION | AO13: VACATION | AP13: CLINIC | AQ13: ICU | AR13: ICU | AS13: A | AT13: A | AU13: CLINIC * | AV13: C | AW13: CLINIC * | AX13: GI | AY13: A | AZ13: CLINIC | BA13: D | BB13: CLINIC | BC13: A | BD13: =COUNTIF($D13:$BC13,"CARDIO")+COUNTIF($D13:$BC13,"CARDIO E")+COUNTIF($D13:$BC13,"CARDIO E *")+COUNTIF($D13:$BC13,"CARDIO-HCA")+COUNTIF($D13:$BC13,"CARDIO-HCA *")+COUNTIF($D13:$BC13,"CARDIO-RAM")+COUNTIF($D13:$BC13,"CARDIO-RAM *") | BE13: =COUNTIF($D13:$BC13,"CLINIC")+COUNTIF($D13:$BC13,"CLINIC *")+COUNTIF($D13:$BC13,"URGENT CARE")+COUNTIF($D13:$BC13,"URGENT CARE *") | BF13: =COUNTIF($D13:$BC13,"ED") | BG13: =COUNTIF($D13:$BC13,"A")+COUNTIF($D13:$BC13,"B")+COUNTIF($D13:$BC13,"C")+COUNTIF($D13:$BC13,"D")+COUNTIF($D13:$BC13,"G") | BH13: =COUNTIF($D13:$BC13,"ICU") | BI13: =COUNTIF($D13:$BC13,"ICU E") | BJ13: =COUNTIF($D13:$BC13,"ICU N") | BK13: =COUNTIF($D13:$BC13,"ID")+COUNTIF($D13:$BC13,"ID *") | BL13: =COUNTIF($D13:$BC13,"NEURO")+COUNTIF($D13:$BC13,"NEURO *") | BM13: =COUNTIF($D13:$BC13,"NF") | BN13: =COUNTIF($D13:$BC13,"SWING") | BO13: =COUNTIF($D13:$BC13,"VACATION") | BP13: =SUM(BD13:BO13) | BQ13: =COUNTIF($D13:$BC13,"PALLIATIVE")+COUNTIF($D13:$BC13,"PALLIATIVE *") | BR13: =COUNTIF($D13:$BC13,"GERIATRIC")+COUNTIF($D13:$BC13,"GERIATRIC 2") | BS13: =COUNTIF($D13:$BC13,"GS")+COUNTIF($D13:$BC13,"GI")+COUNTIF($D13:$BC13,"GI *") | BT13: =COUNTIF($D13:$BC13,"HEM/ONC")+COUNTIF($D13:$BC13,"HEM/ONC *") | BU13: =COUNTIF($D13:$BC13,"PAIN MANAGEMENT")+COUNTIF($D13:$BC13,"PAIN MANAGEMENT *") | BV13: =COUNTIF($D13:$BC13,"RHEUMA")+COUNTIF($D13:$BC13,"RHEUMA *") | BW13: =COUNTIF($D13:$BC13,"ENDO")+COUNTIF($D13:$BC13,"ENDO *") | BX13: =COUNTIF($D13:$BC13,"PLASTIC")+COUNTIF($D13:$BC13,"PLASTIC *") | BY13: =COUNTIF($D13:$BC13,"PULM")+COUNTIF($D13:$BC13,"PULM *") | BZ13: =COUNTIF($D13:$BC13,"SICU")+COUNTIF($D13:$BC13,"SICU *") | CA13: =COUNTIF($D13:$BC13,"DERMATOLOGY")+COUNTIF($D13:$BC13,"DERMATOLOGY *") | CB13: =COUNTIF($D13:$BC13,"NEPHRO")+COUNTIF($D13:$BC13,"NEPHRO *") | CC13: =SUM(BQ13:CB13) | CD13: =BP13+CC13
C14: M. Delgadillo | D14: C | E14: CLINIC | F14: ICU | G14: ICU | H14: ID * | I14: HEM/ONC | J14: CLINIC | K14: D | L14: D | M14: D | N14: D | O14: CLINIC * | P14: NF | Q14: NF | R14: CLINIC * | S14: HEM/ONC | T14: CLINIC | U14: NF | V14: NF | W14: VACATION | X14: VACATION | Y14: CLINIC | Z14: D | AA14: D | AB14: D | AC14: D | AD14: ICU H* | AE14: ID | AF14: CLINIC | AG14: A | AH14: A | AI14: ED | AJ14: ED | AK14: CLINIC | AL14: ICU N | AM14: ICU N | AN14: CARDIO* | AO14: CARDIO | AP14: CLINIC | AQ14: A | AR14: A | AS14: VACATION | AT14: VACATION | AU14: ICU N | AV14: ICU | AW14: ICU | AX14: CLINIC | AY14: HEM/ONC | AZ14: B | BA14: B | BB14: B | BC14: B | BD14: =COUNTIF($D14:$BC14,"CARDIO")+COUNTIF($D14:$BC14,"CARDIO E")+COUNTIF($D14:$BC14,"CARDIO E *")+COUNTIF($D14:$BC14,"CARDIO-HCA")+COUNTIF($D14:$BC14,"CARDIO-HCA *")+COUNTIF($D14:$BC14,"CARDIO-RAM")+COUNTIF($D14:$BC14,"CARDIO-RAM *") | BE14: =COUNTIF($D14:$BC14,"CLINIC")+COUNTIF($D14:$BC14,"CLINIC *")+COUNTIF($D14:$BC14,"URGENT CARE")+COUNTIF($D14:$BC14,"URGENT CARE *") | BF14: =COUNTIF($D14:$BC14,"ED") | BG14: =COUNTIF($D14:$BC14,"A")+COUNTIF($D14:$BC14,"B")+COUNTIF($D14:$BC14,"C")+COUNTIF($D14:$BC14,"D")+COUNTIF($D14:$BC14,"G") | BH14: =COUNTIF($D14:$BC14,"ICU") | BI14: =COUNTIF($D14:$BC14,"ICU E") | BJ14: =COUNTIF($D14:$BC14,"ICU N") | BK14: =COUNTIF($D14:$BC14,"ID")+COUNTIF($D14:$BC14,"ID *") | BL14: =COUNTIF($D14:$BC14,"NEURO")+COUNTIF($D14:$BC14,"NEURO *") | BM14: =COUNTIF($D14:$BC14,"NF") | BN14: =COUNTIF($D14:$BC14,"SWING") | BO14: =COUNTIF($D14:$BC14,"VACATION") | BP14: =SUM(BD14:BO14) | BQ14: =COUNTIF($D14:$BC14,"PALLIATIVE")+COUNTIF($D14:$BC14,"PALLIATIVE *") | BR14: =COUNTIF($D14:$BC14,"GERIATRIC")+COUNTIF($D14:$BC14,"GERIATRIC 2") | BS14: =COUNTIF($D14:$BC14,"GS")+COUNTIF($D14:$BC14,"GI")+COUNTIF($D14:$BC14,"GI *") | BT14: =COUNTIF($D14:$BC14,"HEM/ONC")+COUNTIF($D14:$BC14,"HEM/ONC *") | BU14: =COUNTIF($D14:$BC14,"PAIN MANAGEMENT")+COUNTIF($D14:$BC14,"PAIN MANAGEMENT *") | BV14: =COUNTIF($D14:$BC14,"RHEUMA")+COUNTIF($D14:$BC14,"RHEUMA *") | BW14: =COUNTIF($D14:$BC14,"ENDO")+COUNTIF($D14:$BC14,"ENDO *") | BX14: =COUNTIF($D14:$BC14,"PLASTIC")+COUNTIF($D14:$BC14,"PLASTIC *") | BY14: =COUNTIF($D14:$BC14,"PULM")+COUNTIF($D14:$BC14,"PULM *") | BZ14: =COUNTIF($D14:$BC14,"SICU")+COUNTIF($D14:$BC14,"SICU *") | CA14: =COUNTIF($D14:$BC14,"DERMATOLOGY")+COUNTIF($D14:$BC14,"DERMATOLOGY *") | CB14: =COUNTIF($D14:$BC14,"NEPHRO")+COUNTIF($D14:$BC14,"NEPHRO *") | CC14: =SUM(BQ14:CB14) | CD14: =BP14+CC14
C15: K. Gonzalez | D15: C | E15: CLINIC | F15: ICU | G15: ICU | H15: ID | I15: CARDIO* | J15: CLINIC | K15: D | L15: D | M15: D | N15: D | O15: CLINIC | P15: VACATION | Q15: VACATION | R15: ICU | S15: ICU | T15: CLINIC * | U15: A | V15: A | W15: A | X15: A | Y15: CLINIC | Z15: D | AA15: D | AB15: D | AC15: D | AD15: ICU H | AE15: CARDIO | AF15: CLINIC | AG15: D | AH15: D | AI15: CARDIO | AJ15: CARDIO | AK15: CLINIC | AL15: ED | AM15: ED | AN15: ICU N | AO15: ICU N | AP15: CLINIC | AQ15: A | AR15: A | AS15: CLINIC | AT15: ICU N | AU15: CLINIC | AV15: VACATION | AW15: VACATION | AX15: ID | AY15: ICU N | AZ15: B | BA15: B | BB15: B | BC15: B | BD15: =COUNTIF($D15:$BC15,"CARDIO")+COUNTIF($D15:$BC15,"CARDIO E")+COUNTIF($D15:$BC15,"CARDIO E *")+COUNTIF($D15:$BC15,"CARDIO-HCA")+COUNTIF($D15:$BC15,"CARDIO-HCA *")+COUNTIF($D15:$BC15,"CARDIO-RAM")+COUNTIF($D15:$BC15,"CARDIO-RAM *") | BE15: =COUNTIF($D15:$BC15,"CLINIC")+COUNTIF($D15:$BC15,"CLINIC *")+COUNTIF($D15:$BC15,"URGENT CARE")+COUNTIF($D15:$BC15,"URGENT CARE *") | BF15: =COUNTIF($D15:$BC15,"ED") | BG15: =COUNTIF($D15:$BC15,"A")+COUNTIF($D15:$BC15,"B")+COUNTIF($D15:$BC15,"C")+COUNTIF($D15:$BC15,"D")+COUNTIF($D15:$BC15,"G") | BH15: =COUNTIF($D15:$BC15,"ICU") | BI15: =COUNTIF($D15:$BC15,"ICU E") | BJ15: =COUNTIF($D15:$BC15,"ICU N") | BK15: =COUNTIF($D15:$BC15,"ID")+COUNTIF($D15:$BC15,"ID *") | BL15: =COUNTIF($D15:$BC15,"NEURO")+COUNTIF($D15:$BC15,"NEURO *") | BM15: =COUNTIF($D15:$BC15,"NF") | BN15: =COUNTIF($D15:$BC15,"SWING") | BO15: =COUNTIF($D15:$BC15,"VACATION") | BP15: =SUM(BD15:BO15) | BQ15: =COUNTIF($D15:$BC15,"PALLIATIVE")+COUNTIF($D15:$BC15,"PALLIATIVE *") | BR15: =COUNTIF($D15:$BC15,"GERIATRIC")+COUNTIF($D15:$BC15,"GERIATRIC 2") | BS15: =COUNTIF($D15:$BC15,"GS")+COUNTIF($D15:$BC15,"GI")+COUNTIF($D15:$BC15,"GI *") | BT15: =COUNTIF($D15:$BC15,"HEM/ONC")+COUNTIF($D15:$BC15,"HEM/ONC *") | BU15: =COUNTIF($D15:$BC15,"PAIN MANAGEMENT")+COUNTIF($D15:$BC15,"PAIN MANAGEMENT *") | BV15: =COUNTIF($D15:$BC15,"RHEUMA")+COUNTIF($D15:$BC15,"RHEUMA *") | BW15: =COUNTIF($D15:$BC15,"ENDO")+COUNTIF($D15:$BC15,"ENDO *") | BX15: =COUNTIF($D15:$BC15,"PLASTIC")+COUNTIF($D15:$BC15,"PLASTIC *") | BY15: =COUNTIF($D15:$BC15,"PULM")+COUNTIF($D15:$BC15,"PULM *") | BZ15: =COUNTIF($D15:$BC15,"SICU")+COUNTIF($D15:$BC15,"SICU *") | CA15: =COUNTIF($D15:$BC15,"DERMATOLOGY")+COUNTIF($D15:$BC15,"DERMATOLOGY *") | CB15: =COUNTIF($D15:$BC15,"NEPHRO")+COUNTIF($D15:$BC15,"NEPHRO *") | CC15: =SUM(BQ15:CB15) | CD15: =BP15+CC15
B16: PGY-3 | C16: C. Ayala | D16: CLINIC | E16: CLINIC | F16: HEM/ONC | G16: CLINIC | H16: NEURO | I16: NEURO | J16: CLINIC | K16: CARDIO | L16: B | M16: B | N16: CLINIC | O16: CLINIC | P16: VACATION | Q16: VACATION | R16: A | S16: B | T16: CLINIC | U16: D | V16: NF | W16: NF | X16: CLINIC | Y16: CLINIC | Z16: NEURO | AA16: B | AB16: ICU | AC16: ICU | AD16: ICU H* | AE16: CLINIC | AF16: CLINIC | AG16: NEPHRO | AH16: CARDIO* | AI16: B | AJ16: B | AK16: CLINIC | AL16: SWING | AM16: ICU | AN16: ICU | AO16: SWING | AP16: CLINIC | AQ16: ICU | AR16: ICU | AS16: VACATION | AT16: VACATION | AU16: CLINIC | AV16: B | AW16: B | AX16: NF | AY16: NF | AZ16: CLINIC | BA16: CLINIC * | BB16: ICU N | BC16: ICU N | BD16: =COUNTIF($D16:$BC16,"CARDIO")+COUNTIF($D16:$BC16,"CARDIO E")+COUNTIF($D16:$BC16,"CARDIO E *")+COUNTIF($D16:$BC16,"CARDIO-HCA")+COUNTIF($D16:$BC16,"CARDIO-HCA *")+COUNTIF($D16:$BC16,"CARDIO-RAM")+COUNTIF($D16:$BC16,"CARDIO-RAM *") | BE16: =COUNTIF($D16:$BC16,"CLINIC")+COUNTIF($D16:$BC16,"CLINIC *")+COUNTIF($D16:$BC16,"URGENT CARE")+COUNTIF($D16:$BC16,"URGENT CARE *") | BF16: =COUNTIF($D16:$BC16,"ED") | BG16: =COUNTIF($D16:$BC16,"A")+COUNTIF($D16:$BC16,"B")+COUNTIF($D16:$BC16,"C")+COUNTIF($D16:$BC16,"D")+COUNTIF($D16:$BC16,"G") | BH16: =COUNTIF($D16:$BC16,"ICU") | BI16: =COUNTIF($D16:$BC16,"ICU E") | BJ16: =COUNTIF($D16:$BC16,"ICU N") | BK16: =COUNTIF($D16:$BC16,"ID")+COUNTIF($D16:$BC16,"ID *") | BL16: =COUNTIF($D16:$BC16,"NEURO")+COUNTIF($D16:$BC16,"NEURO *") | BM16: =COUNTIF($D16:$BC16,"NF") | BN16: =COUNTIF($D16:$BC16,"SWING") | BO16: =COUNTIF($D16:$BC16,"VACATION") | BP16: =SUM(BD16:BO16) | BQ16: =COUNTIF($D16:$BC16,"PALLIATIVE")+COUNTIF($D16:$BC16,"PALLIATIVE *") | BR16: =COUNTIF($D16:$BC16,"GERIATRIC")+COUNTIF($D16:$BC16,"GERIATRIC 2") | BS16: =COUNTIF($D16:$BC16,"GS")+COUNTIF($D16:$BC16,"GI")+COUNTIF($D16:$BC16,"GI *") | BT16: =COUNTIF($D16:$BC16,"HEM/ONC")+COUNTIF($D16:$BC16,"HEM/ONC *") | BU16: =COUNTIF($D16:$BC16,"PAIN MANAGEMENT")+COUNTIF($D16:$BC16,"PAIN MANAGEMENT *") | BV16: =COUNTIF($D16:$BC16,"RHEUMA")+COUNTIF($D16:$BC16,"RHEUMA *") | BW16: =COUNTIF($D16:$BC16,"ENDO")+COUNTIF($D16:$BC16,"ENDO *") | BX16: =COUNTIF($D16:$BC16,"PLASTIC")+COUNTIF($D16:$BC16,"PLASTIC *") | BY16: =COUNTIF($D16:$BC16,"PULM")+COUNTIF($D16:$BC16,"PULM *") | BZ16: =COUNTIF($D16:$BC16,"SICU")+COUNTIF($D16:$BC16,"SICU *") | CA16: =COUNTIF($D16:$BC16,"DERMATOLOGY")+COUNTIF($D16:$BC16,"DERMATOLOGY *") | CB16: =COUNTIF($D16:$BC16,"NEPHRO")+COUNTIF($D16:$BC16,"NEPHRO *") | CC16: =SUM(BQ16:CB16) | CD16: =BP16+CC16
C17: K. Vallejo | D17: CLINIC | E17: CLINIC | F17: NEURO | G17: NEURO | H17: CLINIC | I17: B | J17: CLINIC | K17: ED | L17: ED | M17: ICU | N17: NEURO | O17: CLINIC | P17: VACATION | Q17: VACATION | R17: D | S17: D | T17: CLINIC | U17: GI * | V17: GI | W17: CLINIC | X17: GI | Y17: CLINIC | Z17: SWING | AA17: A | AB17: CLINIC | AC17: ICU H | AD17: NF | AE17: NF | AF17: CLINIC | AG17: NEURO | AH17: A | AI17: A | AJ17: A | AK17: CLINIC | AL17: C | AM17: C | AN17: ICU | AO17: ICU | AP17: CLINIC | AQ17: ICU N | AR17: ICU N | AS17: GI | AT17: GI | AU17: CLINIC | AV17: VACATION | AW17: VACATION | AX17: A | AY17: NF | AZ17: CLINIC | BA17: SWING | BB17: ICU | BC17: A | BD17: =COUNTIF($D17:$BC17,"CARDIO")+COUNTIF($D17:$BC17,"CARDIO E")+COUNTIF($D17:$BC17,"CARDIO E *")+COUNTIF($D17:$BC17,"CARDIO-HCA")+COUNTIF($D17:$BC17,"CARDIO-HCA *")+COUNTIF($D17:$BC17,"CARDIO-RAM")+COUNTIF($D17:$BC17,"CARDIO-RAM *") | BE17: =COUNTIF($D17:$BC17,"CLINIC")+COUNTIF($D17:$BC17,"CLINIC *")+COUNTIF($D17:$BC17,"URGENT CARE")+COUNTIF($D17:$BC17,"URGENT CARE *") | BF17: =COUNTIF($D17:$BC17,"ED") | BG17: =COUNTIF($D17:$BC17,"A")+COUNTIF($D17:$BC17,"B")+COUNTIF($D17:$BC17,"C")+COUNTIF($D17:$BC17,"D")+COUNTIF($D17:$BC17,"G") | BH17: =COUNTIF($D17:$BC17,"ICU") | BI17: =COUNTIF($D17:$BC17,"ICU E") | BJ17: =COUNTIF($D17:$BC17,"ICU N") | BK17: =COUNTIF($D17:$BC17,"ID")+COUNTIF($D17:$BC17,"ID *") | BL17: =COUNTIF($D17:$BC17,"NEURO")+COUNTIF($D17:$BC17,"NEURO *") | BM17: =COUNTIF($D17:$BC17,"NF") | BN17: =COUNTIF($D17:$BC17,"SWING") | BO17: =COUNTIF($D17:$BC17,"VACATION") | BP17: =SUM(BD17:BO17) | BQ17: =COUNTIF($D17:$BC17,"PALLIATIVE")+COUNTIF($D17:$BC17,"PALLIATIVE *") | BR17: =COUNTIF($D17:$BC17,"GERIATRIC")+COUNTIF($D17:$BC17,"GERIATRIC 2") | BS17: =COUNTIF($D17:$BC17,"GS")+COUNTIF($D17:$BC17,"GI")+COUNTIF($D17:$BC17,"GI *") | BT17: =COUNTIF($D17:$BC17,"HEM/ONC")+COUNTIF($D17:$BC17,"HEM/ONC *") | BU17: =COUNTIF($D17:$BC17,"PAIN MANAGEMENT")+COUNTIF($D17:$BC17,"PAIN MANAGEMENT *") | BV17: =COUNTIF($D17:$BC17,"RHEUMA")+COUNTIF($D17:$BC17,"RHEUMA *") | BW17: =COUNTIF($D17:$BC17,"ENDO")+COUNTIF($D17:$BC17,"ENDO *") | BX17: =COUNTIF($D17:$BC17,"PLASTIC")+COUNTIF($D17:$BC17,"PLASTIC *") | BY17: =COUNTIF($D17:$BC17,"PULM")+COUNTIF($D17:$BC17,"PULM *") | BZ17: =COUNTIF($D17:$BC17,"SICU")+COUNTIF($D17:$BC17,"SICU *") | CA17: =COUNTIF($D17:$BC17,"DERMATOLOGY")+COUNTIF($D17:$BC17,"DERMATOLOGY *") | CB17: =COUNTIF($D17:$BC17,"NEPHRO")+COUNTIF($D17:$BC17,"NEPHRO *") | CC17: =SUM(BQ17:CB17) | CD17: =BP17+CC17
B18: PGY-3 | C18: A. Silva | D18: D | E18: CLINIC | F18: ICU N | G18: ICU N | H18: CLINIC | I18: C | J18: CLINIC | K18: C | L18: C | M18: GI | N18: NF | O18: CLINIC | P18: G | Q18: VACATION | R18: VACATION | S18: GI | T18: CLINIC | U18: CLINIC | V18: ICU | W18: ICU | X18: CLINIC | Y18: CLINIC | Z18: CARDIO | AA18: CARDIO | AB18: C | AC18: CLINIC | AD18: ICU H | AE18: G | AF18: ICU | AG18: CLINIC | AH18: ICU | AI18: CLINIC | AJ18: CARDIO | AK18: CLINIC | AL18: HEM/ONC | AM18: HEM/ONC | AN18: RHEUMA | AO18: ID | AP18: CLINIC | AQ18: PALLIATIVE | AR18: PALLIATIVE | AS18: VACATION | AT18: VACATION | AU18: CLINIC | AV18: PULM | AW18: PULM | AX18: G | AY18: CLINIC | AZ18: CLINIC | BA18: ID | BB18: PAIN MANAGEMENT | BC18: GERIATRIC | BD18: =COUNTIF($D18:$BC18,"CARDIO")+COUNTIF($D18:$BC18,"CARDIO E")+COUNTIF($D18:$BC18,"CARDIO E *")+COUNTIF($D18:$BC18,"CARDIO-HCA")+COUNTIF($D18:$BC18,"CARDIO-HCA *")+COUNTIF($D18:$BC18,"CARDIO-RAM")+COUNTIF($D18:$BC18,"CARDIO-RAM *") | BE18: =COUNTIF($D18:$BC18,"CLINIC")+COUNTIF($D18:$BC18,"CLINIC *")+COUNTIF($D18:$BC18,"URGENT CARE")+COUNTIF($D18:$BC18,"URGENT CARE *") | BF18: =COUNTIF($D18:$BC18,"ED") | BG18: =COUNTIF($D18:$BC18,"A")+COUNTIF($D18:$BC18,"B")+COUNTIF($D18:$BC18,"C")+COUNTIF($D18:$BC18,"D")+COUNTIF($D18:$BC18,"G") | BH18: =COUNTIF($D18:$BC18,"ICU") | BI18: =COUNTIF($D18:$BC18,"ICU E") | BJ18: =COUNTIF($D18:$BC18,"ICU N") | BK18: =COUNTIF($D18:$BC18,"ID")+COUNTIF($D18:$BC18,"ID *") | BL18: =COUNTIF($D18:$BC18,"NEURO")+COUNTIF($D18:$BC18,"NEURO *") | BM18: =COUNTIF($D18:$BC18,"NF") | BN18: =COUNTIF($D18:$BC18,"SWING") | BO18: =COUNTIF($D18:$BC18,"VACATION") | BP18: =SUM(BD18:BO18) | BQ18: =COUNTIF($D18:$BC18,"PALLIATIVE")+COUNTIF($D18:$BC18,"PALLIATIVE *") | BR18: =COUNTIF($D18:$BC18,"GERIATRIC")+COUNTIF($D18:$BC18,"GERIATRIC 2") | BS18: =COUNTIF($D18:$BC18,"GS")+COUNTIF($D18:$BC18,"GI")+COUNTIF($D18:$BC18,"GI *") | BT18: =COUNTIF($D18:$BC18,"HEM/ONC")+COUNTIF($D18:$BC18,"HEM/ONC *") | BU18: =COUNTIF($D18:$BC18,"PAIN MANAGEMENT")+COUNTIF($D18:$BC18,"PAIN MANAGEMENT *") | BV18: =COUNTIF($D18:$BC18,"RHEUMA")+COUNTIF($D18:$BC18,"RHEUMA *") | BW18: =COUNTIF($D18:$BC18,"ENDO")+COUNTIF($D18:$BC18,"ENDO *") | BX18: =COUNTIF($D18:$BC18,"PLASTIC")+COUNTIF($D18:$BC18,"PLASTIC *") | BY18: =COUNTIF($D18:$BC18,"PULM")+COUNTIF($D18:$BC18,"PULM *") | BZ18: =COUNTIF($D18:$BC18,"SICU")+COUNTIF($D18:$BC18,"SICU *") | CA18: =COUNTIF($D18:$BC18,"DERMATOLOGY")+COUNTIF($D18:$BC18,"DERMATOLOGY *") | CB18: =COUNTIF($D18:$BC18,"NEPHRO")+COUNTIF($D18:$BC18,"NEPHRO *") | CC18: =SUM(BQ18:CB18) | CD18: =BP18+CC18
C19: F. Monefeldt | D19: C | E19: CLINIC | F19: NF | G19: NEURO | H19: NEURO | I19: A | J19: CLINIC | K19: A | L19: A | M19: HEM/ONC | N19: D | O19: CLINIC | P19: CLINIC | Q19: SWING | R19: VACATION | S19: VACATION | T19: NF | U19: CLINIC | V19: ICU | W19: ICU | X19: CLINIC | Y19: CLINIC | Z19: CARDIO | AA19: CARDIO | AB19: SWING | AC19: CLINIC | AD19: ICU H | AE19: CLINIC | AF19: CLINIC | AG19: ENDO | AH19: ENDO | AI19: NEPHRO * | AJ19: NEPHRO | AK19: CLINIC | AL19: GERIATRIC 2 | AM19: GERIATRIC 2 | AN19: VACATION | AO19: VACATION | AP19: CLINIC | AQ19: HEM/ONC | AR19: ID | AS19: ID | AT19: CLINIC | AU19: CLINIC | AV19: PULM | AW19: PULM | AX19: ENDO | AY19: ENDO | AZ19: CLINIC | BA19: PALLIATIVE | BB19: PALLIATIVE | BC19: GI | BD19: =COUNTIF($D19:$BC19,"CARDIO")+COUNTIF($D19:$BC19,"CARDIO E")+COUNTIF($D19:$BC19,"CARDIO E *")+COUNTIF($D19:$BC19,"CARDIO-HCA")+COUNTIF($D19:$BC19,"CARDIO-HCA *")+COUNTIF($D19:$BC19,"CARDIO-RAM")+COUNTIF($D19:$BC19,"CARDIO-RAM *") | BE19: =COUNTIF($D19:$BC19,"CLINIC")+COUNTIF($D19:$BC19,"CLINIC *")+COUNTIF($D19:$BC19,"URGENT CARE")+COUNTIF($D19:$BC19,"URGENT CARE *") | BF19: =COUNTIF($D19:$BC19,"ED") | BG19: =COUNTIF($D19:$BC19,"A")+COUNTIF($D19:$BC19,"B")+COUNTIF($D19:$BC19,"C")+COUNTIF($D19:$BC19,"D")+COUNTIF($D19:$BC19,"G") | BH19: =COUNTIF($D19:$BC19,"ICU") | BI19: =COUNTIF($D19:$BC19,"ICU E") | BJ19: =COUNTIF($D19:$BC19,"ICU N") | BK19: =COUNTIF($D19:$BC19,"ID")+COUNTIF($D19:$BC19,"ID *") | BL19: =COUNTIF($D19:$BC19,"NEURO")+COUNTIF($D19:$BC19,"NEURO *") | BM19: =COUNTIF($D19:$BC19,"NF") | BN19: =COUNTIF($D19:$BC19,"SWING") | BO19: =COUNTIF($D19:$BC19,"VACATION") | BP19: =SUM(BD19:BO19) | BQ19: =COUNTIF($D19:$BC19,"PALLIATIVE")+COUNTIF($D19:$BC19,"PALLIATIVE *") | BR19: =COUNTIF($D19:$BC19,"GERIATRIC")+COUNTIF($D19:$BC19,"GERIATRIC 2") | BS19: =COUNTIF($D19:$BC19,"GS")+COUNTIF($D19:$BC19,"GI")+COUNTIF($D19:$BC19,"GI *") | BT19: =COUNTIF($D19:$BC19,"HEM/ONC")+COUNTIF($D19:$BC19,"HEM/ONC *") | BU19: =COUNTIF($D19:$BC19,"PAIN MANAGEMENT")+COUNTIF($D19:$BC19,"PAIN MANAGEMENT *") | BV19: =COUNTIF($D19:$BC19,"RHEUMA")+COUNTIF($D19:$BC19,"RHEUMA *") | BW19: =COUNTIF($D19:$BC19,"ENDO")+COUNTIF($D19:$BC19,"ENDO *") | BX19: =COUNTIF($D19:$BC19,"PLASTIC")+COUNTIF($D19:$BC19,"PLASTIC *") | BY19: =COUNTIF($D19:$BC19,"PULM")+COUNTIF($D19:$BC19,"PULM *") | BZ19: =COUNTIF($D19:$BC19,"SICU")+COUNTIF($D19:$BC19,"SICU *") | CA19: =COUNTIF($D19:$BC19,"DERMATOLOGY")+COUNTIF($D19:$BC19,"DERMATOLOGY *") | CB19: =COUNTIF($D19:$BC19,"NEPHRO")+COUNTIF($D19:$BC19,"NEPHRO *") | CC19: =SUM(BQ19:CB19) | CD19: =BP19+CC19
A20: Cohort 3 | B20: PGY-2 | C20: M. Cruz | D20: B | E20: B | F20: CLINIC | G20: D | H20: D | I20: D | J20: D | K20: CLINIC | L20: ID | M20: CARDIO | N20: ICU | O20: ICU | P20: CLINIC | Q20: A | R20: A | S20: A | T20: A | U20: CLINIC * | V20: D | W20: D | X20: VACATION | Y20: VACATION | Z20: CLINIC | AA20: ICU | AB20: ICU | AC20: ICU H* | AD20: B | AE20: CARDIO | AF20: B | AG20: CLINIC | AH20: ICU | AI20: ICU | AJ20: CARDIO | AK20: NF | AL20: CLINIC | AM20: A | AN20: A | AO20: VACATION | AP20: VACATION | AQ20: CLINIC | AR20: B | AS20: B | AT20: ID * | AU20: B | AV20: CLINIC * | AW20: A | AX20: A | AY20: CARDIO | AZ20: ICU N | BA20: ICU N | BB20: CARDIO | BC20: CLINIC * | BD20: =COUNTIF($D20:$BC20,"CARDIO")+COUNTIF($D20:$BC20,"CARDIO E")+COUNTIF($D20:$BC20,"CARDIO E *")+COUNTIF($D20:$BC20,"CARDIO-HCA")+COUNTIF($D20:$BC20,"CARDIO-HCA *")+COUNTIF($D20:$BC20,"CARDIO-RAM")+COUNTIF($D20:$BC20,"CARDIO-RAM *") | BE20: =COUNTIF($D20:$BC20,"CLINIC")+COUNTIF($D20:$BC20,"CLINIC *")+COUNTIF($D20:$BC20,"URGENT CARE")+COUNTIF($D20:$BC20,"URGENT CARE *") | BF20: =COUNTIF($D20:$BC20,"ED") | BG20: =COUNTIF($D20:$BC20,"A")+COUNTIF($D20:$BC20,"B")+COUNTIF($D20:$BC20,"C")+COUNTIF($D20:$BC20,"D")+COUNTIF($D20:$BC20,"G") | BH20: =COUNTIF($D20:$BC20,"ICU") | BI20: =COUNTIF($D20:$BC20,"ICU E") | BJ20: =COUNTIF($D20:$BC20,"ICU N") | BK20: =COUNTIF($D20:$BC20,"ID")+COUNTIF($D20:$BC20,"ID *") | BL20: =COUNTIF($D20:$BC20,"NEURO")+COUNTIF($D20:$BC20,"NEURO *") | BM20: =COUNTIF($D20:$BC20,"NF") | BN20: =COUNTIF($D20:$BC20,"SWING") | BO20: =COUNTIF($D20:$BC20,"VACATION") | BP20: =SUM(BD20:BO20) | BQ20: =COUNTIF($D20:$BC20,"PALLIATIVE")+COUNTIF($D20:$BC20,"PALLIATIVE *") | BR20: =COUNTIF($D20:$BC20,"GERIATRIC")+COUNTIF($D20:$BC20,"GERIATRIC 2") | BS20: =COUNTIF($D20:$BC20,"GS")+COUNTIF($D20:$BC20,"GI")+COUNTIF($D20:$BC20,"GI *") | BT20: =COUNTIF($D20:$BC20,"HEM/ONC")+COUNTIF($D20:$BC20,"HEM/ONC *") | BU20: =COUNTIF($D20:$BC20,"PAIN MANAGEMENT")+COUNTIF($D20:$BC20,"PAIN MANAGEMENT *") | BV20: =COUNTIF($D20:$BC20,"RHEUMA")+COUNTIF($D20:$BC20,"RHEUMA *") | BW20: =COUNTIF($D20:$BC20,"ENDO")+COUNTIF($D20:$BC20,"ENDO *") | BX20: =COUNTIF($D20:$BC20,"PLASTIC")+COUNTIF($D20:$BC20,"PLASTIC *") | BY20: =COUNTIF($D20:$BC20,"PULM")+COUNTIF($D20:$BC20,"PULM *") | BZ20: =COUNTIF($D20:$BC20,"SICU")+COUNTIF($D20:$BC20,"SICU *") | CA20: =COUNTIF($D20:$BC20,"DERMATOLOGY")+COUNTIF($D20:$BC20,"DERMATOLOGY *") | CB20: =COUNTIF($D20:$BC20,"NEPHRO")+COUNTIF($D20:$BC20,"NEPHRO *") | CC20: =SUM(BQ20:CB20) | CD20: =BP20+CC20
C21: I. Estrada | D21: B | E21: B | F21: CLINIC | G21: D | H21: D | I21: D | J21: D | K21: CLINIC | L21: ID * | M21: ID | N21: ICU | O21: ICU | P21: CLINIC | Q21: HEM/ONC * | R21: A | S21: A | T21: A | U21: CLINIC | V21: D | W21: D | X21: VACATION | Y21: VACATION | Z21: CLINIC | AA21: ED | AB21: ED | AC21: ICU H* | AD21: B | AE21: B | AF21: B | AG21: CLINIC | AH21: ICU | AI21: ICU | AJ21: HEM/ONC * | AK21: ICU N | AL21: CLINIC | AM21: A | AN21: A | AO21: A | AP21: A | AQ21: CLINIC | AR21: ICU | AS21: ICU | AT21: CLINIC | AU21: NF | AV21: CLINIC | AW21: VACATION | AX21: VACATION | AY21: ICU | AZ21: A | BA21: A | BB21: A | BC21: CLINIC | BD21: =COUNTIF($D21:$BC21,"CARDIO")+COUNTIF($D21:$BC21,"CARDIO E")+COUNTIF($D21:$BC21,"CARDIO E *")+COUNTIF($D21:$BC21,"CARDIO-HCA")+COUNTIF($D21:$BC21,"CARDIO-HCA *")+COUNTIF($D21:$BC21,"CARDIO-RAM")+COUNTIF($D21:$BC21,"CARDIO-RAM *") | BE21: =COUNTIF($D21:$BC21,"CLINIC")+COUNTIF($D21:$BC21,"CLINIC *")+COUNTIF($D21:$BC21,"URGENT CARE")+COUNTIF($D21:$BC21,"URGENT CARE *") | BF21: =COUNTIF($D21:$BC21,"ED") | BG21: =COUNTIF($D21:$BC21,"A")+COUNTIF($D21:$BC21,"B")+COUNTIF($D21:$BC21,"C")+COUNTIF($D21:$BC21,"D")+COUNTIF($D21:$BC21,"G") | BH21: =COUNTIF($D21:$BC21,"ICU") | BI21: =COUNTIF($D21:$BC21,"ICU E") | BJ21: =COUNTIF($D21:$BC21,"ICU N") | BK21: =COUNTIF($D21:$BC21,"ID")+COUNTIF($D21:$BC21,"ID *") | BL21: =COUNTIF($D21:$BC21,"NEURO")+COUNTIF($D21:$BC21,"NEURO *") | BM21: =COUNTIF($D21:$BC21,"NF") | BN21: =COUNTIF($D21:$BC21,"SWING") | BO21: =COUNTIF($D21:$BC21,"VACATION") | BP21: =SUM(BD21:BO21) | BQ21: =COUNTIF($D21:$BC21,"PALLIATIVE")+COUNTIF($D21:$BC21,"PALLIATIVE *") | BR21: =COUNTIF($D21:$BC21,"GERIATRIC")+COUNTIF($D21:$BC21,"GERIATRIC 2") | BS21: =COUNTIF($D21:$BC21,"GS")+COUNTIF($D21:$BC21,"GI")+COUNTIF($D21:$BC21,"GI *") | BT21: =COUNTIF($D21:$BC21,"HEM/ONC")+COUNTIF($D21:$BC21,"HEM/ONC *") | BU21: =COUNTIF($D21:$BC21,"PAIN MANAGEMENT")+COUNTIF($D21:$BC21,"PAIN MANAGEMENT *") | BV21: =COUNTIF($D21:$BC21,"RHEUMA")+COUNTIF($D21:$BC21,"RHEUMA *") | BW21: =COUNTIF($D21:$BC21,"ENDO")+COUNTIF($D21:$BC21,"ENDO *") | BX21: =COUNTIF($D21:$BC21,"PLASTIC")+COUNTIF($D21:$BC21,"PLASTIC *") | BY21: =COUNTIF($D21:$BC21,"PULM")+COUNTIF($D21:$BC21,"PULM *") | BZ21: =COUNTIF($D21:$BC21,"SICU")+COUNTIF($D21:$BC21,"SICU *") | CA21: =COUNTIF($D21:$BC21,"DERMATOLOGY")+COUNTIF($D21:$BC21,"DERMATOLOGY *") | CB21: =COUNTIF($D21:$BC21,"NEPHRO")+COUNTIF($D21:$BC21,"NEPHRO *") | CC21: =SUM(BQ21:CB21) | CD21: =BP21+CC21
B22: PGY-3 | C22: J. Cabrera | D22: B | E22: B | F22: CLINIC | G22: GI * | H22: GI | I22: ICU N | J22: CLINIC | K22: CLINIC | L22: NEURO | M22: A | N22: A | O22: CLINIC | P22: CLINIC | Q22: NEURO | R22: CLINIC | S22: VACATION | T22: VACATION | U22: CLINIC | V22: HEM/ONC | W22: HEM/ONC | X22: GI | Y22: GI | Z22: CLINIC | AA22: NEURO | AB22: CARDIO | AC22: ICU H | AD22: C | AE22: NF | AF22: NF | AG22: CLINIC | AH22: ED | AI22: SWING | AJ22: CLINIC | AK22: ICU | AL22: CLINIC | AM22: D | AN22: D | AO22: ED | AP22: ICU N | AQ22: CLINIC | AR22: VACATION | AS22: VACATION | AT22: A | AU22: A | AV22: CLINIC | AW22: C | AX22: C | AY22: ICU | AZ22: ICU | BA22: CLINIC | BB22: SWING | BC22: B | BD22: =COUNTIF($D22:$BC22,"CARDIO")+COUNTIF($D22:$BC22,"CARDIO E")+COUNTIF($D22:$BC22,"CARDIO E *")+COUNTIF($D22:$BC22,"CARDIO-HCA")+COUNTIF($D22:$BC22,"CARDIO-HCA *")+COUNTIF($D22:$BC22,"CARDIO-RAM")+COUNTIF($D22:$BC22,"CARDIO-RAM *") | BE22: =COUNTIF($D22:$BC22,"CLINIC")+COUNTIF($D22:$BC22,"CLINIC *")+COUNTIF($D22:$BC22,"URGENT CARE")+COUNTIF($D22:$BC22,"URGENT CARE *") | BF22: =COUNTIF($D22:$BC22,"ED") | BG22: =COUNTIF($D22:$BC22,"A")+COUNTIF($D22:$BC22,"B")+COUNTIF($D22:$BC22,"C")+COUNTIF($D22:$BC22,"D")+COUNTIF($D22:$BC22,"G") | BH22: =COUNTIF($D22:$BC22,"ICU") | BI22: =COUNTIF($D22:$BC22,"ICU E") | BJ22: =COUNTIF($D22:$BC22,"ICU N") | BK22: =COUNTIF($D22:$BC22,"ID")+COUNTIF($D22:$BC22,"ID *") | BL22: =COUNTIF($D22:$BC22,"NEURO")+COUNTIF($D22:$BC22,"NEURO *") | BM22: =COUNTIF($D22:$BC22,"NF") | BN22: =COUNTIF($D22:$BC22,"SWING") | BO22: =COUNTIF($D22:$BC22,"VACATION") | BP22: =SUM(BD22:BO22) | BQ22: =COUNTIF($D22:$BC22,"PALLIATIVE")+COUNTIF($D22:$BC22,"PALLIATIVE *") | BR22: =COUNTIF($D22:$BC22,"GERIATRIC")+COUNTIF($D22:$BC22,"GERIATRIC 2") | BS22: =COUNTIF($D22:$BC22,"GS")+COUNTIF($D22:$BC22,"GI")+COUNTIF($D22:$BC22,"GI *") | BT22: =COUNTIF($D22:$BC22,"HEM/ONC")+COUNTIF($D22:$BC22,"HEM/ONC *") | BU22: =COUNTIF($D22:$BC22,"PAIN MANAGEMENT")+COUNTIF($D22:$BC22,"PAIN MANAGEMENT *") | BV22: =COUNTIF($D22:$BC22,"RHEUMA")+COUNTIF($D22:$BC22,"RHEUMA *") | BW22: =COUNTIF($D22:$BC22,"ENDO")+COUNTIF($D22:$BC22,"ENDO *") | BX22: =COUNTIF($D22:$BC22,"PLASTIC")+COUNTIF($D22:$BC22,"PLASTIC *") | BY22: =COUNTIF($D22:$BC22,"PULM")+COUNTIF($D22:$BC22,"PULM *") | BZ22: =COUNTIF($D22:$BC22,"SICU")+COUNTIF($D22:$BC22,"SICU *") | CA22: =COUNTIF($D22:$BC22,"DERMATOLOGY")+COUNTIF($D22:$BC22,"DERMATOLOGY *") | CB22: =COUNTIF($D22:$BC22,"NEPHRO")+COUNTIF($D22:$BC22,"NEPHRO *") | CC22: =SUM(BQ22:CB22) | CD22: =BP22+CC22
C23: J. Perez | D23: ID | E23: CLINIC | F23: CLINIC | G23: CARDIO | H23: CARDIO* | I23: VACATION | J23: VACATION | K23: CLINIC | L23: ED | M23: ED | N23: G | O23: SWING | P23: CLINIC | Q23: HEM/ONC | R23: G | S23: CLINIC | T23: NEURO | U23: CLINIC | V23: CLINIC | W23: A | X23: CLINIC | Y23: NEURO | Z23: A | AA23: NEURO | AB23: NEURO | AC23: NF | AD23: ICU H* | AE23: C | AF23: C | AG23: CLINIC | AH23: NEPHRO | AI23: ICU N | AJ23: ICU N | AK23: G | AL23: CLINIC | AM23: VACATION | AN23: VACATION | AO23: NF | AP23: NF | AQ23: CLINIC | AR23: A | AS23: A | AT23: B | AU23: B | AV23: CLINIC | AW23: ICU | AX23: ICU | AY23: HEM/ONC * | AZ23: ICU N | BA23: ICU N | BB23: CLINIC | BC23: C | BD23: =COUNTIF($D23:$BC23,"CARDIO")+COUNTIF($D23:$BC23,"CARDIO E")+COUNTIF($D23:$BC23,"CARDIO E *")+COUNTIF($D23:$BC23,"CARDIO-HCA")+COUNTIF($D23:$BC23,"CARDIO-HCA *")+COUNTIF($D23:$BC23,"CARDIO-RAM")+COUNTIF($D23:$BC23,"CARDIO-RAM *") | BE23: =COUNTIF($D23:$BC23,"CLINIC")+COUNTIF($D23:$BC23,"CLINIC *")+COUNTIF($D23:$BC23,"URGENT CARE")+COUNTIF($D23:$BC23,"URGENT CARE *") | BF23: =COUNTIF($D23:$BC23,"ED") | BG23: =COUNTIF($D23:$BC23,"A")+COUNTIF($D23:$BC23,"B")+COUNTIF($D23:$BC23,"C")+COUNTIF($D23:$BC23,"D")+COUNTIF($D23:$BC23,"G") | BH23: =COUNTIF($D23:$BC23,"ICU") | BI23: =COUNTIF($D23:$BC23,"ICU E") | BJ23: =COUNTIF($D23:$BC23,"ICU N") | BK23: =COUNTIF($D23:$BC23,"ID")+COUNTIF($D23:$BC23,"ID *") | BL23: =COUNTIF($D23:$BC23,"NEURO")+COUNTIF($D23:$BC23,"NEURO *") | BM23: =COUNTIF($D23:$BC23,"NF") | BN23: =COUNTIF($D23:$BC23,"SWING") | BO23: =COUNTIF($D23:$BC23,"VACATION") | BP23: =SUM(BD23:BO23) | BQ23: =COUNTIF($D23:$BC23,"PALLIATIVE")+COUNTIF($D23:$BC23,"PALLIATIVE *") | BR23: =COUNTIF($D23:$BC23,"GERIATRIC")+COUNTIF($D23:$BC23,"GERIATRIC 2") | BS23: =COUNTIF($D23:$BC23,"GS")+COUNTIF($D23:$BC23,"GI")+COUNTIF($D23:$BC23,"GI *") | BT23: =COUNTIF($D23:$BC23,"HEM/ONC")+COUNTIF($D23:$BC23,"HEM/ONC *") | BU23: =COUNTIF($D23:$BC23,"PAIN MANAGEMENT")+COUNTIF($D23:$BC23,"PAIN MANAGEMENT *") | BV23: =COUNTIF($D23:$BC23,"RHEUMA")+COUNTIF($D23:$BC23,"RHEUMA *") | BW23: =COUNTIF($D23:$BC23,"ENDO")+COUNTIF($D23:$BC23,"ENDO *") | BX23: =COUNTIF($D23:$BC23,"PLASTIC")+COUNTIF($D23:$BC23,"PLASTIC *") | BY23: =COUNTIF($D23:$BC23,"PULM")+COUNTIF($D23:$BC23,"PULM *") | BZ23: =COUNTIF($D23:$BC23,"SICU")+COUNTIF($D23:$BC23,"SICU *") | CA23: =COUNTIF($D23:$BC23,"DERMATOLOGY")+COUNTIF($D23:$BC23,"DERMATOLOGY *") | CB23: =COUNTIF($D23:$BC23,"NEPHRO")+COUNTIF($D23:$BC23,"NEPHRO *") | CC23: =SUM(BQ23:CB23) | CD23: =BP23+CC23
B24: PGY-3 | C24: C. Ndigamkong | D24: CLINIC | E24: PAIN MANAGEMENT | F24: CLINIC | G24: CLINIC | H24: NEPHRO | I24: GI | J24: GI | K24: CLINIC | L24: SWING | M24: GI | N24: NEPHRO * | O24: NEPHRO | P24: SWING | Q24: CLINIC | R24: CLINIC | S24: CLINIC | T24: CLINIC | U24: GI | V24: CLINIC | W24: VACATION | X24: VACATION | Y24: NF | Z24: HEM/ONC | AA24: CLINIC | AB24: NEPHRO | AC24: C | AD24: ICU H | AE24: RHEUMA | AF24: CLINIC | AG24: G | AH24: PALLIATIVE | AI24: NF | AJ24: CLINIC * | AK24: GI | AL24: CARDIO | AM24: NF | AN24: NF | AO24: CLINIC | AP24: DERMATOLOGY | AQ24: SWING | AR24: SWING | AS24: VACATION | AT24: VACATION | AU24: CLINIC | AV24: NF | AW24: NF | AX24: CLINIC | AY24: CLINIC | AZ24: ID | BA24: PAIN MANAGEMENT | BB24: RHEUMA | BC24: CLINIC | BD24: =COUNTIF($D24:$BC24,"CARDIO")+COUNTIF($D24:$BC24,"CARDIO E")+COUNTIF($D24:$BC24,"CARDIO E *")+COUNTIF($D24:$BC24,"CARDIO-HCA")+COUNTIF($D24:$BC24,"CARDIO-HCA *")+COUNTIF($D24:$BC24,"CARDIO-RAM")+COUNTIF($D24:$BC24,"CARDIO-RAM *") | BE24: =COUNTIF($D24:$BC24,"CLINIC")+COUNTIF($D24:$BC24,"CLINIC *")+COUNTIF($D24:$BC24,"URGENT CARE")+COUNTIF($D24:$BC24,"URGENT CARE *") | BF24: =COUNTIF($D24:$BC24,"ED") | BG24: =COUNTIF($D24:$BC24,"A")+COUNTIF($D24:$BC24,"B")+COUNTIF($D24:$BC24,"C")+COUNTIF($D24:$BC24,"D")+COUNTIF($D24:$BC24,"G") | BH24: =COUNTIF($D24:$BC24,"ICU") | BI24: =COUNTIF($D24:$BC24,"ICU E") | BJ24: =COUNTIF($D24:$BC24,"ICU N") | BK24: 0 | BL24: =COUNTIF($D24:$BC24,"NEURO")+COUNTIF($D24:$BC24,"NEURO *") | BM24: =COUNTIF($D24:$BC24,"NF") | BN24: =COUNTIF($D24:$BC24,"SWING") | BO24: =COUNTIF($D24:$BC24,"VACATION") | BP24: =SUM(BD24:BO24) | BQ24: =COUNTIF($D24:$BC24,"PALLIATIVE")+COUNTIF($D24:$BC24,"PALLIATIVE *") | BR24: =COUNTIF($D24:$BC24,"GERIATRIC")+COUNTIF($D24:$BC24,"GERIATRIC 2") | BS24: =COUNTIF($D24:$BC24,"GS")+COUNTIF($D24:$BC24,"GI")+COUNTIF($D24:$BC24,"GI *") | BT24: =COUNTIF($D24:$BC24,"HEM/ONC")+COUNTIF($D24:$BC24,"HEM/ONC *") | BU24: =COUNTIF($D24:$BC24,"PAIN MANAGEMENT")+COUNTIF($D24:$BC24,"PAIN MANAGEMENT *") | BV24: =COUNTIF($D24:$BC24,"RHEUMA")+COUNTIF($D24:$BC24,"RHEUMA *") | BW24: =COUNTIF($D24:$BC24,"ENDO")+COUNTIF($D24:$BC24,"ENDO *") | BX24: =COUNTIF($D24:$BC24,"PLASTIC")+COUNTIF($D24:$BC24,"PLASTIC *") | BY24: =COUNTIF($D24:$BC24,"PULM")+COUNTIF($D24:$BC24,"PULM *") | BZ24: =COUNTIF($D24:$BC24,"SICU")+COUNTIF($D24:$BC24,"SICU *") | CA24: =COUNTIF($D24:$BC24,"DERMATOLOGY")+COUNTIF($D24:$BC24,"DERMATOLOGY *") | CB24: =COUNTIF($D24:$BC24,"NEPHRO")+COUNTIF($D24:$BC24,"NEPHRO *") | CC24: =SUM(BQ24:CB24) | CD24: =BP24+CC24
C25: C. Fontela | D25: HEM/ONC | E25: ICU | F25: CLINIC | G25: G | H25: ICU | I25: ICU | J25: CLINIC | K25: CLINIC | L25: CLINIC | M25: SWING | N25: GI | O25: GI | P25: CLINIC | Q25: VACATION | R25: VACATION | S25: PALLIATIVE | T25: ID | U25: CLINIC | V25: SWING | W25: D | X25: SWING | Y25: RHEUMA | Z25: CLINIC | AA25: C | AB25: G | AC25: CLINIC | AD25: ICU H | AE25: B | AF25: RHEUMA | AG25: CLINIC | AH25: HEM/ONC | AI25: CARDIO | AJ25: GERIATRIC | AK25: GERIATRIC | AL25: CLINIC | AM25: CLINIC | AN25: CARDIO* | AO25: PAIN MANAGEMENT | AP25: PULM | AQ25: CLINIC | AR25: RHEUMA | AS25: G | AT25: HEM/ONC | AU25: ID | AV25: CLINIC | AW25: VACATION | AX25: VACATION | AY25: PAIN MANAGEMENT | AZ25: CLINIC | BA25: CLINIC | BB25: GI | BC25: GI | BD25: =COUNTIF($D25:$BC25,"CARDIO")+COUNTIF($D25:$BC25,"CARDIO E")+COUNTIF($D25:$BC25,"CARDIO E *")+COUNTIF($D25:$BC25,"CARDIO-HCA")+COUNTIF($D25:$BC25,"CARDIO-HCA *")+COUNTIF($D25:$BC25,"CARDIO-RAM")+COUNTIF($D25:$BC25,"CARDIO-RAM *") | BE25: =COUNTIF($D25:$BC25,"CLINIC")+COUNTIF($D25:$BC25,"CLINIC *")+COUNTIF($D25:$BC25,"URGENT CARE")+COUNTIF($D25:$BC25,"URGENT CARE *") | BF25: =COUNTIF($D25:$BC25,"ED") | BG25: =COUNTIF($D25:$BC25,"A")+COUNTIF($D25:$BC25,"B")+COUNTIF($D25:$BC25,"C")+COUNTIF($D25:$BC25,"D")+COUNTIF($D25:$BC25,"G") | BH25: =COUNTIF($D25:$BC25,"ICU") | BI25: =COUNTIF($D25:$BC25,"ICU E") | BJ25: =COUNTIF($D25:$BC25,"ICU N") | BK25: =COUNTIF($D25:$BC25,"ID")+COUNTIF($D25:$BC25,"ID *") | BL25: =COUNTIF($D25:$BC25,"NEURO")+COUNTIF($D25:$BC25,"NEURO *") | BM25: =COUNTIF($D25:$BC25,"NF") | BN25: =COUNTIF($D25:$BC25,"SWING") | BO25: =COUNTIF($D25:$BC25,"VACATION") | BP25: =SUM(BD25:BO25) | BQ25: =COUNTIF($D25:$BC25,"PALLIATIVE")+COUNTIF($D25:$BC25,"PALLIATIVE *") | BR25: =COUNTIF($D25:$BC25,"GERIATRIC")+COUNTIF($D25:$BC25,"GERIATRIC 2") | BS25: =COUNTIF($D25:$BC25,"GS")+COUNTIF($D25:$BC25,"GI")+COUNTIF($D25:$BC25,"GI *") | BT25: =COUNTIF($D25:$BC25,"HEM/ONC")+COUNTIF($D25:$BC25,"HEM/ONC *") | BU25: =COUNTIF($D25:$BC25,"PAIN MANAGEMENT")+COUNTIF($D25:$BC25,"PAIN MANAGEMENT *") | BV25: =COUNTIF($D25:$BC25,"RHEUMA")+COUNTIF($D25:$BC25,"RHEUMA *") | BW25: =COUNTIF($D25:$BC25,"ENDO")+COUNTIF($D25:$BC25,"ENDO *") | BX25: =COUNTIF($D25:$BC25,"PLASTIC")+COUNTIF($D25:$BC25,"PLASTIC *") | BY25: =COUNTIF($D25:$BC25,"PULM")+COUNTIF($D25:$BC25,"PULM *") | BZ25: =COUNTIF($D25:$BC25,"SICU")+COUNTIF($D25:$BC25,"SICU *") | CA25: =COUNTIF($D25:$BC25,"DERMATOLOGY")+COUNTIF($D25:$BC25,"DERMATOLOGY *") | CB25: =COUNTIF($D25:$BC25,"NEPHRO")+COUNTIF($D25:$BC25,"NEPHRO *") | CC25: =SUM(BQ25:CB25) | CD25: =BP25+CC25
C26: M. Rodriguez | D26: NF | E26: NF | F26: CLINIC | G26: NEURO | H26: C | I26: GERIATRIC | J26: GERIATRIC | K26: CLINIC | L26: D | M26: VACATION | N26: VACATION | O26: ICU N | P26: CLINIC | Q26: D | R26: NEURO | S26: GI * | T26: CLINIC | U26: CLINIC | V26: GERIATRIC | W26: GERIATRIC | X26: ICU | Y26: ICU | Z26: CLINIC | AA26: HEM/ONC | AB26: NEPHRO | AC26: ICU H | AD26: CLINIC | AE26: ICU | AF26: PULM | AG26: CLINIC | AH26: D | AI26: HEM/ONC | AJ26: NEPHRO | AK26: SWING | AL26: CLINIC | AM26: HEM/ONC | AN26: VACATION | AO26: VACATION | AP26: PAIN MANAGEMENT | AQ26: CLINIC | AR26: CLINIC | AS26: CLINIC | AT26: RHEUMA | AU26: RHEUMA | AV26: CLINIC | AW26: PAIN MANAGEMENT | AX26: ID | AY26: PALLIATIVE | AZ26: PALLIATIVE | BA26: CLINIC | BB26: ID | BC26: ENDO | BD26: =COUNTIF($D26:$BC26,"CARDIO")+COUNTIF($D26:$BC26,"CARDIO E")+COUNTIF($D26:$BC26,"CARDIO E *")+COUNTIF($D26:$BC26,"CARDIO-HCA")+COUNTIF($D26:$BC26,"CARDIO-HCA *")+COUNTIF($D26:$BC26,"CARDIO-RAM")+COUNTIF($D26:$BC26,"CARDIO-RAM *") | BE26: =COUNTIF($D26:$BC26,"CLINIC")+COUNTIF($D26:$BC26,"CLINIC *")+COUNTIF($D26:$BC26,"URGENT CARE")+COUNTIF($D26:$BC26,"URGENT CARE *") | BF26: =COUNTIF($D26:$BC26,"ED") | BG26: =COUNTIF($D26:$BC26,"A")+COUNTIF($D26:$BC26,"B")+COUNTIF($D26:$BC26,"C")+COUNTIF($D26:$BC26,"D")+COUNTIF($D26:$BC26,"G") | BH26: =COUNTIF($D26:$BC26,"ICU") | BI26: =COUNTIF($D26:$BC26,"ICU E") | BJ26: =COUNTIF($D26:$BC26,"ICU N") | BK26: =COUNTIF($D26:$BC26,"ID")+COUNTIF($D26:$BC26,"ID *") | BL26: =COUNTIF($D26:$BC26,"NEURO")+COUNTIF($D26:$BC26,"NEURO *") | BM26: =COUNTIF($D26:$BC26,"NF") | BN26: =COUNTIF($D26:$BC26,"SWING") | BO26: =COUNTIF($D26:$BC26,"VACATION") | BP26: =SUM(BD26:BO26) | BQ26: =COUNTIF($D26:$BC26,"PALLIATIVE")+COUNTIF($D26:$BC26,"PALLIATIVE *") | BR26: =COUNTIF($D26:$BC26,"GERIATRIC")+COUNTIF($D26:$BC26,"GERIATRIC 2") | BS26: =COUNTIF($D26:$BC26,"GS")+COUNTIF($D26:$BC26,"GI")+COUNTIF($D26:$BC26,"GI *") | BT26: =COUNTIF($D26:$BC26,"HEM/ONC")+COUNTIF($D26:$BC26,"HEM/ONC *") | BU26: =COUNTIF($D26:$BC26,"PAIN MANAGEMENT")+COUNTIF($D26:$BC26,"PAIN MANAGEMENT *") | BV26: =COUNTIF($D26:$BC26,"RHEUMA")+COUNTIF($D26:$BC26,"RHEUMA *") | BW26: =COUNTIF($D26:$BC26,"ENDO")+COUNTIF($D26:$BC26,"ENDO *") | BX26: =COUNTIF($D26:$BC26,"PLASTIC")+COUNTIF($D26:$BC26,"PLASTIC *") | BY26: =COUNTIF($D26:$BC26,"PULM")+COUNTIF($D26:$BC26,"PULM *") | BZ26: =COUNTIF($D26:$BC26,"SICU")+COUNTIF($D26:$BC26,"SICU *") | CA26: =COUNTIF($D26:$BC26,"DERMATOLOGY")+COUNTIF($D26:$BC26,"DERMATOLOGY *") | CB26: =COUNTIF($D26:$BC26,"NEPHRO")+COUNTIF($D26:$BC26,"NEPHRO *") | CC26: =SUM(BQ26:CB26) | CD26: =BP26+CC26
